Workbook
Name __DAT1: #REF!
Name __DAT10: #REF!
Name __DAT11: #REF!
Name __DAT12: #REF!
Name __DAT13: #REF!
Name __DAT14: #REF!
Name __DAT15: #REF!
Name __DAT16: #REF!
Name __DAT17: #REF!
Name __DAT18: #REF!
Name __DAT19: #REF!
Name __DAT2: #REF!
Name __DAT20: #REF!
Name __DAT21: #REF!
Name __DAT22: #REF!
Name __DAT23: #REF!
Name __DAT24: #REF!
Name __DAT25: #REF!
Name __DAT26: #REF!
Name __DAT3: #REF!
Name __DAT4: #REF!
Name __DAT5: #REF!
Name __DAT6: #REF!
Name __DAT7: #REF!
Name __DAT8: #REF!
Name __DAT9: #REF!
Name _1007.5: 'Factor Table 2'!$D$93:$G$93
Name _10175: 'Factor Table 2'!$D$111:$G$111
Name _10350: 'Factor Table 2'!$D$112:$G$112
Name _1126.2: 'Factor Table 2'!$D$64:$G$64
Name _1222.9: 'Factor Table 2'!$D$65:$G$65
Name _1258.5: 'Factor Table 2'!$D$90:$G$90
Name _13077: 'Factor Table 2'!$D$106:$G$106
Name _1337.5: 'Factor Table 2'!$D$89:$G$89
Name _1360: 'Factor Table 2'!$D$97:$G$97
Name _1362.5: 'Factor Table 2'!$D$78:$G$78
Name _1415: 'Factor Table 2'!$D$69:$G$69
Name _1419.2: 'Factor Table 2'!$D$91:$G$91
Name _1427.5: 'Factor Table 2'!$D$77:$G$77
Name _1437.2: 'Factor Table 2'!$D$81:$G$81
Name _1442.2: 'Factor Table 2'!$D$80:$G$80
Name _1502.9: 'Factor Table 2'!$D$84:$G$84
Name _1525.5: 'Factor Table 2'!$D$76:$G$76
Name _1602.2: 'Factor Table 2'!$D$85:$G$85
Name _1617.5: 'Factor Table 2'!$D$83:$G$83
Name _1625.6: 'Factor Table 2'!$D$86:$G$86
Name _1635.5: 'Factor Table 2'!$D$95:$G$95
Name _1673: 'Factor Table 2'!$D$73:$G$73
Name _1725: 'Factor Table 2'!$D$82:$G$82
Name _1770: 'Factor Table 2'!$D$74:$G$74
Name _1774: 'Factor Table 2'!$D$88:$G$88
Name _1954.8: 'Factor Table 2'!$D$94:$G$94
Name _1990: 'Factor Table 2'!$D$87:$G$87
Name _2084: 'Factor Table 2'!$D$68:$G$68
Name _2086: 'Factor Table 2'!$D$101:$G$101
Name _2170: 'Factor Table 2'!$D$98:$G$98
Name _2285: 'Factor Table 2'!$D$75:$G$75
Name _2326: 'Factor Table 2'!$D$67:$G$67
Name _2403: 'Factor Table 2'!$D$96:$G$96
Name _2491: 'Factor Table 2'!$D$102:$G$102

Sheet 組織邊界
B1: 組織邊界表
B2: 序號 | C2: 區域 | D2: 廠區名稱 | E2: 廠區地址 | F2: 邊界內排除 | G2: 主要承辦單位 | H2: 管理代表 | I2: 執行秘書 (主要窗口) | J2: 主史電話 | K2: 聯絡人電子郵件信箱
B3: 1 | C3: 台灣 | D3: 桃園廠 | E3: 333613 台灣桃園市龜山工業區興邦路31-1號 | G3: 廠務 | H3: 林明和 | I3: 林新欽 李志祥 | J3: 03-3626301#5901 03-3626301#5902 | K3: david.sh.lin@deltaww.com JEFF.LI@deltaww.com
B4: 2 | C4: 台灣 | D4: 桃園二廠 | E4: 333425 台灣桃園市龜山區山鶯路252號 | F4: 與晶睿通訊股份有限公司共用之設施 | G4: 廠務 | H4: 周哲禎 | I4: 許銘傑 | J4: 03-3191098#8382 | K4: jerry.hsu@deltaww.com
B5: 3 | C5: 台灣 | D5: 桃園五廠 | E5: 333425 台灣桃園市龜山區山鶯路268號 | F5: 5F與晶睿通訊股份有限公司共用之設施 | G5: 廠務 | H5: 葉雲軒 | I5: 許銘傑 | J5: 03-3191098#8382 | K5: jerry.hsu@deltaww.com
B6: 4 | C6: 台灣 | D6: 桃三廠 | E6: 330477 桃園市桃園區興隆路18號 | G6: 廠務 | H6: 劉佳容 | I6: 石政忠 | J6: 03-3626301#5905 | K6: jaffrey.shih@deltaww.com
B7: 5 | C7: 台灣 | D7: 中壢一廠 | E7: 320023 桃園市中壢區東園路3號 | G7: 廠務 | H7: 鍾治滿 | I7: 朱正宇 | J7: 03-4526107#5917 | K7: DEVEN.CHU@deltaww.com
B8: 6 | C8: 台灣 | D8: 中壢RD廠 | E8: 320023 中壢區東園路5號 | H8: 鍾治滿 | I8: 朱正宇 | J8: 03-4526107#5917 | K8: DEVEN.CHU@deltaww.com
B9: 7 | C9: 台灣 | D9: 中壢五廠 | E9: 320023 桃園市中壢區東園路16號 | G9: 廠務 | H9: 鍾治滿 | I9: 朱正宇 | J9: 03-4526107#5917 | K9: deven.chu@deltaww.com
B10: 8 | C10: 台灣 | D10: 平鎮廠 | E10: 324020 台灣桃園市平鎮區中興路458號 | F10: DC棟為華信光電所承租(含行政大樓部分樓層辦公室)、聚積科技(行政大樓二樓、四樓部份區域) | G10: 廠務 | H10: 鍾光文 | I10: 黃偉昌 李建廷 | J10: 03-46994861#3018 03-46994861#3012 | K10: WEICHANG.HUANG@deltaww.com CC.LI@deltaww.com
B11: 9 | C11: 台灣 | D11: 台南分公司第一廠 | E11: 741014 台灣台南市善化區環東路二段39號 | G11: 廠務 | H11: 蔡文蔭 | I11: 楊健廷 | J11: 06-5056565#5903 | K11: CTING.YANG@deltaww.com
B12: 10 | C12: 台灣 | D12: 台南二廠 | E12: 741014 台灣台南市善化區環東路二段30號 | G12: 廠務 | I12: 方豪生 | K12: MARVIN.HS.FANG@deltaww.com
B13: 11 | C13: 台灣 | D13: 瑞光大樓 | E13: 114501 台北市內湖區瑞光路186號 | G13: 廠務 | I13: 賴科仁 | J13: 02-87972088#5911 | K13: KOJEN.LAI@deltaww.com
B14: 12 | C14: 台灣 | D14: 陽光大樓 | E14: 114067 台北市內湖區陽光街256號 | G14: 廠務 | I14: 趙冠瑜 | J14: 02-87972088#5916 | K14: GUANYU.ZHAO@deltaww.com
B15: 13 | C15: 台灣 | D15: 台中廠 | E15: 407751 台中市西屯區科園一路8號 | G15: 廠務 | I15: 江國生 | K15: JOHNSON.KS.CHIANG@deltaww.com
B16: 14 | C16: 台灣 | D16: 錦鋐廠(新增) | E16: 337桃園市大園區高鐵站前西路三段66號 | G16: 廠務 | I16: 朱正宇 | J16: 03-4526107#5917 | K16: DEVEN.CHU@deltaww.com
B17: 15 | C17: 台灣 | D17: 楊梅廠(新增) | E17: 桃園市楊梅區高獅路158號 | G17: 廠務 | H17: 鍾光文 | I17: 黃偉昌 李建廷 | J17: 03-46994861#3018 03-46994861#3012 | K17: WEICHANG.HUANG@deltaww.com CC.LI@deltaww.com
B18: 16 | C18: 台灣
B19: 17
B20: 18
B21: 19
B22: 20
B23: 21
B24: 22
B25: 23
B26: 24
B27: 25
B28: 26
B29: 27
B30: 28
... B109: 107
B110: 108 | G110: ??

Sheet 盤查表單
B2: 報告邊界 | I2: 總碳排放量 | J2: =ROUND(D3+D55,3) -> 1758.644 | K2: tonCO2e
B3: 直接溫室氣體排放 | D3: =SUM(AR6:AR53) -> 192.1789 | F3: 噸CO2e | G3: 類型 | H3: 類別 | I3: 鑑別 (有/無) | J3: 設備 | K3: 排放源 | L3: 活動數據 | M3: 活動數據單位 | N3: 活動數據佐證 | O3: 可能產生之溫室氣體種類 | V3: 排放係數 | AC3: 排放係數來源 | AD3: GWP | AK3: 溫室氣體排放量 | AR3: 合計 t-CO2e | AS3: 類別1、2佔比 | AT3: 總碳排放量佔比
O4: CO2 | P4: CH4 | Q4: N2O | R4: HFCs | S4: PFCs | T4: SF6 | U4: NF3 | V4: CO2 | W4: CH4 | X4: N2O | Y4: HFCs | Z4: PFCs | AA4: SF6 | AB4: NF3 | AD4: CO2 | AE4: CH4 | AF4: N2O | AG4: HFCs | AH4: PFCs | AI4: SF6 | AJ4: NF3 | AK4: CO2 | AL4: CH4 | AM4: N2O | AN4: HFCs | AO4: PFCs | AP4: SF6 | AQ4: NF3
B5: 類別 1: | C5: 直接溫室氣體排放和移除(1)
B6: 1.1 | C6: 固定燃燒直接排放 | G6: =IF(K6<>"","固定燃燒","") -> 固定燃燒 | H6: =IF(K6<>"",1,"") -> 1 | I6: =IF(COUNTA(K6:K15)>0,"有","無") -> 有 | J6: 餐飲服務作業程序 | K6: 天然氣 | L6: 12.917 | M6: 千立方公尺 | N6: 天然氣收費單 | O6: =IF(V6>0.0000000001,"V","") -> V | P6: =IF(W6>0.0000000001,"V","") -> V | Q6: =IF(X6>0.0000000001,"V","") -> V | R6: =IF(Y6>0.0000000001,"V","") | S6: =IF(Z6>0.0000000001,"V","") | T6: =IF(AA6>0.0000000001,"V","") | U6: =IF(AB6>0.0000000001,"V","") | V6: =IFERROR(ROUND(VLOOKUP($K6,'Factor Table 1'!$D$3:$AD$60,11,FALSE),10),0) -> 1.8790358 | W6: =IFERROR(ROUND(VLOOKUP($K6,'Factor Table 1'!$D$3:$AD$60,13,FALSE),10),0) -> 3.34944e-05 | X6: =IFERROR(ROUND(VLOOKUP($K6,'Factor Table 1'!$D$3:$AD$60,15,FALSE),10),0) -> 3.3494e-06 | Y6: =IFERROR(IF(OR(K6="CO2",K6="CH4",K6="N2O"),ROUND(VLOOKUP($K6,'Factor Table 1'!$D$3:$AD$69,17,FALSE),10),IFERROR(ROUND(VLOOKUP(J6,'Factor Table 1'!$C$3:$AD$69,18,FALSE),10),ROUND(VLOOKUP(K6,'Factor Table 1'!$D$3:$AD$69,17,FALSE),10))),0) -> 0 | Z6: 0 | AA6: =IFERROR(IF(K6="SF6",1,0),0) -> 0 | AB6: =IFERROR(IF(K6="NF3",1,0),0) -> 0 | AC6: =IFERROR(IF(OR(K6="CO2",K6="CH4",K6="N2O"),VLOOKUP($K6,'Factor Table 1'!$D$3:$AD$69,19,FALSE),IFERROR(VLOOKUP(J6,'Factor Table 1'!$C$3:$AD$69,20,FALSE),VLOOKUP(K6,'Factor Table 1'!$D$3:$AD$69,19,FALSE))),"") -> 環境部排放係管理表6.0.4 | AD6: =IF(H6=1,1,0) -> 1 | AE6: =IF(H6=1,IF(盤查結果!$F$6="IPCC第二次評估報告（1995）",'Factor Table 1'!$L$75,IF(盤查結果!$F$6="IPCC第三次評估報告(2001)",'Factor Table 1'!$M$75,IF(盤查結果!$F$6="IPCC第四次評估報告(2007)",'Factor Table 1'!$N$75,IF(盤查結果!$F$6="IPCC第五次評估報告(2013)",'Factor Table 1'!$O$75,IF(盤查結果!$F$6="IPCC第六次評估報告(2021)",'Factor Table 1'!$P$75,0))))),0) -> 27 | AF6: =IF(H6=1,IF(盤查結果!$F$6="IPCC第二次評估報告（1995）",'Factor Table 1'!$L$76,IF(盤查結果!$F$6="IPCC第三次評估報告(2001)",'Factor Table 1'!$M$76,IF(盤查結果!$F$6="IPCC第四次評估報告(2007)",'Factor Table 1'!$N$76,IF(盤查結果!$F$6="IPCC第五次評估報告(2013)",'Factor Table 1'!$O$76,IF(盤查結果!$F$6="IPCC第六次評估報告(2021)",'Factor Table 1'!$P$76,0))))),0) -> 273 | AG6: =IFERROR(IF(H6=1,IF(盤查結果!$F$6="IPCC第二次評估報告（1995）",VLOOKUP(K6,'Factor Table 1'!$D$75:$P$169,9,FALSE),IF(盤查結果!$F$6="IPCC第三次評估報告(2001)",VLOOKUP(K6,'Factor Table 1'!$D$75:$P$169,10,FALSE),IF(盤查結果!$F$6="IPCC第四次評估報告(2007)",VLOOKUP(K6,'Factor Table 1'!$D$75:$P$169,11,FALSE),IF(盤查結果!$F$6="IPCC第五次評估報告(2013)",VLOOKUP(K6,'Factor Table 1'!$D$75:$P$169,12,FALSE),IF(盤查結果!$F$6="IPCC第六次評估報告(2021)",VLOOKUP(K6,'Factor Table 1'!$D$75:$P$169,13,FALSE),0))))),0),0) -> 0 | AH6: 0 | AI6: =IFERROR(IF(H6=1,IF(盤查結果!$F$6="IPCC第二次評估報告（1995）",VLOOKUP(K6,'Factor Table 1'!$D$172:$P$172,9,FALSE),IF(盤查結果!$F$6="IPCC第三次評估報告(2001)",VLOOKUP(K6,'Factor Table 1'!$D$172:$P$172,10,FALSE),IF(盤查結果!$F$6="IPCC第四次評估報告(2007)",VLOOKUP(K6,'Factor Table 1'!$D$172:$P$172,11,FALSE),IF(盤查結果!$F$6="IPCC第五次評估報告(2013)",VLOOKUP(K6,'Factor Table 1'!$D$172:$P$172,12,FALSE),IF(盤查結果!$F$6="IPCC第六次評估報告(2021)",VLOOKUP(K6,'Factor Table 1'!$D$172:$P$172,13,FALSE),0))))),0),0) -> 0 | AJ6: =IFERROR(IF(H6=1,IF(盤查結果!$F$6="IPCC第二次評估報告（1995）",VLOOKUP(K6,'Factor Table 1'!$D$171:$P$171,9,FALSE),IF(盤查結果!$F$6="IPCC第三次評估報告(2001)",VLOOKUP(K6,'Factor Table 1'!$D$171:$P$171,10,FALSE),IF(盤查結果!$F$6="IPCC第四次評估報告(2007)",VLOOKUP(K6,'Factor Table 1'!$D$171:$P$172,11,FALSE),IF(盤查結果!$F$6="IPCC第五次評估報告(2013)",VLOOKUP(K6,'Factor Table 1'!$D$171:$P$171,12,FALSE),IF(盤查結果!$F$6="IPCC第六次評估報告(2021)",VLOOKUP(K6,'Factor Table 1'!$D$171:$P$171,13,FALSE),0))))),0),0) -> 0 | AK6: =$L6*V6*AD6 -> 24.271506 | AL6: =$L6*W6*AE6 -> 0.011681473 | AM6: =$L6*X6*AF6 -> 0.011811127 | AN6: =$L6*Y6*AG6 -> 0 | AO6: =$L6*Z6*AH6 -> 0 | AP6: =$L6*AA6*AI6 -> 0 | AQ6: =$L6*AB6*AJ6 -> 0 | AR6: =ROUND(SUM(AK6:AQ6),4) -> 24.295 | AS6: =AR6/($D$3+$Y$57+$Y$63) -> 0.050883268 | AT6: =AS6/($D$3+$D$55) -> 2.8933246e-05
G7: =IF(K7<>"","固定燃燒","") -> 固定燃燒 | H7: =IF(K7<>"",1,"") -> 1 | J7: 緊急發電機作業 | K7: 柴油 | L7: 0 | M7: 公秉 | N7: 購買發票 | O7: =IF(V7>0.0000000001,"V","") -> V | P7: =IF(W7>0.0000000001,"V","") -> V | Q7: =IF(X7>0.0000000001,"V","") -> V | R7: =IF(Y7>0.0000000001,"V","") | S7: =IF(Z7>0.0000000001,"V","") | T7: =IF(AA7>0.0000000001,"V","") | U7: =IF(AB7>0.0000000001,"V","") | V7: =IFERROR(ROUND(VLOOKUP($K7,'Factor Table 1'!$D$3:$AD$60,11,FALSE),10),0) -> 2.6060318 | W7: =IFERROR(ROUND(VLOOKUP($K7,'Factor Table 1'!$D$3:$AD$60,13,FALSE),10),0) -> 0.0001055074 | X7: =IFERROR(ROUND(VLOOKUP($K7,'Factor Table 1'!$D$3:$AD$60,15,FALSE),10),0) -> 2.11015e-05 | Y7: =IFERROR(IF(OR(K7="CO2",K7="CH4",K7="N2O"),ROUND(VLOOKUP($K7,'Factor Table 1'!$D$3:$AD$69,17,FALSE),10),IFERROR(ROUND(VLOOKUP(J7,'Factor Table 1'!$C$3:$AD$69,18,FALSE),10),ROUND(VLOOKUP(K7,'Factor Table 1'!$D$3:$AD$69,17,FALSE),10))),0) -> 0 | Z7: 0 | AA7: =IFERROR(IF(K7="SF6",1,0),0) -> 0 | AB7: =IFERROR(IF(K7="NF3",1,0),0) -> 0 | AC7: =IFERROR(IF(OR(K7="CO2",K7="CH4",K7="N2O"),VLOOKUP($K7,'Factor Table 1'!$D$3:$AD$69,19,FALSE),IFERROR(VLOOKUP(J7,'Factor Table 1'!$C$3:$AD$69,20,FALSE),VLOOKUP(K7,'Factor Table 1'!$D$3:$AD$69,19,FALSE))),"") -> 環境部排放係管理表6.0.4 | AD7: =IF(H7=1,1,0) -> 1 | AE7: =IF(H7=1,IF(盤查結果!$F$6="IPCC第二次評估報告（1995）",'Factor Table 1'!$L$75,IF(盤查結果!$F$6="IPCC第三次評估報告(2001)",'Factor Table 1'!$M$75,IF(盤查結果!$F$6="IPCC第四次評估報告(2007)",'Factor Table 1'!$N$75,IF(盤查結果!$F$6="IPCC第五次評估報告(2013)",'Factor Table 1'!$O$75,IF(盤查結果!$F$6="IPCC第六次評估報告(2021)",'Factor Table 1'!$P$75,0))))),0) -> 27 | AF7: =IF(H7=1,IF(盤查結果!$F$6="IPCC第二次評估報告（1995）",'Factor Table 1'!$L$76,IF(盤查結果!$F$6="IPCC第三次評估報告(2001)",'Factor Table 1'!$M$76,IF(盤查結果!$F$6="IPCC第四次評估報告(2007)",'Factor Table 1'!$N$76,IF(盤查結果!$F$6="IPCC第五次評估報告(2013)",'Factor Table 1'!$O$76,IF(盤查結果!$F$6="IPCC第六次評估報告(2021)",'Factor Table 1'!$P$76,0))))),0) -> 273 | AG7: =IFERROR(IF(H7=1,IF(盤查結果!$F$6="IPCC第二次評估報告（1995）",VLOOKUP(K7,'Factor Table 1'!$D$75:$P$169,9,FALSE),IF(盤查結果!$F$6="IPCC第三次評估報告(2001)",VLOOKUP(K7,'Factor Table 1'!$D$75:$P$169,10,FALSE),IF(盤查結果!$F$6="IPCC第四次評估報告(2007)",VLOOKUP(K7,'Factor Table 1'!$D$75:$P$169,11,FALSE),IF(盤查結果!$F$6="IPCC第五次評估報告(2013)",VLOOKUP(K7,'Factor Table 1'!$D$75:$P$169,12,FALSE),IF(盤查結果!$F$6="IPCC第六次評估報告(2021)",VLOOKUP(K7,'Factor Table 1'!$D$75:$P$169,13,FALSE),0))))),0),0) -> 0 | AH7: 0 | AI7: =IFERROR(IF(H7=1,IF(盤查結果!$F$6="IPCC第二次評估報告（1995）",VLOOKUP(K7,'Factor Table 1'!$D$172:$P$172,9,FALSE),IF(盤查結果!$F$6="IPCC第三次評估報告(2001)",VLOOKUP(K7,'Factor Table 1'!$D$172:$P$172,10,FALSE),IF(盤查結果!$F$6="IPCC第四次評估報告(2007)",VLOOKUP(K7,'Factor Table 1'!$D$172:$P$172,11,FALSE),IF(盤查結果!$F$6="IPCC第五次評估報告(2013)",VLOOKUP(K7,'Factor Table 1'!$D$172:$P$172,12,FALSE),IF(盤查結果!$F$6="IPCC第六次評估報告(2021)",VLOOKUP(K7,'Factor Table 1'!$D$172:$P$172,13,FALSE),0))))),0),0) -> 0 | AJ7: =IFERROR(IF(H7=1,IF(盤查結果!$F$6="IPCC第二次評估報告（1995）",VLOOKUP(K7,'Factor Table 1'!$D$171:$P$171,9,FALSE),IF(盤查結果!$F$6="IPCC第三次評估報告(2001)",VLOOKUP(K7,'Factor Table 1'!$D$171:$P$171,10,FALSE),IF(盤查結果!$F$6="IPCC第四次評估報告(2007)",VLOOKUP(K7,'Factor Table 1'!$D$171:$P$171,11,FALSE),IF(盤查結果!$F$6="IPCC第五次評估報告(2013)",VLOOKUP(K7,'Factor Table 1'!$D$171:$P$171,12,FALSE),IF(盤查結果!$F$6="IPCC第六次評估報告(2021)",VLOOKUP(K7,'Factor Table 1'!$D$171:$P$171,13,FALSE),0))))),0),0) -> 0 | AK7: =$L7*V7*AD7 -> 0 | AL7: =$L7*W7*AE7 -> 0 | AM7: =$L7*X7*AF7 -> 0 | AN7: =$L7*Y7*AG7 -> 0 | AO7: =$L7*Z7*AH7 -> 0 | AP7: =$L7*AA7*AI7 -> 0 | AQ7: =$L7*AB7*AJ7 -> 0 | AR7: =ROUND(SUM(AK7:AQ7),4) -> 0 | AS7: =AR7/($D$3+$Y$57+$Y$63) -> 0 | AT7: =AS7/($D$3+$D$55) -> 0
G8: =IF(K8<>"","固定燃燒","") | H8: =IF(K8<>"",1,"") | O8: =IF(V8>0.0000000001,"V","") | P8: =IF(W8>0.0000000001,"V","") | Q8: =IF(X8>0.0000000001,"V","") | R8: =IF(Y8>0.0000000001,"V","") | S8: =IF(Z8>0.0000000001,"V","") | T8: =IF(AA8>0.0000000001,"V","") | U8: =IF(AB8>0.0000000001,"V","") | V8: =IFERROR(ROUND(VLOOKUP($K8,'Factor Table 1'!$D$3:$AD$60,11,FALSE),10),0) -> 0 | W8: =IFERROR(ROUND(VLOOKUP($K8,'Factor Table 1'!$D$3:$AD$60,13,FALSE),10),0) -> 0 | X8: =IFERROR(ROUND(VLOOKUP($K8,'Factor Table 1'!$D$3:$AD$60,15,FALSE),10),0) -> 0 | Y8: =IFERROR(IF(OR(K8="CO2",K8="CH4",K8="N2O"),ROUND(VLOOKUP($K8,'Factor Table 1'!$D$3:$AD$69,17,FALSE),10),IFERROR(ROUND(VLOOKUP(J8,'Factor Table 1'!$C$3:$AD$69,18,FALSE),10),ROUND(VLOOKUP(K8,'Factor Table 1'!$D$3:$AD$69,17,FALSE),10))),0) -> 0 | Z8: 0 | AA8: =IFERROR(IF(K8="SF6",1,0),0) -> 0 | AB8: =IFERROR(IF(K8="NF3",1,0),0) -> 0 | AC8: =IFERROR(IF(OR(K8="CO2",K8="CH4",K8="N2O"),VLOOKUP($K8,'Factor Table 1'!$D$3:$AD$69,19,FALSE),IFERROR(VLOOKUP(J8,'Factor Table 1'!$C$3:$AD$69,20,FALSE),VLOOKUP(K8,'Factor Table 1'!$D$3:$AD$69,19,FALSE))),"") | AD8: =IF(H8=1,1,0) -> 0 | AE8: =IF(H8=1,IF(盤查結果!$F$6="IPCC第二次評估報告（1995）",'Factor Table 1'!$L$75,IF(盤查結果!$F$6="IPCC第三次評估報告(2001)",'Factor Table 1'!$M$75,IF(盤查結果!$F$6="IPCC第四次評估報告(2007)",'Factor Table 1'!$N$75,IF(盤查結果!$F$6="IPCC第五次評估報告(2013)",'Factor Table 1'!$O$75,IF(盤查結果!$F$6="IPCC第六次評估報告(2021)",'Factor Table 1'!$P$75,0))))),0) -> 0 | AF8: =IF(H8=1,IF(盤查結果!$F$6="IPCC第二次評估報告（1995）",'Factor Table 1'!$L$76,IF(盤查結果!$F$6="IPCC第三次評估報告(2001)",'Factor Table 1'!$M$76,IF(盤查結果!$F$6="IPCC第四次評估報告(2007)",'Factor Table 1'!$N$76,IF(盤查結果!$F$6="IPCC第五次評估報告(2013)",'Factor Table 1'!$O$76,IF(盤查結果!$F$6="IPCC第六次評估報告(2021)",'Factor Table 1'!$P$76,0))))),0) -> 0 | AG8: =IFERROR(IF(H8=1,IF(盤查結果!$F$6="IPCC第二次評估報告（1995）",VLOOKUP(K8,'Factor Table 1'!$D$75:$P$169,9,FALSE),IF(盤查結果!$F$6="IPCC第三次評估報告(2001)",VLOOKUP(K8,'Factor Table 1'!$D$75:$P$169,10,FALSE),IF(盤查結果!$F$6="IPCC第四次評估報告(2007)",VLOOKUP(K8,'Factor Table 1'!$D$75:$P$169,11,FALSE),IF(盤查結果!$F$6="IPCC第五次評估報告(2013)",VLOOKUP(K8,'Factor Table 1'!$D$75:$P$169,12,FALSE),IF(盤查結果!$F$6="IPCC第六次評估報告(2021)",VLOOKUP(K8,'Factor Table 1'!$D$75:$P$169,13,FALSE),0))))),0),0) -> 0 | AH8: 0 | AI8: =IFERROR(IF(H8=1,IF(盤查結果!$F$6="IPCC第二次評估報告（1995）",VLOOKUP(K8,'Factor Table 1'!$D$172:$P$172,9,FALSE),IF(盤查結果!$F$6="IPCC第三次評估報告(2001)",VLOOKUP(K8,'Factor Table 1'!$D$172:$P$172,10,FALSE),IF(盤查結果!$F$6="IPCC第四次評估報告(2007)",VLOOKUP(K8,'Factor Table 1'!$D$172:$P$172,11,FALSE),IF(盤查結果!$F$6="IPCC第五次評估報告(2013)",VLOOKUP(K8,'Factor Table 1'!$D$172:$P$172,12,FALSE),IF(盤查結果!$F$6="IPCC第六次評估報告(2021)",VLOOKUP(K8,'Factor Table 1'!$D$172:$P$172,13,FALSE),0))))),0),0) -> 0 | AJ8: =IFERROR(IF(H8=1,IF(盤查結果!$F$6="IPCC第二次評估報告（1995）",VLOOKUP(K8,'Factor Table 1'!$D$171:$P$171,9,FALSE),IF(盤查結果!$F$6="IPCC第三次評估報告(2001)",VLOOKUP(K8,'Factor Table 1'!$D$171:$P$171,10,FALSE),IF(盤查結果!$F$6="IPCC第四次評估報告(2007)",VLOOKUP(K8,'Factor Table 1'!$D$171:$P$171,11,FALSE),IF(盤查結果!$F$6="IPCC第五次評估報告(2013)",VLOOKUP(K8,'Factor Table 1'!$D$171:$P$171,12,FALSE),IF(盤查結果!$F$6="IPCC第六次評估報告(2021)",VLOOKUP(K8,'Factor Table 1'!$D$171:$P$171,13,FALSE),0))))),0),0) -> 0 | AK8: =$L8*V8*AD8 -> 0 | AL8: =$L8*W8*AE8 -> 0 | AM8: =$L8*X8*AF8 -> 0 | AN8: =$L8*Y8*AG8 -> 0 | AO8: =$L8*Z8*AH8 -> 0 | AP8: =$L8*AA8*AI8 -> 0 | AQ8: =$L8*AB8*AJ8 -> 0 | AR8: =ROUND(SUM(AK8:AQ8),4) -> 0 | AS8: =AR8/($D$3+$Y$57+$Y$63) -> 0 | AT8: =AS8/($D$3+$D$55) -> 0
G9: =IF(K9<>"","固定燃燒","") | H9: =IF(K9<>"",1,"") | O9: =IF(V9>0.0000000001,"V","") | P9: =IF(W9>0.0000000001,"V","") | Q9: =IF(X9>0.0000000001,"V","") | R9: =IF(Y9>0.0000000001,"V","") | S9: =IF(Z9>0.0000000001,"V","") | T9: =IF(AA9>0.0000000001,"V","") | U9: =IF(AB9>0.0000000001,"V","") | V9: =IFERROR(ROUND(VLOOKUP($K9,'Factor Table 1'!$D$3:$AD$60,11,FALSE),10),0) -> 0 | W9: =IFERROR(ROUND(VLOOKUP($K9,'Factor Table 1'!$D$3:$AD$60,13,FALSE),10),0) -> 0 | X9: =IFERROR(ROUND(VLOOKUP($K9,'Factor Table 1'!$D$3:$AD$60,15,FALSE),10),0) -> 0 | Y9: =IFERROR(IF(OR(K9="CO2",K9="CH4",K9="N2O"),ROUND(VLOOKUP($K9,'Factor Table 1'!$D$3:$AD$69,17,FALSE),10),IFERROR(ROUND(VLOOKUP(J9,'Factor Table 1'!$C$3:$AD$69,18,FALSE),10),ROUND(VLOOKUP(K9,'Factor Table 1'!$D$3:$AD$69,17,FALSE),10))),0) -> 0 | Z9: 0 | AA9: =IFERROR(IF(K9="SF6",1,0),0) -> 0 | AB9: =IFERROR(IF(K9="NF3",1,0),0) -> 0 | AC9: =IFERROR(IF(OR(K9="CO2",K9="CH4",K9="N2O"),VLOOKUP($K9,'Factor Table 1'!$D$3:$AD$69,19,FALSE),IFERROR(VLOOKUP(J9,'Factor Table 1'!$C$3:$AD$69,20,FALSE),VLOOKUP(K9,'Factor Table 1'!$D$3:$AD$69,19,FALSE))),"") | AD9: =IF(H9=1,1,0) -> 0 | AE9: =IF(H9=1,IF(盤查結果!$F$6="IPCC第二次評估報告（1995）",'Factor Table 1'!$L$75,IF(盤查結果!$F$6="IPCC第三次評估報告(2001)",'Factor Table 1'!$M$75,IF(盤查結果!$F$6="IPCC第四次評估報告(2007)",'Factor Table 1'!$N$75,IF(盤查結果!$F$6="IPCC第五次評估報告(2013)",'Factor Table 1'!$O$75,IF(盤查結果!$F$6="IPCC第六次評估報告(2021)",'Factor Table 1'!$P$75,0))))),0) -> 0 | AF9: =IF(H9=1,IF(盤查結果!$F$6="IPCC第二次評估報告（1995）",'Factor Table 1'!$L$76,IF(盤查結果!$F$6="IPCC第三次評估報告(2001)",'Factor Table 1'!$M$76,IF(盤查結果!$F$6="IPCC第四次評估報告(2007)",'Factor Table 1'!$N$76,IF(盤查結果!$F$6="IPCC第五次評估報告(2013)",'Factor Table 1'!$O$76,IF(盤查結果!$F$6="IPCC第六次評估報告(2021)",'Factor Table 1'!$P$76,0))))),0) -> 0 | AG9: =IFERROR(IF(H9=1,IF(盤查結果!$F$6="IPCC第二次評估報告（1995）",VLOOKUP(K9,'Factor Table 1'!$D$75:$P$169,9,FALSE),IF(盤查結果!$F$6="IPCC第三次評估報告(2001)",VLOOKUP(K9,'Factor Table 1'!$D$75:$P$169,10,FALSE),IF(盤查結果!$F$6="IPCC第四次評估報告(2007)",VLOOKUP(K9,'Factor Table 1'!$D$75:$P$169,11,FALSE),IF(盤查結果!$F$6="IPCC第五次評估報告(2013)",VLOOKUP(K9,'Factor Table 1'!$D$75:$P$169,12,FALSE),IF(盤查結果!$F$6="IPCC第六次評估報告(2021)",VLOOKUP(K9,'Factor Table 1'!$D$75:$P$169,13,FALSE),0))))),0),0) -> 0 | AH9: 0 | AI9: =IFERROR(IF(H9=1,IF(盤查結果!$F$6="IPCC第二次評估報告（1995）",VLOOKUP(K9,'Factor Table 1'!$D$172:$P$172,9,FALSE),IF(盤查結果!$F$6="IPCC第三次評估報告(2001)",VLOOKUP(K9,'Factor Table 1'!$D$172:$P$172,10,FALSE),IF(盤查結果!$F$6="IPCC第四次評估報告(2007)",VLOOKUP(K9,'Factor Table 1'!$D$172:$P$172,11,FALSE),IF(盤查結果!$F$6="IPCC第五次評估報告(2013)",VLOOKUP(K9,'Factor Table 1'!$D$172:$P$172,12,FALSE),IF(盤查結果!$F$6="IPCC第六次評估報告(2021)",VLOOKUP(K9,'Factor Table 1'!$D$172:$P$172,13,FALSE),0))))),0),0) -> 0 | AJ9: =IFERROR(IF(H9=1,IF(盤查結果!$F$6="IPCC第二次評估報告（1995）",VLOOKUP(K9,'Factor Table 1'!$D$171:$P$171,9,FALSE),IF(盤查結果!$F$6="IPCC第三次評估報告(2001)",VLOOKUP(K9,'Factor Table 1'!$D$171:$P$171,10,FALSE),IF(盤查結果!$F$6="IPCC第四次評估報告(2007)",VLOOKUP(K9,'Factor Table 1'!$D$171:$P$171,11,FALSE),IF(盤查結果!$F$6="IPCC第五次評估報告(2013)",VLOOKUP(K9,'Factor Table 1'!$D$171:$P$171,12,FALSE),IF(盤查結果!$F$6="IPCC第六次評估報告(2021)",VLOOKUP(K9,'Factor Table 1'!$D$171:$P$171,13,FALSE),0))))),0),0) -> 0 | AK9: =$L9*V9*AD9 -> 0 | AL9: =$L9*W9*AE9 -> 0 | AM9: =$L9*X9*AF9 -> 0 | AN9: =$L9*Y9*AG9 -> 0 | AO9: =$L9*Z9*AH9 -> 0 | AP9: =$L9*AA9*AI9 -> 0 | AQ9: =$L9*AB9*AJ9 -> 0 | AR9: =ROUND(SUM(AK9:AQ9),4) -> 0 | AS9: =AR9/($D$3+$Y$57+$Y$63) -> 0 | AT9: =AS9/($D$3+$D$55) -> 0
G10: =IF(K10<>"","固定燃燒","") | H10: =IF(K10<>"",1,"") | O10: =IF(V10>0.0000000001,"V","") | P10: =IF(W10>0.0000000001,"V","") | Q10: =IF(X10>0.0000000001,"V","") | R10: =IF(Y10>0.0000000001,"V","") | S10: =IF(Z10>0.0000000001,"V","") | T10: =IF(AA10>0.0000000001,"V","") | U10: =IF(AB10>0.0000000001,"V","") | V10: =IFERROR(ROUND(VLOOKUP($K10,'Factor Table 1'!$D$3:$AD$60,11,FALSE),10),0) -> 0 | W10: =IFERROR(ROUND(VLOOKUP($K10,'Factor Table 1'!$D$3:$AD$60,13,FALSE),10),0) -> 0 | X10: =IFERROR(ROUND(VLOOKUP($K10,'Factor Table 1'!$D$3:$AD$60,15,FALSE),10),0) -> 0 | Y10: =IFERROR(IF(OR(K10="CO2",K10="CH4",K10="N2O"),ROUND(VLOOKUP($K10,'Factor Table 1'!$D$3:$AD$69,17,FALSE),10),IFERROR(ROUND(VLOOKUP(J10,'Factor Table 1'!$C$3:$AD$69,18,FALSE),10),ROUND(VLOOKUP(K10,'Factor Table 1'!$D$3:$AD$69,17,FALSE),10))),0) -> 0 | Z10: 0 | AA10: =IFERROR(IF(K10="SF6",1,0),0) -> 0 | AB10: =IFERROR(IF(K10="NF3",1,0),0) -> 0 | AC10: =IFERROR(IF(OR(K10="CO2",K10="CH4",K10="N2O"),VLOOKUP($K10,'Factor Table 1'!$D$3:$AD$69,19,FALSE),IFERROR(VLOOKUP(J10,'Factor Table 1'!$C$3:$AD$69,20,FALSE),VLOOKUP(K10,'Factor Table 1'!$D$3:$AD$69,19,FALSE))),"") | AD10: =IF(H10=1,1,0) -> 0 | AE10: =IF(H10=1,IF(盤查結果!$F$6="IPCC第二次評估報告（1995）",'Factor Table 1'!$L$75,IF(盤查結果!$F$6="IPCC第三次評估報告(2001)",'Factor Table 1'!$M$75,IF(盤查結果!$F$6="IPCC第四次評估報告(2007)",'Factor Table 1'!$N$75,IF(盤查結果!$F$6="IPCC第五次評估報告(2013)",'Factor Table 1'!$O$75,IF(盤查結果!$F$6="IPCC第六次評估報告(2021)",'Factor Table 1'!$P$75,0))))),0) -> 0 | AF10: =IF(H10=1,IF(盤查結果!$F$6="IPCC第二次評估報告（1995）",'Factor Table 1'!$L$76,IF(盤查結果!$F$6="IPCC第三次評估報告(2001)",'Factor Table 1'!$M$76,IF(盤查結果!$F$6="IPCC第四次評估報告(2007)",'Factor Table 1'!$N$76,IF(盤查結果!$F$6="IPCC第五次評估報告(2013)",'Factor Table 1'!$O$76,IF(盤查結果!$F$6="IPCC第六次評估報告(2021)",'Factor Table 1'!$P$76,0))))),0) -> 0 | AG10: =IFERROR(IF(H10=1,IF(盤查結果!$F$6="IPCC第二次評估報告（1995）",VLOOKUP(K10,'Factor Table 1'!$D$75:$P$169,9,FALSE),IF(盤查結果!$F$6="IPCC第三次評估報告(2001)",VLOOKUP(K10,'Factor Table 1'!$D$75:$P$169,10,FALSE),IF(盤查結果!$F$6="IPCC第四次評估報告(2007)",VLOOKUP(K10,'Factor Table 1'!$D$75:$P$169,11,FALSE),IF(盤查結果!$F$6="IPCC第五次評估報告(2013)",VLOOKUP(K10,'Factor Table 1'!$D$75:$P$169,12,FALSE),IF(盤查結果!$F$6="IPCC第六次評估報告(2021)",VLOOKUP(K10,'Factor Table 1'!$D$75:$P$169,13,FALSE),0))))),0),0) -> 0 | AH10: 0 | AI10: =IFERROR(IF(H10=1,IF(盤查結果!$F$6="IPCC第二次評估報告（1995）",VLOOKUP(K10,'Factor Table 1'!$D$172:$P$172,9,FALSE),IF(盤查結果!$F$6="IPCC第三次評估報告(2001)",VLOOKUP(K10,'Factor Table 1'!$D$172:$P$172,10,FALSE),IF(盤查結果!$F$6="IPCC第四次評估報告(2007)",VLOOKUP(K10,'Factor Table 1'!$D$172:$P$172,11,FALSE),IF(盤查結果!$F$6="IPCC第五次評估報告(2013)",VLOOKUP(K10,'Factor Table 1'!$D$172:$P$172,12,FALSE),IF(盤查結果!$F$6="IPCC第六次評估報告(2021)",VLOOKUP(K10,'Factor Table 1'!$D$172:$P$172,13,FALSE),0))))),0),0) -> 0 | AJ10: =IFERROR(IF(H10=1,IF(盤查結果!$F$6="IPCC第二次評估報告（1995）",VLOOKUP(K10,'Factor Table 1'!$D$171:$P$171,9,FALSE),IF(盤查結果!$F$6="IPCC第三次評估報告(2001)",VLOOKUP(K10,'Factor Table 1'!$D$171:$P$171,10,FALSE),IF(盤查結果!$F$6="IPCC第四次評估報告(2007)",VLOOKUP(K10,'Factor Table 1'!$D$171:$P$171,11,FALSE),IF(盤查結果!$F$6="IPCC第五次評估報告(2013)",VLOOKUP(K10,'Factor Table 1'!$D$171:$P$171,12,FALSE),IF(盤查結果!$F$6="IPCC第六次評估報告(2021)",VLOOKUP(K10,'Factor Table 1'!$D$171:$P$171,13,FALSE),0))))),0),0) -> 0 | AK10: =$L10*V10*AD10 -> 0 | AL10: =$L10*W10*AE10 -> 0 | AM10: =$L10*X10*AF10 -> 0 | AN10: =$L10*Y10*AG10 -> 0 | AO10: =$L10*Z10*AH10 -> 0 | AP10: =$L10*AA10*AI10 -> 0 | AQ10: =$L10*AB10*AJ10 -> 0 | AR10: =ROUND(SUM(AK10:AQ10),4) -> 0 | AS10: =AR10/($D$3+$Y$57+$Y$63) -> 0 | AT10: =AS10/($D$3+$D$55) -> 0
G11: =IF(K11<>"","固定燃燒","") | H11: =IF(K11<>"",1,"") | O11: =IF(V11>0.0000000001,"V","") | P11: =IF(W11>0.0000000001,"V","") | Q11: =IF(X11>0.0000000001,"V","") | R11: =IF(Y11>0.0000000001,"V","") | S11: =IF(Z11>0.0000000001,"V","") | T11: =IF(AA11>0.0000000001,"V","") | U11: =IF(AB11>0.0000000001,"V","") | V11: =IFERROR(ROUND(VLOOKUP($K11,'Factor Table 1'!$D$3:$AD$60,11,FALSE),10),0) -> 0 | W11: =IFERROR(ROUND(VLOOKUP($K11,'Factor Table 1'!$D$3:$AD$60,13,FALSE),10),0) -> 0 | X11: =IFERROR(ROUND(VLOOKUP($K11,'Factor Table 1'!$D$3:$AD$60,15,FALSE),10),0) -> 0 | Y11: =IFERROR(IF(OR(K11="CO2",K11="CH4",K11="N2O"),ROUND(VLOOKUP($K11,'Factor Table 1'!$D$3:$AD$69,17,FALSE),10),IFERROR(ROUND(VLOOKUP(J11,'Factor Table 1'!$C$3:$AD$69,18,FALSE),10),ROUND(VLOOKUP(K11,'Factor Table 1'!$D$3:$AD$69,17,FALSE),10))),0) -> 0 | Z11: 0 | AA11: =IFERROR(IF(K11="SF6",1,0),0) -> 0 | AB11: =IFERROR(IF(K11="NF3",1,0),0) -> 0 | AC11: =IFERROR(IF(OR(K11="CO2",K11="CH4",K11="N2O"),VLOOKUP($K11,'Factor Table 1'!$D$3:$AD$69,19,FALSE),IFERROR(VLOOKUP(J11,'Factor Table 1'!$C$3:$AD$69,20,FALSE),VLOOKUP(K11,'Factor Table 1'!$D$3:$AD$69,19,FALSE))),"") | AD11: =IF(H11=1,1,0) -> 0 | AE11: =IF(H11=1,IF(盤查結果!$F$6="IPCC第二次評估報告（1995）",'Factor Table 1'!$L$75,IF(盤查結果!$F$6="IPCC第三次評估報告(2001)",'Factor Table 1'!$M$75,IF(盤查結果!$F$6="IPCC第四次評估報告(2007)",'Factor Table 1'!$N$75,IF(盤查結果!$F$6="IPCC第五次評估報告(2013)",'Factor Table 1'!$O$75,IF(盤查結果!$F$6="IPCC第六次評估報告(2021)",'Factor Table 1'!$P$75,0))))),0) -> 0 | AF11: =IF(H11=1,IF(盤查結果!$F$6="IPCC第二次評估報告（1995）",'Factor Table 1'!$L$76,IF(盤查結果!$F$6="IPCC第三次評估報告(2001)",'Factor Table 1'!$M$76,IF(盤查結果!$F$6="IPCC第四次評估報告(2007)",'Factor Table 1'!$N$76,IF(盤查結果!$F$6="IPCC第五次評估報告(2013)",'Factor Table 1'!$O$76,IF(盤查結果!$F$6="IPCC第六次評估報告(2021)",'Factor Table 1'!$P$76,0))))),0) -> 0 | AG11: =IFERROR(IF(H11=1,IF(盤查結果!$F$6="IPCC第二次評估報告（1995）",VLOOKUP(K11,'Factor Table 1'!$D$75:$P$169,9,FALSE),IF(盤查結果!$F$6="IPCC第三次評估報告(2001)",VLOOKUP(K11,'Factor Table 1'!$D$75:$P$169,10,FALSE),IF(盤查結果!$F$6="IPCC第四次評估報告(2007)",VLOOKUP(K11,'Factor Table 1'!$D$75:$P$169,11,FALSE),IF(盤查結果!$F$6="IPCC第五次評估報告(2013)",VLOOKUP(K11,'Factor Table 1'!$D$75:$P$169,12,FALSE),IF(盤查結果!$F$6="IPCC第六次評估報告(2021)",VLOOKUP(K11,'Factor Table 1'!$D$75:$P$169,13,FALSE),0))))),0),0) -> 0 | AH11: 0 | AI11: =IFERROR(IF(H11=1,IF(盤查結果!$F$6="IPCC第二次評估報告（1995）",VLOOKUP(K11,'Factor Table 1'!$D$172:$P$172,9,FALSE),IF(盤查結果!$F$6="IPCC第三次評估報告(2001)",VLOOKUP(K11,'Factor Table 1'!$D$172:$P$172,10,FALSE),IF(盤查結果!$F$6="IPCC第四次評估報告(2007)",VLOOKUP(K11,'Factor Table 1'!$D$172:$P$172,11,FALSE),IF(盤查結果!$F$6="IPCC第五次評估報告(2013)",VLOOKUP(K11,'Factor Table 1'!$D$172:$P$172,12,FALSE),IF(盤查結果!$F$6="IPCC第六次評估報告(2021)",VLOOKUP(K11,'Factor Table 1'!$D$172:$P$172,13,FALSE),0))))),0),0) -> 0 | AJ11: =IFERROR(IF(H11=1,IF(盤查結果!$F$6="IPCC第二次評估報告（1995）",VLOOKUP(K11,'Factor Table 1'!$D$171:$P$171,9,FALSE),IF(盤查結果!$F$6="IPCC第三次評估報告(2001)",VLOOKUP(K11,'Factor Table 1'!$D$171:$P$171,10,FALSE),IF(盤查結果!$F$6="IPCC第四次評估報告(2007)",VLOOKUP(K11,'Factor Table 1'!$D$171:$P$171,11,FALSE),IF(盤查結果!$F$6="IPCC第五次評估報告(2013)",VLOOKUP(K11,'Factor Table 1'!$D$171:$P$171,12,FALSE),IF(盤查結果!$F$6="IPCC第六次評估報告(2021)",VLOOKUP(K11,'Factor Table 1'!$D$171:$P$171,13,FALSE),0))))),0),0) -> 0 | AK11: =$L11*V11*AD11 -> 0 | AL11: =$L11*W11*AE11 -> 0 | AM11: =$L11*X11*AF11 -> 0 | AN11: =$L11*Y11*AG11 -> 0 | AO11: =$L11*Z11*AH11 -> 0 | AP11: =$L11*AA11*AI11 -> 0 | AQ11: =$L11*AB11*AJ11 -> 0 | AR11: =ROUND(SUM(AK11:AQ11),4) -> 0 | AS11: =AR11/($D$3+$Y$57+$Y$63) -> 0 | AT11: =AS11/($D$3+$D$55) -> 0
G12: =IF(K12<>"","固定燃燒","") | H12: =IF(K12<>"",1,"") | O12: =IF(V12>0.0000000001,"V","") | P12: =IF(W12>0.0000000001,"V","") | Q12: =IF(X12>0.0000000001,"V","") | R12: =IF(Y12>0.0000000001,"V","") | S12: =IF(Z12>0.0000000001,"V","") | T12: =IF(AA12>0.0000000001,"V","") | U12: =IF(AB12>0.0000000001,"V","") | V12: =IFERROR(ROUND(VLOOKUP($K12,'Factor Table 1'!$D$3:$AD$60,11,FALSE),10),0) -> 0 | W12: =IFERROR(ROUND(VLOOKUP($K12,'Factor Table 1'!$D$3:$AD$60,13,FALSE),10),0) -> 0 | X12: =IFERROR(ROUND(VLOOKUP($K12,'Factor Table 1'!$D$3:$AD$60,15,FALSE),10),0) -> 0 | Y12: =IFERROR(IF(OR(K12="CO2",K12="CH4",K12="N2O"),ROUND(VLOOKUP($K12,'Factor Table 1'!$D$3:$AD$69,17,FALSE),10),IFERROR(ROUND(VLOOKUP(J12,'Factor Table 1'!$C$3:$AD$69,18,FALSE),10),ROUND(VLOOKUP(K12,'Factor Table 1'!$D$3:$AD$69,17,FALSE),10))),0) -> 0 | Z12: 0 | AA12: =IFERROR(IF(K12="SF6",1,0),0) -> 0 | AB12: =IFERROR(IF(K12="NF3",1,0),0) -> 0 | AC12: =IFERROR(IF(OR(K12="CO2",K12="CH4",K12="N2O"),VLOOKUP($K12,'Factor Table 1'!$D$3:$AD$69,19,FALSE),IFERROR(VLOOKUP(J12,'Factor Table 1'!$C$3:$AD$69,20,FALSE),VLOOKUP(K12,'Factor Table 1'!$D$3:$AD$69,19,FALSE))),"") | AD12: =IF(H12=1,1,0) -> 0 | AE12: =IF(H12=1,IF(盤查結果!$F$6="IPCC第二次評估報告（1995）",'Factor Table 1'!$L$75,IF(盤查結果!$F$6="IPCC第三次評估報告(2001)",'Factor Table 1'!$M$75,IF(盤查結果!$F$6="IPCC第四次評估報告(2007)",'Factor Table 1'!$N$75,IF(盤查結果!$F$6="IPCC第五次評估報告(2013)",'Factor Table 1'!$O$75,IF(盤查結果!$F$6="IPCC第六次評估報告(2021)",'Factor Table 1'!$P$75,0))))),0) -> 0 | AF12: =IF(H12=1,IF(盤查結果!$F$6="IPCC第二次評估報告（1995）",'Factor Table 1'!$L$76,IF(盤查結果!$F$6="IPCC第三次評估報告(2001)",'Factor Table 1'!$M$76,IF(盤查結果!$F$6="IPCC第四次評估報告(2007)",'Factor Table 1'!$N$76,IF(盤查結果!$F$6="IPCC第五次評估報告(2013)",'Factor Table 1'!$O$76,IF(盤查結果!$F$6="IPCC第六次評估報告(2021)",'Factor Table 1'!$P$76,0))))),0) -> 0 | AG12: =IFERROR(IF(H12=1,IF(盤查結果!$F$6="IPCC第二次評估報告（1995）",VLOOKUP(K12,'Factor Table 1'!$D$75:$P$169,9,FALSE),IF(盤查結果!$F$6="IPCC第三次評估報告(2001)",VLOOKUP(K12,'Factor Table 1'!$D$75:$P$169,10,FALSE),IF(盤查結果!$F$6="IPCC第四次評估報告(2007)",VLOOKUP(K12,'Factor Table 1'!$D$75:$P$169,11,FALSE),IF(盤查結果!$F$6="IPCC第五次評估報告(2013)",VLOOKUP(K12,'Factor Table 1'!$D$75:$P$169,12,FALSE),IF(盤查結果!$F$6="IPCC第六次評估報告(2021)",VLOOKUP(K12,'Factor Table 1'!$D$75:$P$169,13,FALSE),0))))),0),0) -> 0 | AH12: 0 | AI12: =IFERROR(IF(H12=1,IF(盤查結果!$F$6="IPCC第二次評估報告（1995）",VLOOKUP(K12,'Factor Table 1'!$D$172:$P$172,9,FALSE),IF(盤查結果!$F$6="IPCC第三次評估報告(2001)",VLOOKUP(K12,'Factor Table 1'!$D$172:$P$172,10,FALSE),IF(盤查結果!$F$6="IPCC第四次評估報告(2007)",VLOOKUP(K12,'Factor Table 1'!$D$172:$P$172,11,FALSE),IF(盤查結果!$F$6="IPCC第五次評估報告(2013)",VLOOKUP(K12,'Factor Table 1'!$D$172:$P$172,12,FALSE),IF(盤查結果!$F$6="IPCC第六次評估報告(2021)",VLOOKUP(K12,'Factor Table 1'!$D$172:$P$172,13,FALSE),0))))),0),0) -> 0 | AJ12: =IFERROR(IF(H12=1,IF(盤查結果!$F$6="IPCC第二次評估報告（1995）",VLOOKUP(K12,'Factor Table 1'!$D$171:$P$171,9,FALSE),IF(盤查結果!$F$6="IPCC第三次評估報告(2001)",VLOOKUP(K12,'Factor Table 1'!$D$171:$P$171,10,FALSE),IF(盤查結果!$F$6="IPCC第四次評估報告(2007)",VLOOKUP(K12,'Factor Table 1'!$D$171:$P$171,11,FALSE),IF(盤查結果!$F$6="IPCC第五次評估報告(2013)",VLOOKUP(K12,'Factor Table 1'!$D$171:$P$171,12,FALSE),IF(盤查結果!$F$6="IPCC第六次評估報告(2021)",VLOOKUP(K12,'Factor Table 1'!$D$171:$P$171,13,FALSE),0))))),0),0) -> 0 | AK12: =$L12*V12*AD12 -> 0 | AL12: =$L12*W12*AE12 -> 0 | AM12: =$L12*X12*AF12 -> 0 | AN12: =$L12*Y12*AG12 -> 0 | AO12: =$L12*Z12*AH12 -> 0 | AP12: =$L12*AA12*AI12 -> 0 | AQ12: =$L12*AB12*AJ12 -> 0 | AR12: =ROUND(SUM(AK12:AQ12),4) -> 0 | AS12: =AR12/($D$3+$Y$57+$Y$63) -> 0 | AT12: =AS12/($D$3+$D$55) -> 0
G13: =IF(K13<>"","固定燃燒","") | H13: =IF(K13<>"",1,"") | O13: =IF(V13>0.0000000001,"V","") | P13: =IF(W13>0.0000000001,"V","") | Q13: =IF(X13>0.0000000001,"V","") | R13: =IF(Y13>0.0000000001,"V","") | S13: =IF(Z13>0.0000000001,"V","") | T13: =IF(AA13>0.0000000001,"V","") | U13: =IF(AB13>0.0000000001,"V","") | V13: =IFERROR(ROUND(VLOOKUP($K13,'Factor Table 1'!$D$3:$AD$60,11,FALSE),10),0) -> 0 | W13: =IFERROR(ROUND(VLOOKUP($K13,'Factor Table 1'!$D$3:$AD$60,13,FALSE),10),0) -> 0 | X13: =IFERROR(ROUND(VLOOKUP($K13,'Factor Table 1'!$D$3:$AD$60,15,FALSE),10),0) -> 0 | Y13: =IFERROR(IF(OR(K13="CO2",K13="CH4",K13="N2O"),ROUND(VLOOKUP($K13,'Factor Table 1'!$D$3:$AD$69,17,FALSE),10),IFERROR(ROUND(VLOOKUP(J13,'Factor Table 1'!$C$3:$AD$69,18,FALSE),10),ROUND(VLOOKUP(K13,'Factor Table 1'!$D$3:$AD$69,17,FALSE),10))),0) -> 0 | Z13: 0 | AA13: =IFERROR(IF(K13="SF6",1,0),0) -> 0 | AB13: =IFERROR(IF(K13="NF3",1,0),0) -> 0 | AC13: =IFERROR(IF(OR(K13="CO2",K13="CH4",K13="N2O"),VLOOKUP($K13,'Factor Table 1'!$D$3:$AD$69,19,FALSE),IFERROR(VLOOKUP(J13,'Factor Table 1'!$C$3:$AD$69,20,FALSE),VLOOKUP(K13,'Factor Table 1'!$D$3:$AD$69,19,FALSE))),"") | AD13: =IF(H13=1,1,0) -> 0 | AE13: =IF(H13=1,IF(盤查結果!$F$6="IPCC第二次評估報告（1995）",'Factor Table 1'!$L$75,IF(盤查結果!$F$6="IPCC第三次評估報告(2001)",'Factor Table 1'!$M$75,IF(盤查結果!$F$6="IPCC第四次評估報告(2007)",'Factor Table 1'!$N$75,IF(盤查結果!$F$6="IPCC第五次評估報告(2013)",'Factor Table 1'!$O$75,IF(盤查結果!$F$6="IPCC第六次評估報告(2021)",'Factor Table 1'!$P$75,0))))),0) -> 0 | AF13: =IF(H13=1,IF(盤查結果!$F$6="IPCC第二次評估報告（1995）",'Factor Table 1'!$L$76,IF(盤查結果!$F$6="IPCC第三次評估報告(2001)",'Factor Table 1'!$M$76,IF(盤查結果!$F$6="IPCC第四次評估報告(2007)",'Factor Table 1'!$N$76,IF(盤查結果!$F$6="IPCC第五次評估報告(2013)",'Factor Table 1'!$O$76,IF(盤查結果!$F$6="IPCC第六次評估報告(2021)",'Factor Table 1'!$P$76,0))))),0) -> 0 | AG13: =IFERROR(IF(H13=1,IF(盤查結果!$F$6="IPCC第二次評估報告（1995）",VLOOKUP(K13,'Factor Table 1'!$D$75:$P$169,9,FALSE),IF(盤查結果!$F$6="IPCC第三次評估報告(2001)",VLOOKUP(K13,'Factor Table 1'!$D$75:$P$169,10,FALSE),IF(盤查結果!$F$6="IPCC第四次評估報告(2007)",VLOOKUP(K13,'Factor Table 1'!$D$75:$P$169,11,FALSE),IF(盤查結果!$F$6="IPCC第五次評估報告(2013)",VLOOKUP(K13,'Factor Table 1'!$D$75:$P$169,12,FALSE),IF(盤查結果!$F$6="IPCC第六次評估報告(2021)",VLOOKUP(K13,'Factor Table 1'!$D$75:$P$169,13,FALSE),0))))),0),0) -> 0 | AH13: 0 | AI13: =IFERROR(IF(H13=1,IF(盤查結果!$F$6="IPCC第二次評估報告（1995）",VLOOKUP(K13,'Factor Table 1'!$D$172:$P$172,9,FALSE),IF(盤查結果!$F$6="IPCC第三次評估報告(2001)",VLOOKUP(K13,'Factor Table 1'!$D$172:$P$172,10,FALSE),IF(盤查結果!$F$6="IPCC第四次評估報告(2007)",VLOOKUP(K13,'Factor Table 1'!$D$172:$P$172,11,FALSE),IF(盤查結果!$F$6="IPCC第五次評估報告(2013)",VLOOKUP(K13,'Factor Table 1'!$D$172:$P$172,12,FALSE),IF(盤查結果!$F$6="IPCC第六次評估報告(2021)",VLOOKUP(K13,'Factor Table 1'!$D$172:$P$172,13,FALSE),0))))),0),0) -> 0 | AJ13: =IFERROR(IF(H13=1,IF(盤查結果!$F$6="IPCC第二次評估報告（1995）",VLOOKUP(K13,'Factor Table 1'!$D$171:$P$171,9,FALSE),IF(盤查結果!$F$6="IPCC第三次評估報告(2001)",VLOOKUP(K13,'Factor Table 1'!$D$171:$P$171,10,FALSE),IF(盤查結果!$F$6="IPCC第四次評估報告(2007)",VLOOKUP(K13,'Factor Table 1'!$D$171:$P$171,11,FALSE),IF(盤查結果!$F$6="IPCC第五次評估報告(2013)",VLOOKUP(K13,'Factor Table 1'!$D$171:$P$171,12,FALSE),IF(盤查結果!$F$6="IPCC第六次評估報告(2021)",VLOOKUP(K13,'Factor Table 1'!$D$171:$P$171,13,FALSE),0))))),0),0) -> 0 | AK13: =$L13*V13*AD13 -> 0 | AL13: =$L13*W13*AE13 -> 0 | AM13: =$L13*X13*AF13 -> 0 | AN13: =$L13*Y13*AG13 -> 0 | AO13: =$L13*Z13*AH13 -> 0 | AP13: =$L13*AA13*AI13 -> 0 | AQ13: =$L13*AB13*AJ13 -> 0 | AR13: =ROUND(SUM(AK13:AQ13),4) -> 0 | AS13: =AR13/($D$3+$Y$57+$Y$63) -> 0 | AT13: =AS13/($D$3+$D$55) -> 0
G14: =IF(K14<>"","固定燃燒","") | H14: =IF(K14<>"",1,"") | O14: =IF(V14>0.0000000001,"V","") | P14: =IF(W14>0.0000000001,"V","") | Q14: =IF(X14>0.0000000001,"V","") | R14: =IF(Y14>0.0000000001,"V","") | S14: =IF(Z14>0.0000000001,"V","") | T14: =IF(AA14>0.0000000001,"V","") | U14: =IF(AB14>0.0000000001,"V","") | V14: =IFERROR(ROUND(VLOOKUP($K14,'Factor Table 1'!$D$3:$AD$60,11,FALSE),10),0) -> 0 | W14: =IFERROR(ROUND(VLOOKUP($K14,'Factor Table 1'!$D$3:$AD$60,13,FALSE),10),0) -> 0 | X14: =IFERROR(ROUND(VLOOKUP($K14,'Factor Table 1'!$D$3:$AD$60,15,FALSE),10),0) -> 0 | Y14: =IFERROR(IF(OR(K14="CO2",K14="CH4",K14="N2O"),ROUND(VLOOKUP($K14,'Factor Table 1'!$D$3:$AD$69,17,FALSE),10),IFERROR(ROUND(VLOOKUP(J14,'Factor Table 1'!$C$3:$AD$69,18,FALSE),10),ROUND(VLOOKUP(K14,'Factor Table 1'!$D$3:$AD$69,17,FALSE),10))),0) -> 0 | Z14: 0 | AA14: =IFERROR(IF(K14="SF6",1,0),0) -> 0 | AB14: =IFERROR(IF(K14="NF3",1,0),0) -> 0 | AC14: =IFERROR(IF(OR(K14="CO2",K14="CH4",K14="N2O"),VLOOKUP($K14,'Factor Table 1'!$D$3:$AD$69,19,FALSE),IFERROR(VLOOKUP(J14,'Factor Table 1'!$C$3:$AD$69,20,FALSE),VLOOKUP(K14,'Factor Table 1'!$D$3:$AD$69,19,FALSE))),"") | AD14: =IF(H14=1,1,0) -> 0 | AE14: =IF(H14=1,IF(盤查結果!$F$6="IPCC第二次評估報告（1995）",'Factor Table 1'!$L$75,IF(盤查結果!$F$6="IPCC第三次評估報告(2001)",'Factor Table 1'!$M$75,IF(盤查結果!$F$6="IPCC第四次評估報告(2007)",'Factor Table 1'!$N$75,IF(盤查結果!$F$6="IPCC第五次評估報告(2013)",'Factor Table 1'!$O$75,IF(盤查結果!$F$6="IPCC第六次評估報告(2021)",'Factor Table 1'!$P$75,0))))),0) -> 0 | AF14: =IF(H14=1,IF(盤查結果!$F$6="IPCC第二次評估報告（1995）",'Factor Table 1'!$L$76,IF(盤查結果!$F$6="IPCC第三次評估報告(2001)",'Factor Table 1'!$M$76,IF(盤查結果!$F$6="IPCC第四次評估報告(2007)",'Factor Table 1'!$N$76,IF(盤查結果!$F$6="IPCC第五次評估報告(2013)",'Factor Table 1'!$O$76,IF(盤查結果!$F$6="IPCC第六次評估報告(2021)",'Factor Table 1'!$P$76,0))))),0) -> 0 | AG14: =IFERROR(IF(H14=1,IF(盤查結果!$F$6="IPCC第二次評估報告（1995）",VLOOKUP(K14,'Factor Table 1'!$D$75:$P$169,9,FALSE),IF(盤查結果!$F$6="IPCC第三次評估報告(2001)",VLOOKUP(K14,'Factor Table 1'!$D$75:$P$169,10,FALSE),IF(盤查結果!$F$6="IPCC第四次評估報告(2007)",VLOOKUP(K14,'Factor Table 1'!$D$75:$P$169,11,FALSE),IF(盤查結果!$F$6="IPCC第五次評估報告(2013)",VLOOKUP(K14,'Factor Table 1'!$D$75:$P$169,12,FALSE),IF(盤查結果!$F$6="IPCC第六次評估報告(2021)",VLOOKUP(K14,'Factor Table 1'!$D$75:$P$169,13,FALSE),0))))),0),0) -> 0 | AH14: 0 | AI14: =IFERROR(IF(H14=1,IF(盤查結果!$F$6="IPCC第二次評估報告（1995）",VLOOKUP(K14,'Factor Table 1'!$D$172:$P$172,9,FALSE),IF(盤查結果!$F$6="IPCC第三次評估報告(2001)",VLOOKUP(K14,'Factor Table 1'!$D$172:$P$172,10,FALSE),IF(盤查結果!$F$6="IPCC第四次評估報告(2007)",VLOOKUP(K14,'Factor Table 1'!$D$172:$P$172,11,FALSE),IF(盤查結果!$F$6="IPCC第五次評估報告(2013)",VLOOKUP(K14,'Factor Table 1'!$D$172:$P$172,12,FALSE),IF(盤查結果!$F$6="IPCC第六次評估報告(2021)",VLOOKUP(K14,'Factor Table 1'!$D$172:$P$172,13,FALSE),0))))),0),0) -> 0 | AJ14: =IFERROR(IF(H14=1,IF(盤查結果!$F$6="IPCC第二次評估報告（1995）",VLOOKUP(K14,'Factor Table 1'!$D$171:$P$171,9,FALSE),IF(盤查結果!$F$6="IPCC第三次評估報告(2001)",VLOOKUP(K14,'Factor Table 1'!$D$171:$P$171,10,FALSE),IF(盤查結果!$F$6="IPCC第四次評估報告(2007)",VLOOKUP(K14,'Factor Table 1'!$D$171:$P$171,11,FALSE),IF(盤查結果!$F$6="IPCC第五次評估報告(2013)",VLOOKUP(K14,'Factor Table 1'!$D$171:$P$171,12,FALSE),IF(盤查結果!$F$6="IPCC第六次評估報告(2021)",VLOOKUP(K14,'Factor Table 1'!$D$171:$P$171,13,FALSE),0))))),0),0) -> 0 | AK14: =$L14*V14*AD14 -> 0 | AL14: =$L14*W14*AE14 -> 0 | AM14: =$L14*X14*AF14 -> 0 | AN14: =$L14*Y14*AG14 -> 0 | AO14: =$L14*Z14*AH14 -> 0 | AP14: =$L14*AA14*AI14 -> 0 | AQ14: =$L14*AB14*AJ14 -> 0 | AR14: =ROUND(SUM(AK14:AQ14),4) -> 0 | AS14: =AR14/($D$3+$Y$57+$Y$63) -> 0 | AT14: =AS14/($D$3+$D$55) -> 0
G15: =IF(K15<>"","固定燃燒","") | H15: =IF(K15<>"",1,"") | O15: =IF(V15>0.0000000001,"V","") | P15: =IF(W15>0.0000000001,"V","") | Q15: =IF(X15>0.0000000001,"V","") | R15: =IF(Y15>0.0000000001,"V","") | S15: =IF(Z15>0.0000000001,"V","") | T15: =IF(AA15>0.0000000001,"V","") | U15: =IF(AB15>0.0000000001,"V","") | V15: =IFERROR(ROUND(VLOOKUP($K15,'Factor Table 1'!$D$3:$AD$60,11,FALSE),10),0) -> 0 | W15: =IFERROR(ROUND(VLOOKUP($K15,'Factor Table 1'!$D$3:$AD$60,13,FALSE),10),0) -> 0 | X15: =IFERROR(ROUND(VLOOKUP($K15,'Factor Table 1'!$D$3:$AD$60,15,FALSE),10),0) -> 0 | Y15: =IFERROR(IF(OR(K15="CO2",K15="CH4",K15="N2O"),ROUND(VLOOKUP($K15,'Factor Table 1'!$D$3:$AD$69,17,FALSE),10),IFERROR(ROUND(VLOOKUP(J15,'Factor Table 1'!$C$3:$AD$69,18,FALSE),10),ROUND(VLOOKUP(K15,'Factor Table 1'!$D$3:$AD$69,17,FALSE),10))),0) -> 0 | Z15: 0 | AA15: =IFERROR(IF(K15="SF6",1,0),0) -> 0 | AB15: =IFERROR(IF(K15="NF3",1,0),0) -> 0 | AC15: =IFERROR(IF(OR(K15="CO2",K15="CH4",K15="N2O"),VLOOKUP($K15,'Factor Table 1'!$D$3:$AD$69,19,FALSE),IFERROR(VLOOKUP(J15,'Factor Table 1'!$C$3:$AD$69,20,FALSE),VLOOKUP(K15,'Factor Table 1'!$D$3:$AD$69,19,FALSE))),"") | AD15: =IF(H15=1,1,0) -> 0 | AE15: =IF(H15=1,IF(盤查結果!$F$6="IPCC第二次評估報告（1995）",'Factor Table 1'!$L$75,IF(盤查結果!$F$6="IPCC第三次評估報告(2001)",'Factor Table 1'!$M$75,IF(盤查結果!$F$6="IPCC第四次評估報告(2007)",'Factor Table 1'!$N$75,IF(盤查結果!$F$6="IPCC第五次評估報告(2013)",'Factor Table 1'!$O$75,IF(盤查結果!$F$6="IPCC第六次評估報告(2021)",'Factor Table 1'!$P$75,0))))),0) -> 0 | AF15: =IF(H15=1,IF(盤查結果!$F$6="IPCC第二次評估報告（1995）",'Factor Table 1'!$L$76,IF(盤查結果!$F$6="IPCC第三次評估報告(2001)",'Factor Table 1'!$M$76,IF(盤查結果!$F$6="IPCC第四次評估報告(2007)",'Factor Table 1'!$N$76,IF(盤查結果!$F$6="IPCC第五次評估報告(2013)",'Factor Table 1'!$O$76,IF(盤查結果!$F$6="IPCC第六次評估報告(2021)",'Factor Table 1'!$P$76,0))))),0) -> 0 | AG15: =IFERROR(IF(H15=1,IF(盤查結果!$F$6="IPCC第二次評估報告（1995）",VLOOKUP(K15,'Factor Table 1'!$D$75:$P$169,9,FALSE),IF(盤查結果!$F$6="IPCC第三次評估報告(2001)",VLOOKUP(K15,'Factor Table 1'!$D$75:$P$169,10,FALSE),IF(盤查結果!$F$6="IPCC第四次評估報告(2007)",VLOOKUP(K15,'Factor Table 1'!$D$75:$P$169,11,FALSE),IF(盤查結果!$F$6="IPCC第五次評估報告(2013)",VLOOKUP(K15,'Factor Table 1'!$D$75:$P$169,12,FALSE),IF(盤查結果!$F$6="IPCC第六次評估報告(2021)",VLOOKUP(K15,'Factor Table 1'!$D$75:$P$169,13,FALSE),0))))),0),0) -> 0 | AH15: 0 | AI15: =IFERROR(IF(H15=1,IF(盤查結果!$F$6="IPCC第二次評估報告（1995）",VLOOKUP(K15,'Factor Table 1'!$D$172:$P$172,9,FALSE),IF(盤查結果!$F$6="IPCC第三次評估報告(2001)",VLOOKUP(K15,'Factor Table 1'!$D$172:$P$172,10,FALSE),IF(盤查結果!$F$6="IPCC第四次評估報告(2007)",VLOOKUP(K15,'Factor Table 1'!$D$172:$P$172,11,FALSE),IF(盤查結果!$F$6="IPCC第五次評估報告(2013)",VLOOKUP(K15,'Factor Table 1'!$D$172:$P$172,12,FALSE),IF(盤查結果!$F$6="IPCC第六次評估報告(2021)",VLOOKUP(K15,'Factor Table 1'!$D$172:$P$172,13,FALSE),0))))),0),0) -> 0 | AJ15: =IFERROR(IF(H15=1,IF(盤查結果!$F$6="IPCC第二次評估報告（1995）",VLOOKUP(K15,'Factor Table 1'!$D$171:$P$171,9,FALSE),IF(盤查結果!$F$6="IPCC第三次評估報告(2001)",VLOOKUP(K15,'Factor Table 1'!$D$171:$P$171,10,FALSE),IF(盤查結果!$F$6="IPCC第四次評估報告(2007)",VLOOKUP(K15,'Factor Table 1'!$D$171:$P$171,11,FALSE),IF(盤查結果!$F$6="IPCC第五次評估報告(2013)",VLOOKUP(K15,'Factor Table 1'!$D$171:$P$171,12,FALSE),IF(盤查結果!$F$6="IPCC第六次評估報告(2021)",VLOOKUP(K15,'Factor Table 1'!$D$171:$P$171,13,FALSE),0))))),0),0) -> 0 | AK15: =$L15*V15*AD15 -> 0 | AL15: =$L15*W15*AE15 -> 0 | AM15: =$L15*X15*AF15 -> 0 | AN15: =$L15*Y15*AG15 -> 0 | AO15: =$L15*Z15*AH15 -> 0 | AP15: =$L15*AA15*AI15 -> 0 | AQ15: =$L15*AB15*AJ15 -> 0 | AR15: =ROUND(SUM(AK15:AQ15),4) -> 0 | AS15: =AR15/($D$3+$Y$57+$Y$63) -> 0 | AT15: =AS15/($D$3+$D$55) -> 0
B16: 1.2 | C16: 移動燃燒直接排放 | G16: =IF(K16<>"","移動燃燒","") | H16: =IF(K16<>"",1,"") | I16: =IF(COUNTA(K16:K22)>0,"有","無") -> 無 | O16: =IF(V16>0.0000000001,"V","") | P16: =IF(W16>0.0000000001,"V","") | Q16: =IF(X16>0.0000000001,"V","") | R16: =IF(Y16>0.0000000001,"V","") | S16: =IF(Z16>0.0000000001,"V","") | T16: =IF(AA16>0.0000000001,"V","") | U16: =IF(AB16>0.0000000001,"V","") | V16: =IFERROR(ROUND(VLOOKUP($K16,'Factor Table 1'!$D$3:$AD$60,11,FALSE),10),0) -> 0 | W16: =IFERROR(ROUND(VLOOKUP($K16,'Factor Table 1'!$D$3:$AD$60,13,FALSE),10),0) -> 0 | X16: =IFERROR(ROUND(VLOOKUP($K16,'Factor Table 1'!$D$3:$AD$60,15,FALSE),10),0) -> 0 | Y16: =IFERROR(IF(OR(K16="CO2",K16="CH4",K16="N2O"),ROUND(VLOOKUP($K16,'Factor Table 1'!$D$3:$AD$69,17,FALSE),10),IFERROR(ROUND(VLOOKUP(J16,'Factor Table 1'!$C$3:$AD$69,18,FALSE),10),ROUND(VLOOKUP(K16,'Factor Table 1'!$D$3:$AD$69,17,FALSE),10))),0) -> 0 | Z16: 0 | AA16: =IFERROR(IF(K16="SF6",1,0),0) -> 0 | AB16: =IFERROR(IF(K16="NF3",1,0),0) -> 0 | AC16: =IFERROR(IF(OR(K16="CO2",K16="CH4",K16="N2O"),VLOOKUP($K16,'Factor Table 1'!$D$3:$AD$69,19,FALSE),IFERROR(VLOOKUP(J16,'Factor Table 1'!$C$3:$AD$69,20,FALSE),VLOOKUP(K16,'Factor Table 1'!$D$3:$AD$69,19,FALSE))),"") | AD16: =IF(H16=1,1,0) -> 0 | AE16: =IF(H16=1,IF(盤查結果!$F$6="IPCC第二次評估報告（1995）",'Factor Table 1'!$L$75,IF(盤查結果!$F$6="IPCC第三次評估報告(2001)",'Factor Table 1'!$M$75,IF(盤查結果!$F$6="IPCC第四次評估報告(2007)",'Factor Table 1'!$N$75,IF(盤查結果!$F$6="IPCC第五次評估報告(2013)",'Factor Table 1'!$O$75,IF(盤查結果!$F$6="IPCC第六次評估報告(2021)",'Factor Table 1'!$P$75,0))))),0) -> 0 | AF16: =IF(H16=1,IF(盤查結果!$F$6="IPCC第二次評估報告（1995）",'Factor Table 1'!$L$76,IF(盤查結果!$F$6="IPCC第三次評估報告(2001)",'Factor Table 1'!$M$76,IF(盤查結果!$F$6="IPCC第四次評估報告(2007)",'Factor Table 1'!$N$76,IF(盤查結果!$F$6="IPCC第五次評估報告(2013)",'Factor Table 1'!$O$76,IF(盤查結果!$F$6="IPCC第六次評估報告(2021)",'Factor Table 1'!$P$76,0))))),0) -> 0 | AG16: =IFERROR(IF(H16=1,IF(盤查結果!$F$6="IPCC第二次評估報告（1995）",VLOOKUP(K16,'Factor Table 1'!$D$75:$P$169,9,FALSE),IF(盤查結果!$F$6="IPCC第三次評估報告(2001)",VLOOKUP(K16,'Factor Table 1'!$D$75:$P$169,10,FALSE),IF(盤查結果!$F$6="IPCC第四次評估報告(2007)",VLOOKUP(K16,'Factor Table 1'!$D$75:$P$169,11,FALSE),IF(盤查結果!$F$6="IPCC第五次評估報告(2013)",VLOOKUP(K16,'Factor Table 1'!$D$75:$P$169,12,FALSE),IF(盤查結果!$F$6="IPCC第六次評估報告(2021)",VLOOKUP(K16,'Factor Table 1'!$D$75:$P$169,13,FALSE),0))))),0),0) -> 0 | AH16: 0 | AI16: =IFERROR(IF(H16=1,IF(盤查結果!$F$6="IPCC第二次評估報告（1995）",VLOOKUP(K16,'Factor Table 1'!$D$172:$P$172,9,FALSE),IF(盤查結果!$F$6="IPCC第三次評估報告(2001)",VLOOKUP(K16,'Factor Table 1'!$D$172:$P$172,10,FALSE),IF(盤查結果!$F$6="IPCC第四次評估報告(2007)",VLOOKUP(K16,'Factor Table 1'!$D$172:$P$172,11,FALSE),IF(盤查結果!$F$6="IPCC第五次評估報告(2013)",VLOOKUP(K16,'Factor Table 1'!$D$172:$P$172,12,FALSE),IF(盤查結果!$F$6="IPCC第六次評估報告(2021)",VLOOKUP(K16,'Factor Table 1'!$D$172:$P$172,13,FALSE),0))))),0),0) -> 0 | AJ16: =IFERROR(IF(H16=1,IF(盤查結果!$F$6="IPCC第二次評估報告（1995）",VLOOKUP(K16,'Factor Table 1'!$D$171:$P$171,9,FALSE),IF(盤查結果!$F$6="IPCC第三次評估報告(2001)",VLOOKUP(K16,'Factor Table 1'!$D$171:$P$171,10,FALSE),IF(盤查結果!$F$6="IPCC第四次評估報告(2007)",VLOOKUP(K16,'Factor Table 1'!$D$171:$P$171,11,FALSE),IF(盤查結果!$F$6="IPCC第五次評估報告(2013)",VLOOKUP(K16,'Factor Table 1'!$D$171:$P$171,12,FALSE),IF(盤查結果!$F$6="IPCC第六次評估報告(2021)",VLOOKUP(K16,'Factor Table 1'!$D$171:$P$171,13,FALSE),0))))),0),0) -> 0 | AK16: =$L16*V16*AD16 -> 0 | AL16: =$L16*W16*AE16 -> 0 | AM16: =$L16*X16*AF16 -> 0 | AN16: =$L16*Y16*AG16 -> 0 | AO16: =$L16*Z16*AH16 -> 0 | AP16: =$L16*AA16*AI16 -> 0 | AQ16: =$L16*AB16*AJ16 -> 0 | AR16: =ROUND(SUM(AK16:AQ16),4) -> 0 | AS16: =AR16/($D$3+$Y$57+$Y$63) -> 0 | AT16: =AS16/($D$3+$D$55) -> 0
G17: =IF(K17<>"","移動燃燒","") | H17: =IF(K17<>"",1,"") | O17: =IF(V17>0.0000000001,"V","") | P17: =IF(W17>0.0000000001,"V","") | Q17: =IF(X17>0.0000000001,"V","") | R17: =IF(Y17>0.0000000001,"V","") | S17: =IF(Z17>0.0000000001,"V","") | T17: =IF(AA17>0.0000000001,"V","") | U17: =IF(AB17>0.0000000001,"V","") | V17: =IFERROR(ROUND(VLOOKUP($K17,'Factor Table 1'!$D$3:$AD$60,11,FALSE),10),0) -> 0 | W17: =IFERROR(ROUND(VLOOKUP($K17,'Factor Table 1'!$D$3:$AD$60,13,FALSE),10),0) -> 0 | X17: =IFERROR(ROUND(VLOOKUP($K17,'Factor Table 1'!$D$3:$AD$60,15,FALSE),10),0) -> 0 | Y17: =IFERROR(IF(OR(K17="CO2",K17="CH4",K17="N2O"),ROUND(VLOOKUP($K17,'Factor Table 1'!$D$3:$AD$69,17,FALSE),10),IFERROR(ROUND(VLOOKUP(J17,'Factor Table 1'!$C$3:$AD$69,18,FALSE),10),ROUND(VLOOKUP(K17,'Factor Table 1'!$D$3:$AD$69,17,FALSE),10))),0) -> 0 | Z17: 0 | AA17: =IFERROR(IF(K17="SF6",1,0),0) -> 0 | AB17: =IFERROR(IF(K17="NF3",1,0),0) -> 0 | AC17: =IFERROR(IF(OR(K17="CO2",K17="CH4",K17="N2O"),VLOOKUP($K17,'Factor Table 1'!$D$3:$AD$69,19,FALSE),IFERROR(VLOOKUP(J17,'Factor Table 1'!$C$3:$AD$69,20,FALSE),VLOOKUP(K17,'Factor Table 1'!$D$3:$AD$69,19,FALSE))),"") | AD17: =IF(H17=1,1,0) -> 0 | AE17: =IF(H17=1,IF(盤查結果!$F$6="IPCC第二次評估報告（1995）",'Factor Table 1'!$L$75,IF(盤查結果!$F$6="IPCC第三次評估報告(2001)",'Factor Table 1'!$M$75,IF(盤查結果!$F$6="IPCC第四次評估報告(2007)",'Factor Table 1'!$N$75,IF(盤查結果!$F$6="IPCC第五次評估報告(2013)",'Factor Table 1'!$O$75,IF(盤查結果!$F$6="IPCC第六次評估報告(2021)",'Factor Table 1'!$P$75,0))))),0) -> 0 | AF17: =IF(H17=1,IF(盤查結果!$F$6="IPCC第二次評估報告（1995）",'Factor Table 1'!$L$76,IF(盤查結果!$F$6="IPCC第三次評估報告(2001)",'Factor Table 1'!$M$76,IF(盤查結果!$F$6="IPCC第四次評估報告(2007)",'Factor Table 1'!$N$76,IF(盤查結果!$F$6="IPCC第五次評估報告(2013)",'Factor Table 1'!$O$76,IF(盤查結果!$F$6="IPCC第六次評估報告(2021)",'Factor Table 1'!$P$76,0))))),0) -> 0 | AG17: =IFERROR(IF(H17=1,IF(盤查結果!$F$6="IPCC第二次評估報告（1995）",VLOOKUP(K17,'Factor Table 1'!$D$75:$P$169,9,FALSE),IF(盤查結果!$F$6="IPCC第三次評估報告(2001)",VLOOKUP(K17,'Factor Table 1'!$D$75:$P$169,10,FALSE),IF(盤查結果!$F$6="IPCC第四次評估報告(2007)",VLOOKUP(K17,'Factor Table 1'!$D$75:$P$169,11,FALSE),IF(盤查結果!$F$6="IPCC第五次評估報告(2013)",VLOOKUP(K17,'Factor Table 1'!$D$75:$P$169,12,FALSE),IF(盤查結果!$F$6="IPCC第六次評估報告(2021)",VLOOKUP(K17,'Factor Table 1'!$D$75:$P$169,13,FALSE),0))))),0),0) -> 0 | AH17: 0 | AI17: =IFERROR(IF(H17=1,IF(盤查結果!$F$6="IPCC第二次評估報告（1995）",VLOOKUP(K17,'Factor Table 1'!$D$172:$P$172,9,FALSE),IF(盤查結果!$F$6="IPCC第三次評估報告(2001)",VLOOKUP(K17,'Factor Table 1'!$D$172:$P$172,10,FALSE),IF(盤查結果!$F$6="IPCC第四次評估報告(2007)",VLOOKUP(K17,'Factor Table 1'!$D$172:$P$172,11,FALSE),IF(盤查結果!$F$6="IPCC第五次評估報告(2013)",VLOOKUP(K17,'Factor Table 1'!$D$172:$P$172,12,FALSE),IF(盤查結果!$F$6="IPCC第六次評估報告(2021)",VLOOKUP(K17,'Factor Table 1'!$D$172:$P$172,13,FALSE),0))))),0),0) -> 0 | AJ17: =IFERROR(IF(H17=1,IF(盤查結果!$F$6="IPCC第二次評估報告（1995）",VLOOKUP(K17,'Factor Table 1'!$D$171:$P$171,9,FALSE),IF(盤查結果!$F$6="IPCC第三次評估報告(2001)",VLOOKUP(K17,'Factor Table 1'!$D$171:$P$171,10,FALSE),IF(盤查結果!$F$6="IPCC第四次評估報告(2007)",VLOOKUP(K17,'Factor Table 1'!$D$171:$P$171,11,FALSE),IF(盤查結果!$F$6="IPCC第五次評估報告(2013)",VLOOKUP(K17,'Factor Table 1'!$D$171:$P$171,12,FALSE),IF(盤查結果!$F$6="IPCC第六次評估報告(2021)",VLOOKUP(K17,'Factor Table 1'!$D$171:$P$171,13,FALSE),0))))),0),0) -> 0 | AK17: =$L17*V17*AD17 -> 0 | AL17: =$L17*W17*AE17 -> 0 | AM17: =$L17*X17*AF17 -> 0 | AN17: =$L17*Y17*AG17 -> 0 | AO17: =$L17*Z17*AH17 -> 0 | AP17: =$L17*AA17*AI17 -> 0 | AQ17: =$L17*AB17*AJ17 -> 0 | AR17: =ROUND(SUM(AK17:AQ17),4) -> 0 | AS17: =AR17/($D$3+$Y$57+$Y$63) -> 0 | AT17: =AS17/($D$3+$D$55) -> 0
G18: =IF(K18<>"","移動燃燒","") | H18: =IF(K18<>"",1,"") | O18: =IF(V18>0.0000000001,"V","") | P18: =IF(W18>0.0000000001,"V","") | Q18: =IF(X18>0.0000000001,"V","") | R18: =IF(Y18>0.0000000001,"V","") | S18: =IF(Z18>0.0000000001,"V","") | T18: =IF(AA18>0.0000000001,"V","") | U18: =IF(AB18>0.0000000001,"V","") | V18: =IFERROR(ROUND(VLOOKUP($K18,'Factor Table 1'!$D$3:$AD$60,11,FALSE),10),0) -> 0 | W18: =IFERROR(ROUND(VLOOKUP($K18,'Factor Table 1'!$D$3:$AD$60,13,FALSE),10),0) -> 0 | X18: =IFERROR(ROUND(VLOOKUP($K18,'Factor Table 1'!$D$3:$AD$60,15,FALSE),10),0) -> 0 | Y18: =IFERROR(IF(OR(K18="CO2",K18="CH4",K18="N2O"),ROUND(VLOOKUP($K18,'Factor Table 1'!$D$3:$AD$69,17,FALSE),10),IFERROR(ROUND(VLOOKUP(J18,'Factor Table 1'!$C$3:$AD$69,18,FALSE),10),ROUND(VLOOKUP(K18,'Factor Table 1'!$D$3:$AD$69,17,FALSE),10))),0) -> 0 | Z18: 0 | AA18: =IFERROR(IF(K18="SF6",1,0),0) -> 0 | AB18: =IFERROR(IF(K18="NF3",1,0),0) -> 0 | AC18: =IFERROR(IF(OR(K18="CO2",K18="CH4",K18="N2O"),VLOOKUP($K18,'Factor Table 1'!$D$3:$AD$69,19,FALSE),IFERROR(VLOOKUP(J18,'Factor Table 1'!$C$3:$AD$69,20,FALSE),VLOOKUP(K18,'Factor Table 1'!$D$3:$AD$69,19,FALSE))),"") | AD18: =IF(H18=1,1,0) -> 0 | AE18: =IF(H18=1,IF(盤查結果!$F$6="IPCC第二次評估報告（1995）",'Factor Table 1'!$L$75,IF(盤查結果!$F$6="IPCC第三次評估報告(2001)",'Factor Table 1'!$M$75,IF(盤查結果!$F$6="IPCC第四次評估報告(2007)",'Factor Table 1'!$N$75,IF(盤查結果!$F$6="IPCC第五次評估報告(2013)",'Factor Table 1'!$O$75,IF(盤查結果!$F$6="IPCC第六次評估報告(2021)",'Factor Table 1'!$P$75,0))))),0) -> 0 | AF18: =IF(H18=1,IF(盤查結果!$F$6="IPCC第二次評估報告（1995）",'Factor Table 1'!$L$76,IF(盤查結果!$F$6="IPCC第三次評估報告(2001)",'Factor Table 1'!$M$76,IF(盤查結果!$F$6="IPCC第四次評估報告(2007)",'Factor Table 1'!$N$76,IF(盤查結果!$F$6="IPCC第五次評估報告(2013)",'Factor Table 1'!$O$76,IF(盤查結果!$F$6="IPCC第六次評估報告(2021)",'Factor Table 1'!$P$76,0))))),0) -> 0 | AG18: =IFERROR(IF(H18=1,IF(盤查結果!$F$6="IPCC第二次評估報告（1995）",VLOOKUP(K18,'Factor Table 1'!$D$75:$P$169,9,FALSE),IF(盤查結果!$F$6="IPCC第三次評估報告(2001)",VLOOKUP(K18,'Factor Table 1'!$D$75:$P$169,10,FALSE),IF(盤查結果!$F$6="IPCC第四次評估報告(2007)",VLOOKUP(K18,'Factor Table 1'!$D$75:$P$169,11,FALSE),IF(盤查結果!$F$6="IPCC第五次評估報告(2013)",VLOOKUP(K18,'Factor Table 1'!$D$75:$P$169,12,FALSE),IF(盤查結果!$F$6="IPCC第六次評估報告(2021)",VLOOKUP(K18,'Factor Table 1'!$D$75:$P$169,13,FALSE),0))))),0),0) -> 0 | AH18: 0 | AI18: =IFERROR(IF(H18=1,IF(盤查結果!$F$6="IPCC第二次評估報告（1995）",VLOOKUP(K18,'Factor Table 1'!$D$172:$P$172,9,FALSE),IF(盤查結果!$F$6="IPCC第三次評估報告(2001)",VLOOKUP(K18,'Factor Table 1'!$D$172:$P$172,10,FALSE),IF(盤查結果!$F$6="IPCC第四次評估報告(2007)",VLOOKUP(K18,'Factor Table 1'!$D$172:$P$172,11,FALSE),IF(盤查結果!$F$6="IPCC第五次評估報告(2013)",VLOOKUP(K18,'Factor Table 1'!$D$172:$P$172,12,FALSE),IF(盤查結果!$F$6="IPCC第六次評估報告(2021)",VLOOKUP(K18,'Factor Table 1'!$D$172:$P$172,13,FALSE),0))))),0),0) -> 0 | AJ18: =IFERROR(IF(H18=1,IF(盤查結果!$F$6="IPCC第二次評估報告（1995）",VLOOKUP(K18,'Factor Table 1'!$D$171:$P$171,9,FALSE),IF(盤查結果!$F$6="IPCC第三次評估報告(2001)",VLOOKUP(K18,'Factor Table 1'!$D$171:$P$171,10,FALSE),IF(盤查結果!$F$6="IPCC第四次評估報告(2007)",VLOOKUP(K18,'Factor Table 1'!$D$171:$P$171,11,FALSE),IF(盤查結果!$F$6="IPCC第五次評估報告(2013)",VLOOKUP(K18,'Factor Table 1'!$D$171:$P$171,12,FALSE),IF(盤查結果!$F$6="IPCC第六次評估報告(2021)",VLOOKUP(K18,'Factor Table 1'!$D$171:$P$171,13,FALSE),0))))),0),0) -> 0 | AK18: =$L18*V18*AD18 -> 0 | AL18: =$L18*W18*AE18 -> 0 | AM18: =$L18*X18*AF18 -> 0 | AN18: =$L18*Y18*AG18 -> 0 | AO18: =$L18*Z18*AH18 -> 0 | AP18: =$L18*AA18*AI18 -> 0 | AQ18: =$L18*AB18*AJ18 -> 0 | AR18: =ROUND(SUM(AK18:AQ18),4) -> 0 | AS18: =AR18/($D$3+$Y$57+$Y$63) -> 0 | AT18: =AS18/($D$3+$D$55) -> 0
G19: =IF(K19<>"","移動燃燒","") | H19: =IF(K19<>"",1,"") | O19: =IF(V19>0.0000000001,"V","") | P19: =IF(W19>0.0000000001,"V","") | Q19: =IF(X19>0.0000000001,"V","") | R19: =IF(Y19>0.0000000001,"V","") | S19: =IF(Z19>0.0000000001,"V","") | T19: =IF(AA19>0.0000000001,"V","") | U19: =IF(AB19>0.0000000001,"V","") | V19: =IFERROR(ROUND(VLOOKUP($K19,'Factor Table 1'!$D$3:$AD$60,11,FALSE),10),0) -> 0 | W19: =IFERROR(ROUND(VLOOKUP($K19,'Factor Table 1'!$D$3:$AD$60,13,FALSE),10),0) -> 0 | X19: =IFERROR(ROUND(VLOOKUP($K19,'Factor Table 1'!$D$3:$AD$60,15,FALSE),10),0) -> 0 | Y19: =IFERROR(IF(OR(K19="CO2",K19="CH4",K19="N2O"),ROUND(VLOOKUP($K19,'Factor Table 1'!$D$3:$AD$69,17,FALSE),10),IFERROR(ROUND(VLOOKUP(J19,'Factor Table 1'!$C$3:$AD$69,18,FALSE),10),ROUND(VLOOKUP(K19,'Factor Table 1'!$D$3:$AD$69,17,FALSE),10))),0) -> 0 | Z19: 0 | AA19: =IFERROR(IF(K19="SF6",1,0),0) -> 0 | AB19: =IFERROR(IF(K19="NF3",1,0),0) -> 0 | AC19: =IFERROR(IF(OR(K19="CO2",K19="CH4",K19="N2O"),VLOOKUP($K19,'Factor Table 1'!$D$3:$AD$69,19,FALSE),IFERROR(VLOOKUP(J19,'Factor Table 1'!$C$3:$AD$69,20,FALSE),VLOOKUP(K19,'Factor Table 1'!$D$3:$AD$69,19,FALSE))),"") | AD19: =IF(H19=1,1,0) -> 0 | AE19: =IF(H19=1,IF(盤查結果!$F$6="IPCC第二次評估報告（1995）",'Factor Table 1'!$L$75,IF(盤查結果!$F$6="IPCC第三次評估報告(2001)",'Factor Table 1'!$M$75,IF(盤查結果!$F$6="IPCC第四次評估報告(2007)",'Factor Table 1'!$N$75,IF(盤查結果!$F$6="IPCC第五次評估報告(2013)",'Factor Table 1'!$O$75,IF(盤查結果!$F$6="IPCC第六次評估報告(2021)",'Factor Table 1'!$P$75,0))))),0) -> 0 | AF19: =IF(H19=1,IF(盤查結果!$F$6="IPCC第二次評估報告（1995）",'Factor Table 1'!$L$76,IF(盤查結果!$F$6="IPCC第三次評估報告(2001)",'Factor Table 1'!$M$76,IF(盤查結果!$F$6="IPCC第四次評估報告(2007)",'Factor Table 1'!$N$76,IF(盤查結果!$F$6="IPCC第五次評估報告(2013)",'Factor Table 1'!$O$76,IF(盤查結果!$F$6="IPCC第六次評估報告(2021)",'Factor Table 1'!$P$76,0))))),0) -> 0 | AG19: =IFERROR(IF(H19=1,IF(盤查結果!$F$6="IPCC第二次評估報告（1995）",VLOOKUP(K19,'Factor Table 1'!$D$75:$P$169,9,FALSE),IF(盤查結果!$F$6="IPCC第三次評估報告(2001)",VLOOKUP(K19,'Factor Table 1'!$D$75:$P$169,10,FALSE),IF(盤查結果!$F$6="IPCC第四次評估報告(2007)",VLOOKUP(K19,'Factor Table 1'!$D$75:$P$169,11,FALSE),IF(盤查結果!$F$6="IPCC第五次評估報告(2013)",VLOOKUP(K19,'Factor Table 1'!$D$75:$P$169,12,FALSE),IF(盤查結果!$F$6="IPCC第六次評估報告(2021)",VLOOKUP(K19,'Factor Table 1'!$D$75:$P$169,13,FALSE),0))))),0),0) -> 0 | AH19: 0 | AI19: =IFERROR(IF(H19=1,IF(盤查結果!$F$6="IPCC第二次評估報告（1995）",VLOOKUP(K19,'Factor Table 1'!$D$172:$P$172,9,FALSE),IF(盤查結果!$F$6="IPCC第三次評估報告(2001)",VLOOKUP(K19,'Factor Table 1'!$D$172:$P$172,10,FALSE),IF(盤查結果!$F$6="IPCC第四次評估報告(2007)",VLOOKUP(K19,'Factor Table 1'!$D$172:$P$172,11,FALSE),IF(盤查結果!$F$6="IPCC第五次評估報告(2013)",VLOOKUP(K19,'Factor Table 1'!$D$172:$P$172,12,FALSE),IF(盤查結果!$F$6="IPCC第六次評估報告(2021)",VLOOKUP(K19,'Factor Table 1'!$D$172:$P$172,13,FALSE),0))))),0),0) -> 0 | AJ19: =IFERROR(IF(H19=1,IF(盤查結果!$F$6="IPCC第二次評估報告（1995）",VLOOKUP(K19,'Factor Table 1'!$D$171:$P$171,9,FALSE),IF(盤查結果!$F$6="IPCC第三次評估報告(2001)",VLOOKUP(K19,'Factor Table 1'!$D$171:$P$171,10,FALSE),IF(盤查結果!$F$6="IPCC第四次評估報告(2007)",VLOOKUP(K19,'Factor Table 1'!$D$171:$P$171,11,FALSE),IF(盤查結果!$F$6="IPCC第五次評估報告(2013)",VLOOKUP(K19,'Factor Table 1'!$D$171:$P$171,12,FALSE),IF(盤查結果!$F$6="IPCC第六次評估報告(2021)",VLOOKUP(K19,'Factor Table 1'!$D$171:$P$171,13,FALSE),0))))),0),0) -> 0 | AK19: =$L19*V19*AD19 -> 0 | AL19: =$L19*W19*AE19 -> 0 | AM19: =$L19*X19*AF19 -> 0 | AN19: =$L19*Y19*AG19 -> 0 | AO19: =$L19*Z19*AH19 -> 0 | AP19: =$L19*AA19*AI19 -> 0 | AQ19: =$L19*AB19*AJ19 -> 0 | AR19: =ROUND(SUM(AK19:AQ19),4) -> 0 | AS19: =AR19/($D$3+$Y$57+$Y$63) -> 0 | AT19: =AS19/($D$3+$D$55) -> 0
G20: =IF(K20<>"","移動燃燒","") | H20: =IF(K20<>"",1,"") | O20: =IF(V20>0.0000000001,"V","") | P20: =IF(W20>0.0000000001,"V","") | Q20: =IF(X20>0.0000000001,"V","") | R20: =IF(Y20>0.0000000001,"V","") | S20: =IF(Z20>0.0000000001,"V","") | T20: =IF(AA20>0.0000000001,"V","") | U20: =IF(AB20>0.0000000001,"V","") | V20: =IFERROR(ROUND(VLOOKUP($K20,'Factor Table 1'!$D$3:$AD$60,11,FALSE),10),0) -> 0 | W20: =IFERROR(ROUND(VLOOKUP($K20,'Factor Table 1'!$D$3:$AD$60,13,FALSE),10),0) -> 0 | X20: =IFERROR(ROUND(VLOOKUP($K20,'Factor Table 1'!$D$3:$AD$60,15,FALSE),10),0) -> 0 | Y20: =IFERROR(IF(OR(K20="CO2",K20="CH4",K20="N2O"),ROUND(VLOOKUP($K20,'Factor Table 1'!$D$3:$AD$69,17,FALSE),10),IFERROR(ROUND(VLOOKUP(J20,'Factor Table 1'!$C$3:$AD$69,18,FALSE),10),ROUND(VLOOKUP(K20,'Factor Table 1'!$D$3:$AD$69,17,FALSE),10))),0) -> 0 | Z20: 0 | AA20: =IFERROR(IF(K20="SF6",1,0),0) -> 0 | AB20: =IFERROR(IF(K20="NF3",1,0),0) -> 0 | AC20: =IFERROR(IF(OR(K20="CO2",K20="CH4",K20="N2O"),VLOOKUP($K20,'Factor Table 1'!$D$3:$AD$69,19,FALSE),IFERROR(VLOOKUP(J20,'Factor Table 1'!$C$3:$AD$69,20,FALSE),VLOOKUP(K20,'Factor Table 1'!$D$3:$AD$69,19,FALSE))),"") | AD20: =IF(H20=1,1,0) -> 0 | AE20: =IF(H20=1,IF(盤查結果!$F$6="IPCC第二次評估報告（1995）",'Factor Table 1'!$L$75,IF(盤查結果!$F$6="IPCC第三次評估報告(2001)",'Factor Table 1'!$M$75,IF(盤查結果!$F$6="IPCC第四次評估報告(2007)",'Factor Table 1'!$N$75,IF(盤查結果!$F$6="IPCC第五次評估報告(2013)",'Factor Table 1'!$O$75,IF(盤查結果!$F$6="IPCC第六次評估報告(2021)",'Factor Table 1'!$P$75,0))))),0) -> 0 | AF20: =IF(H20=1,IF(盤查結果!$F$6="IPCC第二次評估報告（1995）",'Factor Table 1'!$L$76,IF(盤查結果!$F$6="IPCC第三次評估報告(2001)",'Factor Table 1'!$M$76,IF(盤查結果!$F$6="IPCC第四次評估報告(2007)",'Factor Table 1'!$N$76,IF(盤查結果!$F$6="IPCC第五次評估報告(2013)",'Factor Table 1'!$O$76,IF(盤查結果!$F$6="IPCC第六次評估報告(2021)",'Factor Table 1'!$P$76,0))))),0) -> 0 | AG20: =IFERROR(IF(H20=1,IF(盤查結果!$F$6="IPCC第二次評估報告（1995）",VLOOKUP(K20,'Factor Table 1'!$D$75:$P$169,9,FALSE),IF(盤查結果!$F$6="IPCC第三次評估報告(2001)",VLOOKUP(K20,'Factor Table 1'!$D$75:$P$169,10,FALSE),IF(盤查結果!$F$6="IPCC第四次評估報告(2007)",VLOOKUP(K20,'Factor Table 1'!$D$75:$P$169,11,FALSE),IF(盤查結果!$F$6="IPCC第五次評估報告(2013)",VLOOKUP(K20,'Factor Table 1'!$D$75:$P$169,12,FALSE),IF(盤查結果!$F$6="IPCC第六次評估報告(2021)",VLOOKUP(K20,'Factor Table 1'!$D$75:$P$169,13,FALSE),0))))),0),0) -> 0 | AH20: 0 | AI20: =IFERROR(IF(H20=1,IF(盤查結果!$F$6="IPCC第二次評估報告（1995）",VLOOKUP(K20,'Factor Table 1'!$D$172:$P$172,9,FALSE),IF(盤查結果!$F$6="IPCC第三次評估報告(2001)",VLOOKUP(K20,'Factor Table 1'!$D$172:$P$172,10,FALSE),IF(盤查結果!$F$6="IPCC第四次評估報告(2007)",VLOOKUP(K20,'Factor Table 1'!$D$172:$P$172,11,FALSE),IF(盤查結果!$F$6="IPCC第五次評估報告(2013)",VLOOKUP(K20,'Factor Table 1'!$D$172:$P$172,12,FALSE),IF(盤查結果!$F$6="IPCC第六次評估報告(2021)",VLOOKUP(K20,'Factor Table 1'!$D$172:$P$172,13,FALSE),0))))),0),0) -> 0 | AJ20: =IFERROR(IF(H20=1,IF(盤查結果!$F$6="IPCC第二次評估報告（1995）",VLOOKUP(K20,'Factor Table 1'!$D$171:$P$171,9,FALSE),IF(盤查結果!$F$6="IPCC第三次評估報告(2001)",VLOOKUP(K20,'Factor Table 1'!$D$171:$P$171,10,FALSE),IF(盤查結果!$F$6="IPCC第四次評估報告(2007)",VLOOKUP(K20,'Factor Table 1'!$D$171:$P$171,11,FALSE),IF(盤查結果!$F$6="IPCC第五次評估報告(2013)",VLOOKUP(K20,'Factor Table 1'!$D$171:$P$171,12,FALSE),IF(盤查結果!$F$6="IPCC第六次評估報告(2021)",VLOOKUP(K20,'Factor Table 1'!$D$171:$P$171,13,FALSE),0))))),0),0) -> 0 | AK20: =$L20*V20*AD20 -> 0 | AL20: =$L20*W20*AE20 -> 0 | AM20: =$L20*X20*AF20 -> 0 | AN20: =$L20*Y20*AG20 -> 0 | AO20: =$L20*Z20*AH20 -> 0 | AP20: =$L20*AA20*AI20 -> 0 | AQ20: =$L20*AB20*AJ20 -> 0 | AR20: =ROUND(SUM(AK20:AQ20),4) -> 0 | AS20: =AR20/($D$3+$Y$57+$Y$63) -> 0 | AT20: =AS20/($D$3+$D$55) -> 0
