Workbook
Name Africa: 表格8[[#All],[Africa]]
Name Africa: 表格8[[#All],[Africa]]
Name America: #REF!
Name Americas: 表格5[[#All],[Americas]]
Name Americas: 表格5[[#All],[Americas]]
Name Asia: 表格1[[#All],[Asia]]
Name Asia: 表格1[[#All],[Asia]]
Name CHINA: #REF!
Name CO2係數: 表格2[[#Headers],[CO2係數]]
Name CO2係數: 表格2[[#Headers],[CO2係數]]
Name EMEA: #REF!
Name Europe: 表格9[[#All],[Europe]]
Name Europe: 表格9[[#All],[Europe]]
Name India: #REF!
Name NEA: #REF!
Name Oceania: 表格10[[#All],[Oceania]]
Name Oceania: 表格10[[#All],[Oceania]]
Name region: 'Other Emission Factor'!$M$3:$Q$3
Name SEA: #REF!
Name TAIWAN: #REF!
Name title: 'Other Emission Factor'!$B$4:$C$4
Name title2: 'Other Emission Factor'!$B$10:$C$10
Name 國家: 表格13[[#All],[國家/市場]]
Name 國家: 表格13[[#All],[國家/市場]]
Name 國家電網: 表格13[[#All],[國家&電網]]
Name 國家電網: 表格13[[#All],[國家&電網]]
Name 溫室氣體種類: '6.GWP'!$B$1:$B$173
Name 溫室氣體種類: '6.GWP'!$B$1:$B$173
Name 電力係數: 表格13[[#All],[電力係數]]
Name 電力係數: 表格13[[#All],[電力係數]]
Name 電力係數年度: 表格13[[#All],[電力係數年度]]
Name 電力係數年度: 表格13[[#All],[電力係數年度]]
Name 電力係數來源: 表格13[[#All],[電力係數來源]]
Name 電力係數來源: 表格13[[#All],[電力係數來源]]
Name 電網: 表格13[[#All],[電網]]
Name 電網: 表格13[[#All],[電網]]
Name 預設值Default: '4.Default Emission Factor'!$D:$D
Name 預設逸散率: 表格12[[#All],[冷媒設備Factor in Equation]]
Name 預設逸散率Default: 表格12[[#All],[冷媒設備Factor in Equation]]

Sheet 1.GHG Inventory Form
B1: 組織及盤查概況Organization Overview
B3: 填表日期 Date of Form | D3: 區域 Region
B4: 公司名稱： Company Name | D4: 國家/市場： Country or Market
B5: 廠區名稱： Site Name | C5: Soest, DE00 | D5: 盤查年份（西元）： Inventory Year | E5: 2023
B6: 盤查單位： Inventory Dept. | D6: IPCC選擇年度 IPCC Report Year | E6: IPCC AR6 Report(2021)
B7: 填表人： Form Filler | C7: Jan Birkenfeld | D7: 電話： Phone Number
B8: 郵箱： Email | C8: Jan.birkenfeld@deltaww.com
B9: 填表人地址 / 盤查地址 Filler/site Address | C9: Coesterweg 45, D-59494 Soest, Germany
B10: 廠區內排除： Excluded Areas | C10: 0
B12: 報告邊界 Reporting boundaries
B13: 類別 1: 直接溫室氣體排放和移除 Category1: Direct GHG emissions and removals
B14: 主類別 Category | C14: 子類別 Sub-Category | D14: 項目名稱 Emission Source Type | G14: 活動數據Activity Data | P14: 自訂溫室氣體排放係數 Custom GHG Emission Factors | Y14: 可能產生之溫室氣體種類 (GHG Species) | AF14: 排放係數 Default Emission Factors | AN14: Global Warming Potentials (GWP) | AU14: 溫室氣體排放量 (Individual GHG Emissions) | BB14: 合計Sum (t-CO2e) | BC14: 類別1、2佔比 Percentage of Category 1, 2 | BD14: 總碳排放量佔比 Percentage of Total Emissions
G15: 是否有此排放源 Applicability (Yes/No) | H15: 設備 Emission Source (Operation or Process) | I15: 自訂/預設係數 Custom/Default Emission Factor | J15: 預設排放源名稱 Default Fuel (Combustion Emissions), or Greenhouse Gas (Process Direct Emissions or Fugitive Emissions) | K15: 自訂排放源名稱 Custom Fuel (Combustion Emissions), or Greenhouse Gas (Process Direct Emissions or Fugitive Emissions) | L15: 活動數據(使用量/填充量) Usage or Consumption | M15: 活動數據單位 Unit | N15: 自訂活動數據單位 Custom Unit (if different from default) | O15: 活動數據佐證 Data Evidence / Reference | P15: CO2 | Q15: CH4 | R15: N2O | S15: HFCs | T15: PFCs | U15: SF6 | V15: NF3 | W15: 係數單位 Emission Factor Unit | X15: 係數來源 Emission Factor Reference | Y15: CO2 | Z15: CH4 | AA15: N2O | AB15: HFCs | AC15: PFCs | AD15: SF6 | AE15: NF3 | AF15: CO2 | AG15: CH4 | AH15: N2O | AI15: HFCs | AJ15: PFCs | AK15: SF6 | AL15: NF3 | AM15: 排放係數來源 Emission Factor Reference | AN15: CO2 | AO15: CH4 | AP15: N2O | AQ15: HFCs | AR15: PFCs | AS15: SF6 | AT15: NF3 | AU15: CO2 | AV15: CH4 | AW15: N2O | AX15: HFCs | AY15: PFCs | AZ15: SF6 | BA15: NF3 | BI15: 排放源名稱 | BJ15: 活動數據來源 | BK15: 排放係數來源
A16: 1 | B16: 類別1 Category 1 | C16: 1.1 | D16: 固定燃燒直接排放 Stationary Combustion | G16: Y | H16: 鍋爐-發電機 Boiler-Generator | I16: 預設值Default | J16: 天然氣Natural Gas | L16: 265.97722 | M16: =IFERROR(IF(I16="預設值Default",VLOOKUP($J16,'4.Default Emission Factor'!$D:$V,16,FALSE),"請填寫自訂活動數據單位Please fill in Custom Unit"),"請選擇預設排放係數名稱Please Choose Default Fuel or Greenhouse Gas") -> KM3 | Y16: =IF(AF16>0.0000000001,"V","") -> V | Z16: =IF(AG16>0.0000000001,"V","") -> V | AA16: =IF(AH16>0.0000000001,"V","") -> V | AB16: =IF(AI16>0.0000000001,"V","") | AC16: =IF(AJ16>0.0000000001,"V","") | AD16: =IF(AK16>0.0000000001,"V","") | AE16: =IF(AL16>0.0000000001,"V","") | AF16: =IFERROR(IF($I16="預設值Default",ROUND(VLOOKUP($J16,'4.Default Emission Factor'!$D:$V,2,FALSE),10),IF($I16="自訂值Custom Value",P16,0)),0) -> 1.8790358 | AG16: =IFERROR(IF($I16="預設值Default",ROUND(VLOOKUP($J16,'4.Default Emission Factor'!$D:$V,4,FALSE),10),IF($I16="自訂值Custom Value",Q16,0)),0) -> 3.34944e-05 | AH16: =IFERROR(IF($I16="預設值Default",ROUND(VLOOKUP($J16,'4.Default Emission Factor'!$D:$V,6,FALSE),10),IF($I16="自訂值Custom Value",R16,0)),0) -> 3.3494e-06 | AI16: =IFERROR(IF($I16="預設值Default",ROUND(VLOOKUP($J16,'4.Default Emission Factor'!$D:$V,8,FALSE),10),IF($I16="自訂值Custom Value",S16,0)),0) -> 0 | AJ16: =IFERROR(IF($I16="預設值Default",ROUND(VLOOKUP($J16,'4.Default Emission Factor'!$D:$V,10,FALSE),10),IF($I16="自訂值Custom Value",T16,0)),0) -> 0 | AK16: =IFERROR(IF($I16="預設值Default",ROUND(VLOOKUP($J16,'4.Default Emission Factor'!$D:$V,12,FALSE),10),IF($I16="自訂值Custom Value",U16,0)),0) -> 0 | AL16: =IFERROR(IF($I16="預設值Default",ROUND(VLOOKUP($J16,'4.Default Emission Factor'!$D:$V,14,FALSE),10),IF($I16="自訂值Custom Value",V16,0)),0) -> 0 | AM16: =IFERROR(IF(I16="預設值Default",VLOOKUP($J16,'4.Default Emission Factor'!$D:$V,17,FALSE),IF(I16="自訂值Custom Value",X16,"")),"") -> 環保署排放係管理表6.0.4Taiwan EPA GHG coefficient table 6.0.4 | AN16: =IF(Y16="V",1,0) -> 1 | AO16: =IF(Z16="V",IF('1.GHG Inventory Form'!$E$6="IPCC AR2 Report(1995)",'6.GWP'!$C$2,IF('1.GHG Inventory Form'!$E$6="IPCC AR3 Report(2001)",'6.GWP'!$D$2,IF('1.GHG Inventory Form'!$E$6="IPCC AR4 Report(2007)",'6.GWP'!$E$2,IF('1.GHG Inventory Form'!$E$6="IPCC AR5 Report(2013)",'6.GWP'!$F$2,IF('1.GHG Inventory Form'!$E$6="IPCC AR6 Report(2021)",'6.GWP'!$G$2,0))))),0) -> 27.9 | AP16: =IF(AA16="V",IF('1.GHG Inventory Form'!$E$6="IPCC AR2 Report(1995)",'6.GWP'!$C$3,IF('1.GHG Inventory Form'!$E$6="IPCC AR3 Report(2001)",'6.GWP'!$D$3,IF('1.GHG Inventory Form'!$E$6="IPCC AR4 Report(2007)",'6.GWP'!$E$3,IF('1.GHG Inventory Form'!$E$6="IPCC AR5 Report(2013)",'6.GWP'!$F$3,IF('1.GHG Inventory Form'!$E$6="IPCC AR6 Report(2021)",'6.GWP'!$G$3,0))))),0) -> 273 | AQ16: =IFERROR(IF(AND(AB16="V",$I16="預設值"),IF('1.GHG Inventory Form'!$E$6="IPCC AR2 Report(1995)",VLOOKUP($J16,'6.GWP'!$B$1:$G$173,2,FALSE),IF('1.GHG Inventory Form'!$E$6="IPCC AR3 Report(2001)",VLOOKUP($J16,'6.GWP'!$B$1:$G$173,3,FALSE),IF('1.GHG Inventory Form'!$E$6="IPCC AR4 Report(2007)",VLOOKUP($J16,'6.GWP'!$B$1:$G$173,4,FALSE),IF('1.GHG Inventory Form'!$E$6="IPCC AR5 Report(2013)",VLOOKUP($J16,'6.GWP'!$B$1:$G$173,5,FALSE),IF('1.GHG Inventory Form'!$E$6="IPCC AR6 Report(2021)",VLOOKUP($J16,'6.GWP'!$B$2:$G$173,6,FALSE),0))))),IF(AND(AB16="V",$I16="自訂值"),IF('1.GHG Inventory Form'!$E$6="IPCC AR2 Report(1995)",VLOOKUP($K16,'6.GWP'!$B$1:$G$173,2,FALSE),IF('1.GHG Inventory Form'!$E$6="IPCC AR3 Report(2001)",VLOOKUP($K16,'6.GWP'!$B$1:$G$173,3,FALSE),IF('1.GHG Inventory Form'!$E$6="IPCC AR4 Report(2007)",VLOOKUP($K16,'6.GWP'!$B$1:$G$173,4,FALSE),IF('1.GHG Inventory Form'!$E$6="IPCC AR5 Report(2013)",VLOOKUP($K16,'6.GWP'!$B$1:$G$173,5,FALSE),IF('1.GHG Inventory Form'!$E$6="IPCC AR6 Report(2021)",VLOOKUP($K16,'6.GWP'!$B$2:$G$173,6,FALSE),0))))),0)),0) -> 0 | AR16: =IFERROR(IF(AND(AC16="V",$I16="預設值"),IF('1.GHG Inventory Form'!$E$6="IPCC AR2 Report(1995)",VLOOKUP($J16,'6.GWP'!$B$1:$G$173,2,FALSE),IF('1.GHG Inventory Form'!$E$6="IPCC AR3 Report(2001)",VLOOKUP($J16,'6.GWP'!$B$1:$G$173,3,FALSE),IF('1.GHG Inventory Form'!$E$6="IPCC AR4 Report(2007)",VLOOKUP($J16,'6.GWP'!$B$1:$G$173,4,FALSE),IF('1.GHG Inventory Form'!$E$6="IPCC AR5 Report(2013)",VLOOKUP($J16,'6.GWP'!$B$1:$G$173,5,FALSE),IF('1.GHG Inventory Form'!$E$6="IPCC AR6 Report(2021)",VLOOKUP($J16,'6.GWP'!$B$2:$G$173,6,FALSE),0))))),IF(AND(AC16="V",$I16="自訂值"),IF('1.GHG Inventory Form'!$E$6="IPCC AR2 Report(1995)",VLOOKUP($K16,'6.GWP'!$B$1:$G$173,2,FALSE),IF('1.GHG Inventory Form'!$E$6="IPCC AR3 Report(2001)",VLOOKUP($K16,'6.GWP'!$B$1:$G$173,3,FALSE),IF('1.GHG Inventory Form'!$E$6="IPCC AR4 Report(2007)",VLOOKUP($K16,'6.GWP'!$B$1:$G$173,4,FALSE),IF('1.GHG Inventory Form'!$E$6="IPCC AR5 Report(2013)",VLOOKUP($K16,'6.GWP'!$B$1:$G$173,5,FALSE),IF('1.GHG Inventory Form'!$E$6="IPCC AR6 Report(2021)",VLOOKUP($K16,'6.GWP'!$B$2:$G$173,6,FALSE),0))))),0)),0) -> 0 | AS16: =IF(AD16="V",IF('1.GHG Inventory Form'!$E$6="IPCC AR2 Report(1995)",'6.GWP'!$C$5,IF('1.GHG Inventory Form'!$E$6="IPCC AR3 Report(2001)",'6.GWP'!$D$5,IF('1.GHG Inventory Form'!$E$6="IPCC AR4 Report(2007)",'6.GWP'!$E$5,IF('1.GHG Inventory Form'!$E$6="IPCC AR5 Report(2013)",'6.GWP'!$F$5,IF('1.GHG Inventory Form'!$E$6="IPCC AR6 Report(2021)",'6.GWP'!$G$5,0))))),0) -> 0 | AT16: =IF(AE16="V",IF('1.GHG Inventory Form'!$E$6="IPCC AR2 Report(1995)",'6.GWP'!$C$4,IF('1.GHG Inventory Form'!$E$6="IPCC AR3 Report(2001)",'6.GWP'!$D$4,IF('1.GHG Inventory Form'!$E$6="IPCC AR4 Report(2007)",'6.GWP'!$E$4,IF('1.GHG Inventory Form'!$E$6="IPCC AR5 Report(2013)",'6.GWP'!$F$4,IF('1.GHG Inventory Form'!$E$6="IPCC AR6 Report(2021)",'6.GWP'!$G$4,0))))),0) -> 0 | AU16: =IFERROR($L16*AF16*AN16,"") -> 499.78072 | AV16: =IFERROR($L16*AG16*AO16,"") -> 0.24855405 | AW16: =IFERROR($L16*AH16*AP16,"") -> 0.2432059 | AX16: =IFERROR($L16*AI16*AQ16,"") -> 0 | AY16: =IFERROR($L16*AJ16*AR16,"") -> 0 | AZ16: =IFERROR($L16*AK16*AS16,"") -> 0 | BA16: =IFERROR($L16*AL16*AT16,"") -> 0 | BB16: =ROUND(SUM(AU16:BA16),4) -> 500.2725 | BC16: =BB16/SUM($BB$16:$BB$99) -> 0.35001281 | BD16: =BB16/$BB$169 -> 0.31544819 | BI16: =IF(H16="","",IF(I16="預設值Default",H16&J16,IF(I16="自訂值Custom Value",H16&K16,""))) -> 鍋爐-發電機 Boiler-Generator天然氣Natural Gas | BJ16: =IF(H16="其它設備，請說明","",IF(O16=0,"",O16)) | BK16: =IF(H16="","",IF(I16="預設值Default",AM16,IF(I16="自訂值Custom Value",X16,""))) -> 環保署排放係管理表6.0.4Taiwan EPA GHG coefficient table 6.0.4
A17: 2 | I17: 預設值Default | M17: =IFERROR(IF(I17="預設值Default",VLOOKUP($J17,'4.Default Emission Factor'!$D:$V,16,FALSE),"請填寫自訂活動數據單位Please fill in Custom Unit"),"請選擇預設排放係數名稱Please Choose Default Fuel or Greenhouse Gas") -> 請選擇預設排放係數名稱Please Choose Default Fuel or Greenhouse Gas | Y17: =IF(AF17>0.0000000001,"V","") | Z17: =IF(AG17>0.0000000001,"V","") | AA17: =IF(AH17>0.0000000001,"V","") | AB17: =IF(AI17>0.0000000001,"V","") | AC17: =IF(AJ17>0.0000000001,"V","") | AD17: =IF(AK17>0.0000000001,"V","") | AE17: =IF(AL17>0.0000000001,"V","") | AF17: =IFERROR(IF($I17="預設值Default",ROUND(VLOOKUP($J17,'4.Default Emission Factor'!$D:$V,2,FALSE),10),IF($I17="自訂值Custom Value",P17,0)),0) -> 0 | AG17: =IFERROR(IF($I17="預設值Default",ROUND(VLOOKUP($J17,'4.Default Emission Factor'!$D:$V,4,FALSE),10),IF($I17="自訂值Custom Value",Q17,0)),0) -> 0 | AH17: =IFERROR(IF($I17="預設值Default",ROUND(VLOOKUP($J17,'4.Default Emission Factor'!$D:$V,6,FALSE),10),IF($I17="自訂值Custom Value",R17,0)),0) -> 0 | AI17: =IFERROR(IF($I17="預設值Default",ROUND(VLOOKUP($J17,'4.Default Emission Factor'!$D:$V,8,FALSE),10),IF($I17="自訂值Custom Value",S17,0)),0) -> 0 | AJ17: =IFERROR(IF($I17="預設值Default",ROUND(VLOOKUP($J17,'4.Default Emission Factor'!$D:$V,10,FALSE),10),IF($I17="自訂值Custom Value",T17,0)),0) -> 0 | AK17: =IFERROR(IF($I17="預設值Default",ROUND(VLOOKUP($J17,'4.Default Emission Factor'!$D:$V,12,FALSE),10),IF($I17="自訂值Custom Value",U17,0)),0) -> 0 | AL17: =IFERROR(IF($I17="預設值Default",ROUND(VLOOKUP($J17,'4.Default Emission Factor'!$D:$V,14,FALSE),10),IF($I17="自訂值Custom Value",V17,0)),0) -> 0 | AM17: =IFERROR(IF(I17="預設值Default",VLOOKUP($J17,'4.Default Emission Factor'!$D:$V,17,FALSE),IF(I17="自訂值Custom Value",X17,"")),"") | AN17: =IF(Y17="V",1,0) -> 0 | AO17: =IF(Z17="V",IF('1.GHG Inventory Form'!$E$6="IPCC AR2 Report(1995)",'6.GWP'!$C$2,IF('1.GHG Inventory Form'!$E$6="IPCC AR3 Report(2001)",'6.GWP'!$D$2,IF('1.GHG Inventory Form'!$E$6="IPCC AR4 Report(2007)",'6.GWP'!$E$2,IF('1.GHG Inventory Form'!$E$6="IPCC AR5 Report(2013)",'6.GWP'!$F$2,IF('1.GHG Inventory Form'!$E$6="IPCC AR6 Report(2021)",'6.GWP'!$G$2,0))))),0) -> 0 | AP17: =IF(AA17="V",IF('1.GHG Inventory Form'!$E$6="IPCC AR2 Report(1995)",'6.GWP'!$C$3,IF('1.GHG Inventory Form'!$E$6="IPCC AR3 Report(2001)",'6.GWP'!$D$3,IF('1.GHG Inventory Form'!$E$6="IPCC AR4 Report(2007)",'6.GWP'!$E$3,IF('1.GHG Inventory Form'!$E$6="IPCC AR5 Report(2013)",'6.GWP'!$F$3,IF('1.GHG Inventory Form'!$E$6="IPCC AR6 Report(2021)",'6.GWP'!$G$3,0))))),0) -> 0 | AQ17: =IFERROR(IF(AND(AB17="V",$I17="預設值"),IF('1.GHG Inventory Form'!$E$6="IPCC AR2 Report(1995)",VLOOKUP($J17,'6.GWP'!$B$1:$G$173,2,FALSE),IF('1.GHG Inventory Form'!$E$6="IPCC AR3 Report(2001)",VLOOKUP($J17,'6.GWP'!$B$1:$G$173,3,FALSE),IF('1.GHG Inventory Form'!$E$6="IPCC AR4 Report(2007)",VLOOKUP($J17,'6.GWP'!$B$1:$G$173,4,FALSE),IF('1.GHG Inventory Form'!$E$6="IPCC AR5 Report(2013)",VLOOKUP($J17,'6.GWP'!$B$1:$G$173,5,FALSE),IF('1.GHG Inventory Form'!$E$6="IPCC AR6 Report(2021)",VLOOKUP($J17,'6.GWP'!$B$2:$G$173,6,FALSE),0))))),IF(AND(AB17="V",$I17="自訂值"),IF('1.GHG Inventory Form'!$E$6="IPCC AR2 Report(1995)",VLOOKUP($K17,'6.GWP'!$B$1:$G$173,2,FALSE),IF('1.GHG Inventory Form'!$E$6="IPCC AR3 Report(2001)",VLOOKUP($K17,'6.GWP'!$B$1:$G$173,3,FALSE),IF('1.GHG Inventory Form'!$E$6="IPCC AR4 Report(2007)",VLOOKUP($K17,'6.GWP'!$B$1:$G$173,4,FALSE),IF('1.GHG Inventory Form'!$E$6="IPCC AR5 Report(2013)",VLOOKUP($K17,'6.GWP'!$B$1:$G$173,5,FALSE),IF('1.GHG Inventory Form'!$E$6="IPCC AR6 Report(2021)",VLOOKUP($K17,'6.GWP'!$B$2:$G$173,6,FALSE),0))))),0)),0) -> 0 | AR17: =IFERROR(IF(AND(AC17="V",$I17="預設值"),IF('1.GHG Inventory Form'!$E$6="IPCC AR2 Report(1995)",VLOOKUP($J17,'6.GWP'!$B$1:$G$173,2,FALSE),IF('1.GHG Inventory Form'!$E$6="IPCC AR3 Report(2001)",VLOOKUP($J17,'6.GWP'!$B$1:$G$173,3,FALSE),IF('1.GHG Inventory Form'!$E$6="IPCC AR4 Report(2007)",VLOOKUP($J17,'6.GWP'!$B$1:$G$173,4,FALSE),IF('1.GHG Inventory Form'!$E$6="IPCC AR5 Report(2013)",VLOOKUP($J17,'6.GWP'!$B$1:$G$173,5,FALSE),IF('1.GHG Inventory Form'!$E$6="IPCC AR6 Report(2021)",VLOOKUP($J17,'6.GWP'!$B$2:$G$173,6,FALSE),0))))),IF(AND(AC17="V",$I17="自訂值"),IF('1.GHG Inventory Form'!$E$6="IPCC AR2 Report(1995)",VLOOKUP($K17,'6.GWP'!$B$1:$G$173,2,FALSE),IF('1.GHG Inventory Form'!$E$6="IPCC AR3 Report(2001)",VLOOKUP($K17,'6.GWP'!$B$1:$G$173,3,FALSE),IF('1.GHG Inventory Form'!$E$6="IPCC AR4 Report(2007)",VLOOKUP($K17,'6.GWP'!$B$1:$G$173,4,FALSE),IF('1.GHG Inventory Form'!$E$6="IPCC AR5 Report(2013)",VLOOKUP($K17,'6.GWP'!$B$1:$G$173,5,FALSE),IF('1.GHG Inventory Form'!$E$6="IPCC AR6 Report(2021)",VLOOKUP($K17,'6.GWP'!$B$2:$G$173,6,FALSE),0))))),0)),0) -> 0 | AS17: =IF(AD17="V",IF('1.GHG Inventory Form'!$E$6="IPCC AR2 Report(1995)",'6.GWP'!$C$5,IF('1.GHG Inventory Form'!$E$6="IPCC AR3 Report(2001)",'6.GWP'!$D$5,IF('1.GHG Inventory Form'!$E$6="IPCC AR4 Report(2007)",'6.GWP'!$E$5,IF('1.GHG Inventory Form'!$E$6="IPCC AR5 Report(2013)",'6.GWP'!$F$5,IF('1.GHG Inventory Form'!$E$6="IPCC AR6 Report(2021)",'6.GWP'!$G$5,0))))),0) -> 0 | AT17: =IF(AE17="V",IF('1.GHG Inventory Form'!$E$6="IPCC AR2 Report(1995)",'6.GWP'!$C$4,IF('1.GHG Inventory Form'!$E$6="IPCC AR3 Report(2001)",'6.GWP'!$D$4,IF('1.GHG Inventory Form'!$E$6="IPCC AR4 Report(2007)",'6.GWP'!$E$4,IF('1.GHG Inventory Form'!$E$6="IPCC AR5 Report(2013)",'6.GWP'!$F$4,IF('1.GHG Inventory Form'!$E$6="IPCC AR6 Report(2021)",'6.GWP'!$G$4,0))))),0) -> 0 | AU17: =IFERROR($L17*AF17*AN17,"") | AV17: =IFERROR($L17*AG17*AO17,"") | AW17: =IFERROR($L17*AH17*AP17,"") | AX17: =IFERROR($L17*AI17*AQ17,"") | AY17: =IFERROR($L17*AJ17*AR17,"") | AZ17: =IFERROR($L17*AK17*AS17,"") | BA17: =IFERROR($L17*AL17*AT17,"") | BB17: =ROUND(SUM(AU17:BA17),4) -> 0 | BC17: =BB17/SUM($BB$16:$BB$99) -> 0 | BD17: =BB17/$BB$169 -> 0 | BI17: =IF(H17="","",IF(I17="預設值Default",H17&J17,IF(I17="自訂值Custom Value",H17&K17,""))) | BJ17: =IF(H17="其它設備，請說明","",IF(O17=0,"",O17)) | BK17: =IF(H17="","",IF(I17="預設值Default",AM17,IF(I17="自訂值Custom Value",X17,"")))
A18: 3 | I18: 預設值Default | M18: =IFERROR(IF(I18="預設值Default",VLOOKUP($J18,'4.Default Emission Factor'!$D:$V,16,FALSE),"請填寫自訂活動數據單位Please fill in Custom Unit"),"請選擇預設排放係數名稱Please Choose Default Fuel or Greenhouse Gas") -> 請選擇預設排放係數名稱Please Choose Default Fuel or Greenhouse Gas | Y18: =IF(AF18>0.0000000001,"V","") | Z18: =IF(AG18>0.0000000001,"V","") | AA18: =IF(AH18>0.0000000001,"V","") | AB18: =IF(AI18>0.0000000001,"V","") | AC18: =IF(AJ18>0.0000000001,"V","") | AD18: =IF(AK18>0.0000000001,"V","") | AE18: =IF(AL18>0.0000000001,"V","") | AF18: =IFERROR(IF($I18="預設值Default",ROUND(VLOOKUP($J18,'4.Default Emission Factor'!$D:$V,2,FALSE),10),IF($I18="自訂值Custom Value",P18,0)),0) -> 0 | AG18: =IFERROR(IF($I18="預設值Default",ROUND(VLOOKUP($J18,'4.Default Emission Factor'!$D:$V,4,FALSE),10),IF($I18="自訂值Custom Value",Q18,0)),0) -> 0 | AH18: =IFERROR(IF($I18="預設值Default",ROUND(VLOOKUP($J18,'4.Default Emission Factor'!$D:$V,6,FALSE),10),IF($I18="自訂值Custom Value",R18,0)),0) -> 0 | AI18: =IFERROR(IF($I18="預設值Default",ROUND(VLOOKUP($J18,'4.Default Emission Factor'!$D:$V,8,FALSE),10),IF($I18="自訂值Custom Value",S18,0)),0) -> 0 | AJ18: =IFERROR(IF($I18="預設值Default",ROUND(VLOOKUP($J18,'4.Default Emission Factor'!$D:$V,10,FALSE),10),IF($I18="自訂值Custom Value",T18,0)),0) -> 0 | AK18: =IFERROR(IF($I18="預設值Default",ROUND(VLOOKUP($J18,'4.Default Emission Factor'!$D:$V,12,FALSE),10),IF($I18="自訂值Custom Value",U18,0)),0) -> 0 | AL18: =IFERROR(IF($I18="預設值Default",ROUND(VLOOKUP($J18,'4.Default Emission Factor'!$D:$V,14,FALSE),10),IF($I18="自訂值Custom Value",V18,0)),0) -> 0 | AM18: =IFERROR(IF(I18="預設值Default",VLOOKUP($J18,'4.Default Emission Factor'!$D:$V,17,FALSE),IF(I18="自訂值Custom Value",X18,"")),"") | AN18: =IF(Y18="V",1,0) -> 0 | AO18: =IF(Z18="V",IF('1.GHG Inventory Form'!$E$6="IPCC AR2 Report(1995)",'6.GWP'!$C$2,IF('1.GHG Inventory Form'!$E$6="IPCC AR3 Report(2001)",'6.GWP'!$D$2,IF('1.GHG Inventory Form'!$E$6="IPCC AR4 Report(2007)",'6.GWP'!$E$2,IF('1.GHG Inventory Form'!$E$6="IPCC AR5 Report(2013)",'6.GWP'!$F$2,IF('1.GHG Inventory Form'!$E$6="IPCC AR6 Report(2021)",'6.GWP'!$G$2,0))))),0) -> 0 | AP18: =IF(AA18="V",IF('1.GHG Inventory Form'!$E$6="IPCC AR2 Report(1995)",'6.GWP'!$C$3,IF('1.GHG Inventory Form'!$E$6="IPCC AR3 Report(2001)",'6.GWP'!$D$3,IF('1.GHG Inventory Form'!$E$6="IPCC AR4 Report(2007)",'6.GWP'!$E$3,IF('1.GHG Inventory Form'!$E$6="IPCC AR5 Report(2013)",'6.GWP'!$F$3,IF('1.GHG Inventory Form'!$E$6="IPCC AR6 Report(2021)",'6.GWP'!$G$3,0))))),0) -> 0 | AQ18: =IFERROR(IF(AND(AB18="V",$I18="預設值"),IF('1.GHG Inventory Form'!$E$6="IPCC AR2 Report(1995)",VLOOKUP($J18,'6.GWP'!$B$1:$G$173,2,FALSE),IF('1.GHG Inventory Form'!$E$6="IPCC AR3 Report(2001)",VLOOKUP($J18,'6.GWP'!$B$1:$G$173,3,FALSE),IF('1.GHG Inventory Form'!$E$6="IPCC AR4 Report(2007)",VLOOKUP($J18,'6.GWP'!$B$1:$G$173,4,FALSE),IF('1.GHG Inventory Form'!$E$6="IPCC AR5 Report(2013)",VLOOKUP($J18,'6.GWP'!$B$1:$G$173,5,FALSE),IF('1.GHG Inventory Form'!$E$6="IPCC AR6 Report(2021)",VLOOKUP($J18,'6.GWP'!$B$2:$G$173,6,FALSE),0))))),IF(AND(AB18="V",$I18="自訂值"),IF('1.GHG Inventory Form'!$E$6="IPCC AR2 Report(1995)",VLOOKUP($K18,'6.GWP'!$B$1:$G$173,2,FALSE),IF('1.GHG Inventory Form'!$E$6="IPCC AR3 Report(2001)",VLOOKUP($K18,'6.GWP'!$B$1:$G$173,3,FALSE),IF('1.GHG Inventory Form'!$E$6="IPCC AR4 Report(2007)",VLOOKUP($K18,'6.GWP'!$B$1:$G$173,4,FALSE),IF('1.GHG Inventory Form'!$E$6="IPCC AR5 Report(2013)",VLOOKUP($K18,'6.GWP'!$B$1:$G$173,5,FALSE),IF('1.GHG Inventory Form'!$E$6="IPCC AR6 Report(2021)",VLOOKUP($K18,'6.GWP'!$B$2:$G$173,6,FALSE),0))))),0)),0) -> 0 | AR18: =IFERROR(IF(AND(AC18="V",$I18="預設值"),IF('1.GHG Inventory Form'!$E$6="IPCC AR2 Report(1995)",VLOOKUP($J18,'6.GWP'!$B$1:$G$173,2,FALSE),IF('1.GHG Inventory Form'!$E$6="IPCC AR3 Report(2001)",VLOOKUP($J18,'6.GWP'!$B$1:$G$173,3,FALSE),IF('1.GHG Inventory Form'!$E$6="IPCC AR4 Report(2007)",VLOOKUP($J18,'6.GWP'!$B$1:$G$173,4,FALSE),IF('1.GHG Inventory Form'!$E$6="IPCC AR5 Report(2013)",VLOOKUP($J18,'6.GWP'!$B$1:$G$173,5,FALSE),IF('1.GHG Inventory Form'!$E$6="IPCC AR6 Report(2021)",VLOOKUP($J18,'6.GWP'!$B$2:$G$173,6,FALSE),0))))),IF(AND(AC18="V",$I18="自訂值"),IF('1.GHG Inventory Form'!$E$6="IPCC AR2 Report(1995)",VLOOKUP($K18,'6.GWP'!$B$1:$G$173,2,FALSE),IF('1.GHG Inventory Form'!$E$6="IPCC AR3 Report(2001)",VLOOKUP($K18,'6.GWP'!$B$1:$G$173,3,FALSE),IF('1.GHG Inventory Form'!$E$6="IPCC AR4 Report(2007)",VLOOKUP($K18,'6.GWP'!$B$1:$G$173,4,FALSE),IF('1.GHG Inventory Form'!$E$6="IPCC AR5 Report(2013)",VLOOKUP($K18,'6.GWP'!$B$1:$G$173,5,FALSE),IF('1.GHG Inventory Form'!$E$6="IPCC AR6 Report(2021)",VLOOKUP($K18,'6.GWP'!$B$2:$G$173,6,FALSE),0))))),0)),0) -> 0 | AS18: =IF(AD18="V",IF('1.GHG Inventory Form'!$E$6="IPCC AR2 Report(1995)",'6.GWP'!$C$5,IF('1.GHG Inventory Form'!$E$6="IPCC AR3 Report(2001)",'6.GWP'!$D$5,IF('1.GHG Inventory Form'!$E$6="IPCC AR4 Report(2007)",'6.GWP'!$E$5,IF('1.GHG Inventory Form'!$E$6="IPCC AR5 Report(2013)",'6.GWP'!$F$5,IF('1.GHG Inventory Form'!$E$6="IPCC AR6 Report(2021)",'6.GWP'!$G$5,0))))),0) -> 0 | AT18: =IF(AE18="V",IF('1.GHG Inventory Form'!$E$6="IPCC AR2 Report(1995)",'6.GWP'!$C$4,IF('1.GHG Inventory Form'!$E$6="IPCC AR3 Report(2001)",'6.GWP'!$D$4,IF('1.GHG Inventory Form'!$E$6="IPCC AR4 Report(2007)",'6.GWP'!$E$4,IF('1.GHG Inventory Form'!$E$6="IPCC AR5 Report(2013)",'6.GWP'!$F$4,IF('1.GHG Inventory Form'!$E$6="IPCC AR6 Report(2021)",'6.GWP'!$G$4,0))))),0) -> 0 | AU18: =IFERROR($L18*AF18*AN18,"") | AV18: =IFERROR($L18*AG18*AO18,"") | AW18: =IFERROR($L18*AH18*AP18,"") | AX18: =IFERROR($L18*AI18*AQ18,"") | AY18: =IFERROR($L18*AJ18*AR18,"") | AZ18: =IFERROR($L18*AK18*AS18,"") | BA18: =IFERROR($L18*AL18*AT18,"") | BB18: =ROUND(SUM(AU18:BA18),4) -> 0 | BC18: =BB18/SUM($BB$16:$BB$99) -> 0 | BD18: =BB18/$BB$169 -> 0 | BI18: =IF(H18="","",IF(I18="預設值Default",H18&J18,IF(I18="自訂值Custom Value",H18&K18,""))) | BJ18: =IF(H18="其它設備，請說明","",IF(O18=0,"",O18)) | BK18: =IF(H18="","",IF(I18="預設值Default",AM18,IF(I18="自訂值Custom Value",X18,"")))
A19: 4 | I19: 預設值Default | M19: =IFERROR(IF(I19="預設值Default",VLOOKUP($J19,'4.Default Emission Factor'!$D:$V,16,FALSE),"請填寫自訂活動數據單位Please fill in Custom Unit"),"請選擇預設排放係數名稱Please Choose Default Fuel or Greenhouse Gas") -> 請選擇預設排放係數名稱Please Choose Default Fuel or Greenhouse Gas | Y19: =IF(AF19>0.0000000001,"V","") | Z19: =IF(AG19>0.0000000001,"V","") | AA19: =IF(AH19>0.0000000001,"V","") | AB19: =IF(AI19>0.0000000001,"V","") | AC19: =IF(AJ19>0.0000000001,"V","") | AD19: =IF(AK19>0.0000000001,"V","") | AE19: =IF(AL19>0.0000000001,"V","") | AF19: =IFERROR(IF($I19="預設值Default",ROUND(VLOOKUP($J19,'4.Default Emission Factor'!$D:$V,2,FALSE),10),IF($I19="自訂值Custom Value",P19,0)),0) -> 0 | AG19: =IFERROR(IF($I19="預設值Default",ROUND(VLOOKUP($J19,'4.Default Emission Factor'!$D:$V,4,FALSE),10),IF($I19="自訂值Custom Value",Q19,0)),0) -> 0 | AH19: =IFERROR(IF($I19="預設值Default",ROUND(VLOOKUP($J19,'4.Default Emission Factor'!$D:$V,6,FALSE),10),IF($I19="自訂值Custom Value",R19,0)),0) -> 0 | AI19: =IFERROR(IF($I19="預設值Default",ROUND(VLOOKUP($J19,'4.Default Emission Factor'!$D:$V,8,FALSE),10),IF($I19="自訂值Custom Value",S19,0)),0) -> 0 | AJ19: =IFERROR(IF($I19="預設值Default",ROUND(VLOOKUP($J19,'4.Default Emission Factor'!$D:$V,10,FALSE),10),IF($I19="自訂值Custom Value",T19,0)),0) -> 0 | AK19: =IFERROR(IF($I19="預設值Default",ROUND(VLOOKUP($J19,'4.Default Emission Factor'!$D:$V,12,FALSE),10),IF($I19="自訂值Custom Value",U19,0)),0) -> 0 | AL19: =IFERROR(IF($I19="預設值Default",ROUND(VLOOKUP($J19,'4.Default Emission Factor'!$D:$V,14,FALSE),10),IF($I19="自訂值Custom Value",V19,0)),0) -> 0 | AM19: =IFERROR(IF(I19="預設值Default",VLOOKUP($J19,'4.Default Emission Factor'!$D:$V,17,FALSE),IF(I19="自訂值Custom Value",X19,"")),"") | AN19: =IF(Y19="V",1,0) -> 0 | AO19: =IF(Z19="V",IF('1.GHG Inventory Form'!$E$6="IPCC AR2 Report(1995)",'6.GWP'!$C$2,IF('1.GHG Inventory Form'!$E$6="IPCC AR3 Report(2001)",'6.GWP'!$D$2,IF('1.GHG Inventory Form'!$E$6="IPCC AR4 Report(2007)",'6.GWP'!$E$2,IF('1.GHG Inventory Form'!$E$6="IPCC AR5 Report(2013)",'6.GWP'!$F$2,IF('1.GHG Inventory Form'!$E$6="IPCC AR6 Report(2021)",'6.GWP'!$G$2,0))))),0) -> 0 | AP19: =IF(AA19="V",IF('1.GHG Inventory Form'!$E$6="IPCC AR2 Report(1995)",'6.GWP'!$C$3,IF('1.GHG Inventory Form'!$E$6="IPCC AR3 Report(2001)",'6.GWP'!$D$3,IF('1.GHG Inventory Form'!$E$6="IPCC AR4 Report(2007)",'6.GWP'!$E$3,IF('1.GHG Inventory Form'!$E$6="IPCC AR5 Report(2013)",'6.GWP'!$F$3,IF('1.GHG Inventory Form'!$E$6="IPCC AR6 Report(2021)",'6.GWP'!$G$3,0))))),0) -> 0 | AQ19: =IFERROR(IF(AND(AB19="V",$I19="預設值"),IF('1.GHG Inventory Form'!$E$6="IPCC AR2 Report(1995)",VLOOKUP($J19,'6.GWP'!$B$1:$G$173,2,FALSE),IF('1.GHG Inventory Form'!$E$6="IPCC AR3 Report(2001)",VLOOKUP($J19,'6.GWP'!$B$1:$G$173,3,FALSE),IF('1.GHG Inventory Form'!$E$6="IPCC AR4 Report(2007)",VLOOKUP($J19,'6.GWP'!$B$1:$G$173,4,FALSE),IF('1.GHG Inventory Form'!$E$6="IPCC AR5 Report(2013)",VLOOKUP($J19,'6.GWP'!$B$1:$G$173,5,FALSE),IF('1.GHG Inventory Form'!$E$6="IPCC AR6 Report(2021)",VLOOKUP($J19,'6.GWP'!$B$2:$G$173,6,FALSE),0))))),IF(AND(AB19="V",$I19="自訂值"),IF('1.GHG Inventory Form'!$E$6="IPCC AR2 Report(1995)",VLOOKUP($K19,'6.GWP'!$B$1:$G$173,2,FALSE),IF('1.GHG Inventory Form'!$E$6="IPCC AR3 Report(2001)",VLOOKUP($K19,'6.GWP'!$B$1:$G$173,3,FALSE),IF('1.GHG Inventory Form'!$E$6="IPCC AR4 Report(2007)",VLOOKUP($K19,'6.GWP'!$B$1:$G$173,4,FALSE),IF('1.GHG Inventory Form'!$E$6="IPCC AR5 Report(2013)",VLOOKUP($K19,'6.GWP'!$B$1:$G$173,5,FALSE),IF('1.GHG Inventory Form'!$E$6="IPCC AR6 Report(2021)",VLOOKUP($K19,'6.GWP'!$B$2:$G$173,6,FALSE),0))))),0)),0) -> 0 | AR19: =IFERROR(IF(AND(AC19="V",$I19="預設值"),IF('1.GHG Inventory Form'!$E$6="IPCC AR2 Report(1995)",VLOOKUP($J19,'6.GWP'!$B$1:$G$173,2,FALSE),IF('1.GHG Inventory Form'!$E$6="IPCC AR3 Report(2001)",VLOOKUP($J19,'6.GWP'!$B$1:$G$173,3,FALSE),IF('1.GHG Inventory Form'!$E$6="IPCC AR4 Report(2007)",VLOOKUP($J19,'6.GWP'!$B$1:$G$173,4,FALSE),IF('1.GHG Inventory Form'!$E$6="IPCC AR5 Report(2013)",VLOOKUP($J19,'6.GWP'!$B$1:$G$173,5,FALSE),IF('1.GHG Inventory Form'!$E$6="IPCC AR6 Report(2021)",VLOOKUP($J19,'6.GWP'!$B$2:$G$173,6,FALSE),0))))),IF(AND(AC19="V",$I19="自訂值"),IF('1.GHG Inventory Form'!$E$6="IPCC AR2 Report(1995)",VLOOKUP($K19,'6.GWP'!$B$1:$G$173,2,FALSE),IF('1.GHG Inventory Form'!$E$6="IPCC AR3 Report(2001)",VLOOKUP($K19,'6.GWP'!$B$1:$G$173,3,FALSE),IF('1.GHG Inventory Form'!$E$6="IPCC AR4 Report(2007)",VLOOKUP($K19,'6.GWP'!$B$1:$G$173,4,FALSE),IF('1.GHG Inventory Form'!$E$6="IPCC AR5 Report(2013)",VLOOKUP($K19,'6.GWP'!$B$1:$G$173,5,FALSE),IF('1.GHG Inventory Form'!$E$6="IPCC AR6 Report(2021)",VLOOKUP($K19,'6.GWP'!$B$2:$G$173,6,FALSE),0))))),0)),0) -> 0 | AS19: =IF(AD19="V",IF('1.GHG Inventory Form'!$E$6="IPCC AR2 Report(1995)",'6.GWP'!$C$5,IF('1.GHG Inventory Form'!$E$6="IPCC AR3 Report(2001)",'6.GWP'!$D$5,IF('1.GHG Inventory Form'!$E$6="IPCC AR4 Report(2007)",'6.GWP'!$E$5,IF('1.GHG Inventory Form'!$E$6="IPCC AR5 Report(2013)",'6.GWP'!$F$5,IF('1.GHG Inventory Form'!$E$6="IPCC AR6 Report(2021)",'6.GWP'!$G$5,0))))),0) -> 0 | AT19: =IF(AE19="V",IF('1.GHG Inventory Form'!$E$6="IPCC AR2 Report(1995)",'6.GWP'!$C$4,IF('1.GHG Inventory Form'!$E$6="IPCC AR3 Report(2001)",'6.GWP'!$D$4,IF('1.GHG Inventory Form'!$E$6="IPCC AR4 Report(2007)",'6.GWP'!$E$4,IF('1.GHG Inventory Form'!$E$6="IPCC AR5 Report(2013)",'6.GWP'!$F$4,IF('1.GHG Inventory Form'!$E$6="IPCC AR6 Report(2021)",'6.GWP'!$G$4,0))))),0) -> 0 | AU19: =IFERROR($L19*AF19*AN19,"") | AV19: =IFERROR($L19*AG19*AO19,"") | AW19: =IFERROR($L19*AH19*AP19,"") | AX19: =IFERROR($L19*AI19*AQ19,"") | AY19: =IFERROR($L19*AJ19*AR19,"") | AZ19: =IFERROR($L19*AK19*AS19,"") | BA19: =IFERROR($L19*AL19*AT19,"") | BB19: =ROUND(SUM(AU19:BA19),4) -> 0 | BC19: =BB19/SUM($BB$16:$BB$99) -> 0 | BD19: =BB19/$BB$169 -> 0 | BI19: =IF(H19="","",IF(I19="預設值Default",H19&J19,IF(I19="自訂值Custom Value",H19&K19,""))) | BJ19: =IF(H19="其它設備，請說明","",IF(O19=0,"",O19)) | BK19: =IF(H19="","",IF(I19="預設值Default",AM19,IF(I19="自訂值Custom Value",X19,"")))
A20: 5 | I20: 預設值Default | M20: =IFERROR(IF(I20="預設值Default",VLOOKUP($J20,'4.Default Emission Factor'!$D:$V,16,FALSE),"請填寫自訂活動數據單位Please fill in Custom Unit"),"請選擇預設排放係數名稱Please Choose Default Fuel or Greenhouse Gas") -> 請選擇預設排放係數名稱Please Choose Default Fuel or Greenhouse Gas | Y20: =IF(AF20>0.0000000001,"V","") | Z20: =IF(AG20>0.0000000001,"V","") | AA20: =IF(AH20>0.0000000001,"V","") | AB20: =IF(AI20>0.0000000001,"V","") | AC20: =IF(AJ20>0.0000000001,"V","") | AD20: =IF(AK20>0.0000000001,"V","") | AE20: =IF(AL20>0.0000000001,"V","") | AF20: =IFERROR(IF($I20="預設值Default",ROUND(VLOOKUP($J20,'4.Default Emission Factor'!$D:$V,2,FALSE),10),IF($I20="自訂值Custom Value",P20,0)),0) -> 0 | AG20: =IFERROR(IF($I20="預設值Default",ROUND(VLOOKUP($J20,'4.Default Emission Factor'!$D:$V,4,FALSE),10),IF($I20="自訂值Custom Value",Q20,0)),0) -> 0 | AH20: =IFERROR(IF($I20="預設值Default",ROUND(VLOOKUP($J20,'4.Default Emission Factor'!$D:$V,6,FALSE),10),IF($I20="自訂值Custom Value",R20,0)),0) -> 0 | AI20: =IFERROR(IF($I20="預設值Default",ROUND(VLOOKUP($J20,'4.Default Emission Factor'!$D:$V,8,FALSE),10),IF($I20="自訂值Custom Value",S20,0)),0) -> 0 | AJ20: =IFERROR(IF($I20="預設值Default",ROUND(VLOOKUP($J20,'4.Default Emission Factor'!$D:$V,10,FALSE),10),IF($I20="自訂值Custom Value",T20,0)),0) -> 0 | AK20: =IFERROR(IF($I20="預設值Default",ROUND(VLOOKUP($J20,'4.Default Emission Factor'!$D:$V,12,FALSE),10),IF($I20="自訂值Custom Value",U20,0)),0) -> 0 | AL20: =IFERROR(IF($I20="預設值Default",ROUND(VLOOKUP($J20,'4.Default Emission Factor'!$D:$V,14,FALSE),10),IF($I20="自訂值Custom Value",V20,0)),0) -> 0 | AM20: =IFERROR(IF(I20="預設值Default",VLOOKUP($J20,'4.Default Emission Factor'!$D:$V,17,FALSE),IF(I20="自訂值Custom Value",X20,"")),"") | AN20: =IF(Y20="V",1,0) -> 0 | AO20: =IF(Z20="V",IF('1.GHG Inventory Form'!$E$6="IPCC AR2 Report(1995)",'6.GWP'!$C$2,IF('1.GHG Inventory Form'!$E$6="IPCC AR3 Report(2001)",'6.GWP'!$D$2,IF('1.GHG Inventory Form'!$E$6="IPCC AR4 Report(2007)",'6.GWP'!$E$2,IF('1.GHG Inventory Form'!$E$6="IPCC AR5 Report(2013)",'6.GWP'!$F$2,IF('1.GHG Inventory Form'!$E$6="IPCC AR6 Report(2021)",'6.GWP'!$G$2,0))))),0) -> 0 | AP20: =IF(AA20="V",IF('1.GHG Inventory Form'!$E$6="IPCC AR2 Report(1995)",'6.GWP'!$C$3,IF('1.GHG Inventory Form'!$E$6="IPCC AR3 Report(2001)",'6.GWP'!$D$3,IF('1.GHG Inventory Form'!$E$6="IPCC AR4 Report(2007)",'6.GWP'!$E$3,IF('1.GHG Inventory Form'!$E$6="IPCC AR5 Report(2013)",'6.GWP'!$F$3,IF('1.GHG Inventory Form'!$E$6="IPCC AR6 Report(2021)",'6.GWP'!$G$3,0))))),0) -> 0 | AQ20: =IFERROR(IF(AND(AB20="V",$I20="預設值"),IF('1.GHG Inventory Form'!$E$6="IPCC AR2 Report(1995)",VLOOKUP($J20,'6.GWP'!$B$1:$G$173,2,FALSE),IF('1.GHG Inventory Form'!$E$6="IPCC AR3 Report(2001)",VLOOKUP($J20,'6.GWP'!$B$1:$G$173,3,FALSE),IF('1.GHG Inventory Form'!$E$6="IPCC AR4 Report(2007)",VLOOKUP($J20,'6.GWP'!$B$1:$G$173,4,FALSE),IF('1.GHG Inventory Form'!$E$6="IPCC AR5 Report(2013)",VLOOKUP($J20,'6.GWP'!$B$1:$G$173,5,FALSE),IF('1.GHG Inventory Form'!$E$6="IPCC AR6 Report(2021)",VLOOKUP($J20,'6.GWP'!$B$2:$G$173,6,FALSE),0))))),IF(AND(AB20="V",$I20="自訂值"),IF('1.GHG Inventory Form'!$E$6="IPCC AR2 Report(1995)",VLOOKUP($K20,'6.GWP'!$B$1:$G$173,2,FALSE),IF('1.GHG Inventory Form'!$E$6="IPCC AR3 Report(2001)",VLOOKUP($K20,'6.GWP'!$B$1:$G$173,3,FALSE),IF('1.GHG Inventory Form'!$E$6="IPCC AR4 Report(2007)",VLOOKUP($K20,'6.GWP'!$B$1:$G$173,4,FALSE),IF('1.GHG Inventory Form'!$E$6="IPCC AR5 Report(2013)",VLOOKUP($K20,'6.GWP'!$B$1:$G$173,5,FALSE),IF('1.GHG Inventory Form'!$E$6="IPCC AR6 Report(2021)",VLOOKUP($K20,'6.GWP'!$B$2:$G$173,6,FALSE),0))))),0)),0) -> 0 | AR20: =IFERROR(IF(AND(AC20="V",$I20="預設值"),IF('1.GHG Inventory Form'!$E$6="IPCC AR2 Report(1995)",VLOOKUP($J20,'6.GWP'!$B$1:$G$173,2,FALSE),IF('1.GHG Inventory Form'!$E$6="IPCC AR3 Report(2001)",VLOOKUP($J20,'6.GWP'!$B$1:$G$173,3,FALSE),IF('1.GHG Inventory Form'!$E$6="IPCC AR4 Report(2007)",VLOOKUP($J20,'6.GWP'!$B$1:$G$173,4,FALSE),IF('1.GHG Inventory Form'!$E$6="IPCC AR5 Report(2013)",VLOOKUP($J20,'6.GWP'!$B$1:$G$173,5,FALSE),IF('1.GHG Inventory Form'!$E$6="IPCC AR6 Report(2021)",VLOOKUP($J20,'6.GWP'!$B$2:$G$173,6,FALSE),0))))),IF(AND(AC20="V",$I20="自訂值"),IF('1.GHG Inventory Form'!$E$6="IPCC AR2 Report(1995)",VLOOKUP($K20,'6.GWP'!$B$1:$G$173,2,FALSE),IF('1.GHG Inventory Form'!$E$6="IPCC AR3 Report(2001)",VLOOKUP($K20,'6.GWP'!$B$1:$G$173,3,FALSE),IF('1.GHG Inventory Form'!$E$6="IPCC AR4 Report(2007)",VLOOKUP($K20,'6.GWP'!$B$1:$G$173,4,FALSE),IF('1.GHG Inventory Form'!$E$6="IPCC AR5 Report(2013)",VLOOKUP($K20,'6.GWP'!$B$1:$G$173,5,FALSE),IF('1.GHG Inventory Form'!$E$6="IPCC AR6 Report(2021)",VLOOKUP($K20,'6.GWP'!$B$2:$G$173,6,FALSE),0))))),0)),0) -> 0 | AS20: =IF(AD20="V",IF('1.GHG Inventory Form'!$E$6="IPCC AR2 Report(1995)",'6.GWP'!$C$5,IF('1.GHG Inventory Form'!$E$6="IPCC AR3 Report(2001)",'6.GWP'!$D$5,IF('1.GHG Inventory Form'!$E$6="IPCC AR4 Report(2007)",'6.GWP'!$E$5,IF('1.GHG Inventory Form'!$E$6="IPCC AR5 Report(2013)",'6.GWP'!$F$5,IF('1.GHG Inventory Form'!$E$6="IPCC AR6 Report(2021)",'6.GWP'!$G$5,0))))),0) -> 0 | AT20: =IF(AE20="V",IF('1.GHG Inventory Form'!$E$6="IPCC AR2 Report(1995)",'6.GWP'!$C$4,IF('1.GHG Inventory Form'!$E$6="IPCC AR3 Report(2001)",'6.GWP'!$D$4,IF('1.GHG Inventory Form'!$E$6="IPCC AR4 Report(2007)",'6.GWP'!$E$4,IF('1.GHG Inventory Form'!$E$6="IPCC AR5 Report(2013)",'6.GWP'!$F$4,IF('1.GHG Inventory Form'!$E$6="IPCC AR6 Report(2021)",'6.GWP'!$G$4,0))))),0) -> 0 | AU20: =IFERROR($L20*AF20*AN20,"") | AV20: =IFERROR($L20*AG20*AO20,"") | AW20: =IFERROR($L20*AH20*AP20,"") | AX20: =IFERROR($L20*AI20*AQ20,"") | AY20: =IFERROR($L20*AJ20*AR20,"") | AZ20: =IFERROR($L20*AK20*AS20,"") | BA20: =IFERROR($L20*AL20*AT20,"") | BB20: =ROUND(SUM(AU20:BA20),4) -> 0 | BC20: =BB20/SUM($BB$16:$BB$99) -> 0 | BD20: =BB20/$BB$169 -> 0 | BI20: =IF(H20="","",IF(I20="預設值Default",H20&J20,IF(I20="自訂值Custom Value",H20&K20,""))) | BJ20: =IF(H20="其它設備，請說明","",IF(O20=0,"",O20)) | BK20: =IF(H20="","",IF(I20="預設值Default",AM20,IF(I20="自訂值Custom Value",X20,"")))
A21: 6 | I21: 預設值Default | M21: =IFERROR(IF(I21="預設值Default",VLOOKUP($J21,'4.Default Emission Factor'!$D:$V,16,FALSE),"請填寫自訂活動數據單位Please fill in Custom Unit"),"請選擇預設排放係數名稱Please Choose Default Fuel or Greenhouse Gas") -> 請選擇預設排放係數名稱Please Choose Default Fuel or Greenhouse Gas | Y21: =IF(AF21>0.0000000001,"V","") | Z21: =IF(AG21>0.0000000001,"V","") | AA21: =IF(AH21>0.0000000001,"V","") | AB21: =IF(AI21>0.0000000001,"V","") | AC21: =IF(AJ21>0.0000000001,"V","") | AD21: =IF(AK21>0.0000000001,"V","") | AE21: =IF(AL21>0.0000000001,"V","") | AF21: =IFERROR(IF($I21="預設值Default",ROUND(VLOOKUP($J21,'4.Default Emission Factor'!$D:$V,2,FALSE),10),IF($I21="自訂值Custom Value",P21,0)),0) -> 0 | AG21: =IFERROR(IF($I21="預設值Default",ROUND(VLOOKUP($J21,'4.Default Emission Factor'!$D:$V,4,FALSE),10),IF($I21="自訂值Custom Value",Q21,0)),0) -> 0 | AH21: =IFERROR(IF($I21="預設值Default",ROUND(VLOOKUP($J21,'4.Default Emission Factor'!$D:$V,6,FALSE),10),IF($I21="自訂值Custom Value",R21,0)),0) -> 0 | AI21: =IFERROR(IF($I21="預設值Default",ROUND(VLOOKUP($J21,'4.Default Emission Factor'!$D:$V,8,FALSE),10),IF($I21="自訂值Custom Value",S21,0)),0) -> 0 | AJ21: =IFERROR(IF($I21="預設值Default",ROUND(VLOOKUP($J21,'4.Default Emission Factor'!$D:$V,10,FALSE),10),IF($I21="自訂值Custom Value",T21,0)),0) -> 0 | AK21: =IFERROR(IF($I21="預設值Default",ROUND(VLOOKUP($J21,'4.Default Emission Factor'!$D:$V,12,FALSE),10),IF($I21="自訂值Custom Value",U21,0)),0) -> 0 | AL21: =IFERROR(IF($I21="預設值Default",ROUND(VLOOKUP($J21,'4.Default Emission Factor'!$D:$V,14,FALSE),10),IF($I21="自訂值Custom Value",V21,0)),0) -> 0 | AM21: =IFERROR(IF(I21="預設值Default",VLOOKUP($J21,'4.Default Emission Factor'!$D:$V,17,FALSE),IF(I21="自訂值Custom Value",X21,"")),"") | AN21: =IF(Y21="V",1,0) -> 0 | AO21: =IF(Z21="V",IF('1.GHG Inventory Form'!$E$6="IPCC AR2 Report(1995)",'6.GWP'!$C$2,IF('1.GHG Inventory Form'!$E$6="IPCC AR3 Report(2001)",'6.GWP'!$D$2,IF('1.GHG Inventory Form'!$E$6="IPCC AR4 Report(2007)",'6.GWP'!$E$2,IF('1.GHG Inventory Form'!$E$6="IPCC AR5 Report(2013)",'6.GWP'!$F$2,IF('1.GHG Inventory Form'!$E$6="IPCC AR6 Report(2021)",'6.GWP'!$G$2,0))))),0) -> 0 | AP21: =IF(AA21="V",IF('1.GHG Inventory Form'!$E$6="IPCC AR2 Report(1995)",'6.GWP'!$C$3,IF('1.GHG Inventory Form'!$E$6="IPCC AR3 Report(2001)",'6.GWP'!$D$3,IF('1.GHG Inventory Form'!$E$6="IPCC AR4 Report(2007)",'6.GWP'!$E$3,IF('1.GHG Inventory Form'!$E$6="IPCC AR5 Report(2013)",'6.GWP'!$F$3,IF('1.GHG Inventory Form'!$E$6="IPCC AR6 Report(2021)",'6.GWP'!$G$3,0))))),0) -> 0 | AQ21: =IFERROR(IF(AND(AB21="V",$I21="預設值"),IF('1.GHG Inventory Form'!$E$6="IPCC AR2 Report(1995)",VLOOKUP($J21,'6.GWP'!$B$1:$G$173,2,FALSE),IF('1.GHG Inventory Form'!$E$6="IPCC AR3 Report(2001)",VLOOKUP($J21,'6.GWP'!$B$1:$G$173,3,FALSE),IF('1.GHG Inventory Form'!$E$6="IPCC AR4 Report(2007)",VLOOKUP($J21,'6.GWP'!$B$1:$G$173,4,FALSE),IF('1.GHG Inventory Form'!$E$6="IPCC AR5 Report(2013)",VLOOKUP($J21,'6.GWP'!$B$1:$G$173,5,FALSE),IF('1.GHG Inventory Form'!$E$6="IPCC AR6 Report(2021)",VLOOKUP($J21,'6.GWP'!$B$2:$G$173,6,FALSE),0))))),IF(AND(AB21="V",$I21="自訂值"),IF('1.GHG Inventory Form'!$E$6="IPCC AR2 Report(1995)",VLOOKUP($K21,'6.GWP'!$B$1:$G$173,2,FALSE),IF('1.GHG Inventory Form'!$E$6="IPCC AR3 Report(2001)",VLOOKUP($K21,'6.GWP'!$B$1:$G$173,3,FALSE),IF('1.GHG Inventory Form'!$E$6="IPCC AR4 Report(2007)",VLOOKUP($K21,'6.GWP'!$B$1:$G$173,4,FALSE),IF('1.GHG Inventory Form'!$E$6="IPCC AR5 Report(2013)",VLOOKUP($K21,'6.GWP'!$B$1:$G$173,5,FALSE),IF('1.GHG Inventory Form'!$E$6="IPCC AR6 Report(2021)",VLOOKUP($K21,'6.GWP'!$B$2:$G$173,6,FALSE),0))))),0)),0) -> 0 | AR21: =IFERROR(IF(AND(AC21="V",$I21="預設值"),IF('1.GHG Inventory Form'!$E$6="IPCC AR2 Report(1995)",VLOOKUP($J21,'6.GWP'!$B$1:$G$173,2,FALSE),IF('1.GHG Inventory Form'!$E$6="IPCC AR3 Report(2001)",VLOOKUP($J21,'6.GWP'!$B$1:$G$173,3,FALSE),IF('1.GHG Inventory Form'!$E$6="IPCC AR4 Report(2007)",VLOOKUP($J21,'6.GWP'!$B$1:$G$173,4,FALSE),IF('1.GHG Inventory Form'!$E$6="IPCC AR5 Report(2013)",VLOOKUP($J21,'6.GWP'!$B$1:$G$173,5,FALSE),IF('1.GHG Inventory Form'!$E$6="IPCC AR6 Report(2021)",VLOOKUP($J21,'6.GWP'!$B$2:$G$173,6,FALSE),0))))),IF(AND(AC21="V",$I21="自訂值"),IF('1.GHG Inventory Form'!$E$6="IPCC AR2 Report(1995)",VLOOKUP($K21,'6.GWP'!$B$1:$G$173,2,FALSE),IF('1.GHG Inventory Form'!$E$6="IPCC AR3 Report(2001)",VLOOKUP($K21,'6.GWP'!$B$1:$G$173,3,FALSE),IF('1.GHG Inventory Form'!$E$6="IPCC AR4 Report(2007)",VLOOKUP($K21,'6.GWP'!$B$1:$G$173,4,FALSE),IF('1.GHG Inventory Form'!$E$6="IPCC AR5 Report(2013)",VLOOKUP($K21,'6.GWP'!$B$1:$G$173,5,FALSE),IF('1.GHG Inventory Form'!$E$6="IPCC AR6 Report(2021)",VLOOKUP($K21,'6.GWP'!$B$2:$G$173,6,FALSE),0))))),0)),0) -> 0 | AS21: =IF(AD21="V",IF('1.GHG Inventory Form'!$E$6="IPCC AR2 Report(1995)",'6.GWP'!$C$5,IF('1.GHG Inventory Form'!$E$6="IPCC AR3 Report(2001)",'6.GWP'!$D$5,IF('1.GHG Inventory Form'!$E$6="IPCC AR4 Report(2007)",'6.GWP'!$E$5,IF('1.GHG Inventory Form'!$E$6="IPCC AR5 Report(2013)",'6.GWP'!$F$5,IF('1.GHG Inventory Form'!$E$6="IPCC AR6 Report(2021)",'6.GWP'!$G$5,0))))),0) -> 0 | AT21: =IF(AE21="V",IF('1.GHG Inventory Form'!$E$6="IPCC AR2 Report(1995)",'6.GWP'!$C$4,IF('1.GHG Inventory Form'!$E$6="IPCC AR3 Report(2001)",'6.GWP'!$D$4,IF('1.GHG Inventory Form'!$E$6="IPCC AR4 Report(2007)",'6.GWP'!$E$4,IF('1.GHG Inventory Form'!$E$6="IPCC AR5 Report(2013)",'6.GWP'!$F$4,IF('1.GHG Inventory Form'!$E$6="IPCC AR6 Report(2021)",'6.GWP'!$G$4,0))))),0) -> 0 | AU21: =IFERROR($L21*AF21*AN21,"") | AV21: =IFERROR($L21*AG21*AO21,"") | AW21: =IFERROR($L21*AH21*AP21,"") | AX21: =IFERROR($L21*AI21*AQ21,"") | AY21: =IFERROR($L21*AJ21*AR21,"") | AZ21: =IFERROR($L21*AK21*AS21,"") | BA21: =IFERROR($L21*AL21*AT21,"") | BB21: =ROUND(SUM(AU21:BA21),4) -> 0 | BC21: =BB21/SUM($BB$16:$BB$99) -> 0 | BD21: =BB21/$BB$169 -> 0 | BI21: =IF(H21="","",IF(I21="預設值Default",H21&J21,IF(I21="自訂值Custom Value",H21&K21,""))) | BJ21: =IF(H21="其它設備，請說明","",IF(O21=0,"",O21)) | BK21: =IF(H21="","",IF(I21="預設值Default",AM21,IF(I21="自訂值Custom Value",X21,"")))
A22: 7 | I22: 預設值Default | M22: =IFERROR(IF(I22="預設值Default",VLOOKUP($J22,'4.Default Emission Factor'!$D:$V,16,FALSE),"請填寫自訂活動數據單位Please fill in Custom Unit"),"請選擇預設排放係數名稱Please Choose Default Fuel or Greenhouse Gas") -> 請選擇預設排放係數名稱Please Choose Default Fuel or Greenhouse Gas | Y22: =IF(AF22>0.0000000001,"V","") | Z22: =IF(AG22>0.0000000001,"V","") | AA22: =IF(AH22>0.0000000001,"V","") | AB22: =IF(AI22>0.0000000001,"V","") | AC22: =IF(AJ22>0.0000000001,"V","") | AD22: =IF(AK22>0.0000000001,"V","") | AE22: =IF(AL22>0.0000000001,"V","") | AF22: =IFERROR(IF($I22="預設值Default",ROUND(VLOOKUP($J22,'4.Default Emission Factor'!$D:$V,2,FALSE),10),IF($I22="自訂值Custom Value",P22,0)),0) -> 0 | AG22: =IFERROR(IF($I22="預設值Default",ROUND(VLOOKUP($J22,'4.Default Emission Factor'!$D:$V,4,FALSE),10),IF($I22="自訂值Custom Value",Q22,0)),0) -> 0 | AH22: =IFERROR(IF($I22="預設值Default",ROUND(VLOOKUP($J22,'4.Default Emission Factor'!$D:$V,6,FALSE),10),IF($I22="自訂值Custom Value",R22,0)),0) -> 0 | AI22: =IFERROR(IF($I22="預設值Default",ROUND(VLOOKUP($J22,'4.Default Emission Factor'!$D:$V,8,FALSE),10),IF($I22="自訂值Custom Value",S22,0)),0) -> 0 | AJ22: =IFERROR(IF($I22="預設值Default",ROUND(VLOOKUP($J22,'4.Default Emission Factor'!$D:$V,10,FALSE),10),IF($I22="自訂值Custom Value",T22,0)),0) -> 0 | AK22: =IFERROR(IF($I22="預設值Default",ROUND(VLOOKUP($J22,'4.Default Emission Factor'!$D:$V,12,FALSE),10),IF($I22="自訂值Custom Value",U22,0)),0) -> 0 | AL22: =IFERROR(IF($I22="預設值Default",ROUND(VLOOKUP($J22,'4.Default Emission Factor'!$D:$V,14,FALSE),10),IF($I22="自訂值Custom Value",V22,0)),0) -> 0 | AM22: =IFERROR(IF(I22="預設值Default",VLOOKUP($J22,'4.Default Emission Factor'!$D:$V,17,FALSE),IF(I22="自訂值Custom Value",X22,"")),"") | AN22: =IF(Y22="V",1,0) -> 0 | AO22: =IF(Z22="V",IF('1.GHG Inventory Form'!$E$6="IPCC AR2 Report(1995)",'6.GWP'!$C$2,IF('1.GHG Inventory Form'!$E$6="IPCC AR3 Report(2001)",'6.GWP'!$D$2,IF('1.GHG Inventory Form'!$E$6="IPCC AR4 Report(2007)",'6.GWP'!$E$2,IF('1.GHG Inventory Form'!$E$6="IPCC AR5 Report(2013)",'6.GWP'!$F$2,IF('1.GHG Inventory Form'!$E$6="IPCC AR6 Report(2021)",'6.GWP'!$G$2,0))))),0) -> 0 | AP22: =IF(AA22="V",IF('1.GHG Inventory Form'!$E$6="IPCC AR2 Report(1995)",'6.GWP'!$C$3,IF('1.GHG Inventory Form'!$E$6="IPCC AR3 Report(2001)",'6.GWP'!$D$3,IF('1.GHG Inventory Form'!$E$6="IPCC AR4 Report(2007)",'6.GWP'!$E$3,IF('1.GHG Inventory Form'!$E$6="IPCC AR5 Report(2013)",'6.GWP'!$F$3,IF('1.GHG Inventory Form'!$E$6="IPCC AR6 Report(2021)",'6.GWP'!$G$3,0))))),0) -> 0 | AQ22: =IFERROR(IF(AND(AB22="V",$I22="預設值"),IF('1.GHG Inventory Form'!$E$6="IPCC AR2 Report(1995)",VLOOKUP($J22,'6.GWP'!$B$1:$G$173,2,FALSE),IF('1.GHG Inventory Form'!$E$6="IPCC AR3 Report(2001)",VLOOKUP($J22,'6.GWP'!$B$1:$G$173,3,FALSE),IF('1.GHG Inventory Form'!$E$6="IPCC AR4 Report(2007)",VLOOKUP($J22,'6.GWP'!$B$1:$G$173,4,FALSE),IF('1.GHG Inventory Form'!$E$6="IPCC AR5 Report(2013)",VLOOKUP($J22,'6.GWP'!$B$1:$G$173,5,FALSE),IF('1.GHG Inventory Form'!$E$6="IPCC AR6 Report(2021)",VLOOKUP($J22,'6.GWP'!$B$2:$G$173,6,FALSE),0))))),IF(AND(AB22="V",$I22="自訂值"),IF('1.GHG Inventory Form'!$E$6="IPCC AR2 Report(1995)",VLOOKUP($K22,'6.GWP'!$B$1:$G$173,2,FALSE),IF('1.GHG Inventory Form'!$E$6="IPCC AR3 Report(2001)",VLOOKUP($K22,'6.GWP'!$B$1:$G$173,3,FALSE),IF('1.GHG Inventory Form'!$E$6="IPCC AR4 Report(2007)",VLOOKUP($K22,'6.GWP'!$B$1:$G$173,4,FALSE),IF('1.GHG Inventory Form'!$E$6="IPCC AR5 Report(2013)",VLOOKUP($K22,'6.GWP'!$B$1:$G$173,5,FALSE),IF('1.GHG Inventory Form'!$E$6="IPCC AR6 Report(2021)",VLOOKUP($K22,'6.GWP'!$B$2:$G$173,6,FALSE),0))))),0)),0) -> 0 | AR22: =IFERROR(IF(AND(AC22="V",$I22="預設值"),IF('1.GHG Inventory Form'!$E$6="IPCC AR2 Report(1995)",VLOOKUP($J22,'6.GWP'!$B$1:$G$173,2,FALSE),IF('1.GHG Inventory Form'!$E$6="IPCC AR3 Report(2001)",VLOOKUP($J22,'6.GWP'!$B$1:$G$173,3,FALSE),IF('1.GHG Inventory Form'!$E$6="IPCC AR4 Report(2007)",VLOOKUP($J22,'6.GWP'!$B$1:$G$173,4,FALSE),IF('1.GHG Inventory Form'!$E$6="IPCC AR5 Report(2013)",VLOOKUP($J22,'6.GWP'!$B$1:$G$173,5,FALSE),IF('1.GHG Inventory Form'!$E$6="IPCC AR6 Report(2021)",VLOOKUP($J22,'6.GWP'!$B$2:$G$173,6,FALSE),0))))),IF(AND(AC22="V",$I22="自訂值"),IF('1.GHG Inventory Form'!$E$6="IPCC AR2 Report(1995)",VLOOKUP($K22,'6.GWP'!$B$1:$G$173,2,FALSE),IF('1.GHG Inventory Form'!$E$6="IPCC AR3 Report(2001)",VLOOKUP($K22,'6.GWP'!$B$1:$G$173,3,FALSE),IF('1.GHG Inventory Form'!$E$6="IPCC AR4 Report(2007)",VLOOKUP($K22,'6.GWP'!$B$1:$G$173,4,FALSE),IF('1.GHG Inventory Form'!$E$6="IPCC AR5 Report(2013)",VLOOKUP($K22,'6.GWP'!$B$1:$G$173,5,FALSE),IF('1.GHG Inventory Form'!$E$6="IPCC AR6 Report(2021)",VLOOKUP($K22,'6.GWP'!$B$2:$G$173,6,FALSE),0))))),0)),0) -> 0 | AS22: =IF(AD22="V",IF('1.GHG Inventory Form'!$E$6="IPCC AR2 Report(1995)",'6.GWP'!$C$5,IF('1.GHG Inventory Form'!$E$6="IPCC AR3 Report(2001)",'6.GWP'!$D$5,IF('1.GHG Inventory Form'!$E$6="IPCC AR4 Report(2007)",'6.GWP'!$E$5,IF('1.GHG Inventory Form'!$E$6="IPCC AR5 Report(2013)",'6.GWP'!$F$5,IF('1.GHG Inventory Form'!$E$6="IPCC AR6 Report(2021)",'6.GWP'!$G$5,0))))),0) -> 0 | AT22: =IF(AE22="V",IF('1.GHG Inventory Form'!$E$6="IPCC AR2 Report(1995)",'6.GWP'!$C$4,IF('1.GHG Inventory Form'!$E$6="IPCC AR3 Report(2001)",'6.GWP'!$D$4,IF('1.GHG Inventory Form'!$E$6="IPCC AR4 Report(2007)",'6.GWP'!$E$4,IF('1.GHG Inventory Form'!$E$6="IPCC AR5 Report(2013)",'6.GWP'!$F$4,IF('1.GHG Inventory Form'!$E$6="IPCC AR6 Report(2021)",'6.GWP'!$G$4,0))))),0) -> 0 | AU22: =IFERROR($L22*AF22*AN22,"") | AV22: =IFERROR($L22*AG22*AO22,"") | AW22: =IFERROR($L22*AH22*AP22,"") | AX22: =IFERROR($L22*AI22*AQ22,"") | AY22: =IFERROR($L22*AJ22*AR22,"") | AZ22: =IFERROR($L22*AK22*AS22,"") | BA22: =IFERROR($L22*AL22*AT22,"") | BB22: =ROUND(SUM(AU22:BA22),4) -> 0 | BC22: =BB22/SUM($BB$16:$BB$99) -> 0 | BD22: =BB22/$BB$169 -> 0 | BI22: =IF(H22="","",IF(I22="預設值Default",H22&J22,IF(I22="自訂值Custom Value",H22&K22,""))) | BJ22: =IF(H22="其它設備，請說明","",IF(O22=0,"",O22)) | BK22: =IF(H22="","",IF(I22="預設值Default",AM22,IF(I22="自訂值Custom Value",X22,"")))
A23: 8 | I23: 預設值Default | M23: =IFERROR(IF(I23="預設值Default",VLOOKUP($J23,'4.Default Emission Factor'!$D:$V,16,FALSE),"請填寫自訂活動數據單位Please fill in Custom Unit"),"請選擇預設排放係數名稱Please Choose Default Fuel or Greenhouse Gas") -> 請選擇預設排放係數名稱Please Choose Default Fuel or Greenhouse Gas | Y23: =IF(AF23>0.0000000001,"V","") | Z23: =IF(AG23>0.0000000001,"V","") | AA23: =IF(AH23>0.0000000001,"V","") | AB23: =IF(AI23>0.0000000001,"V","") | AC23: =IF(AJ23>0.0000000001,"V","") | AD23: =IF(AK23>0.0000000001,"V","") | AE23: =IF(AL23>0.0000000001,"V","") | AF23: =IFERROR(IF($I23="預設值Default",ROUND(VLOOKUP($J23,'4.Default Emission Factor'!$D:$V,2,FALSE),10),IF($I23="自訂值Custom Value",P23,0)),0) -> 0 | AG23: =IFERROR(IF($I23="預設值Default",ROUND(VLOOKUP($J23,'4.Default Emission Factor'!$D:$V,4,FALSE),10),IF($I23="自訂值Custom Value",Q23,0)),0) -> 0 | AH23: =IFERROR(IF($I23="預設值Default",ROUND(VLOOKUP($J23,'4.Default Emission Factor'!$D:$V,6,FALSE),10),IF($I23="自訂值Custom Value",R23,0)),0) -> 0 | AI23: =IFERROR(IF($I23="預設值Default",ROUND(VLOOKUP($J23,'4.Default Emission Factor'!$D:$V,8,FALSE),10),IF($I23="自訂值Custom Value",S23,0)),0) -> 0 | AJ23: =IFERROR(IF($I23="預設值Default",ROUND(VLOOKUP($J23,'4.Default Emission Factor'!$D:$V,10,FALSE),10),IF($I23="自訂值Custom Value",T23,0)),0) -> 0 | AK23: =IFERROR(IF($I23="預設值Default",ROUND(VLOOKUP($J23,'4.Default Emission Factor'!$D:$V,12,FALSE),10),IF($I23="自訂值Custom Value",U23,0)),0) -> 0 | AL23: =IFERROR(IF($I23="預設值Default",ROUND(VLOOKUP($J23,'4.Default Emission Factor'!$D:$V,14,FALSE),10),IF($I23="自訂值Custom Value",V23,0)),0) -> 0 | AM23: =IFERROR(IF(I23="預設值Default",VLOOKUP($J23,'4.Default Emission Factor'!$D:$V,17,FALSE),IF(I23="自訂值Custom Value",X23,"")),"") | AN23: =IF(Y23="V",1,0) -> 0 | AO23: =IF(Z23="V",IF('1.GHG Inventory Form'!$E$6="IPCC AR2 Report(1995)",'6.GWP'!$C$2,IF('1.GHG Inventory Form'!$E$6="IPCC AR3 Report(2001)",'6.GWP'!$D$2,IF('1.GHG Inventory Form'!$E$6="IPCC AR4 Report(2007)",'6.GWP'!$E$2,IF('1.GHG Inventory Form'!$E$6="IPCC AR5 Report(2013)",'6.GWP'!$F$2,IF('1.GHG Inventory Form'!$E$6="IPCC AR6 Report(2021)",'6.GWP'!$G$2,0))))),0) -> 0 | AP23: =IF(AA23="V",IF('1.GHG Inventory Form'!$E$6="IPCC AR2 Report(1995)",'6.GWP'!$C$3,IF('1.GHG Inventory Form'!$E$6="IPCC AR3 Report(2001)",'6.GWP'!$D$3,IF('1.GHG Inventory Form'!$E$6="IPCC AR4 Report(2007)",'6.GWP'!$E$3,IF('1.GHG Inventory Form'!$E$6="IPCC AR5 Report(2013)",'6.GWP'!$F$3,IF('1.GHG Inventory Form'!$E$6="IPCC AR6 Report(2021)",'6.GWP'!$G$3,0))))),0) -> 0 | AQ23: =IFERROR(IF(AND(AB23="V",$I23="預設值"),IF('1.GHG Inventory Form'!$E$6="IPCC AR2 Report(1995)",VLOOKUP($J23,'6.GWP'!$B$1:$G$173,2,FALSE),IF('1.GHG Inventory Form'!$E$6="IPCC AR3 Report(2001)",VLOOKUP($J23,'6.GWP'!$B$1:$G$173,3,FALSE),IF('1.GHG Inventory Form'!$E$6="IPCC AR4 Report(2007)",VLOOKUP($J23,'6.GWP'!$B$1:$G$173,4,FALSE),IF('1.GHG Inventory Form'!$E$6="IPCC AR5 Report(2013)",VLOOKUP($J23,'6.GWP'!$B$1:$G$173,5,FALSE),IF('1.GHG Inventory Form'!$E$6="IPCC AR6 Report(2021)",VLOOKUP($J23,'6.GWP'!$B$2:$G$173,6,FALSE),0))))),IF(AND(AB23="V",$I23="自訂值"),IF('1.GHG Inventory Form'!$E$6="IPCC AR2 Report(1995)",VLOOKUP($K23,'6.GWP'!$B$1:$G$173,2,FALSE),IF('1.GHG Inventory Form'!$E$6="IPCC AR3 Report(2001)",VLOOKUP($K23,'6.GWP'!$B$1:$G$173,3,FALSE),IF('1.GHG Inventory Form'!$E$6="IPCC AR4 Report(2007)",VLOOKUP($K23,'6.GWP'!$B$1:$G$173,4,FALSE),IF('1.GHG Inventory Form'!$E$6="IPCC AR5 Report(2013)",VLOOKUP($K23,'6.GWP'!$B$1:$G$173,5,FALSE),IF('1.GHG Inventory Form'!$E$6="IPCC AR6 Report(2021)",VLOOKUP($K23,'6.GWP'!$B$2:$G$173,6,FALSE),0))))),0)),0) -> 0 | AR23: =IFERROR(IF(AND(AC23="V",$I23="預設值"),IF('1.GHG Inventory Form'!$E$6="IPCC AR2 Report(1995)",VLOOKUP($J23,'6.GWP'!$B$1:$G$173,2,FALSE),IF('1.GHG Inventory Form'!$E$6="IPCC AR3 Report(2001)",VLOOKUP($J23,'6.GWP'!$B$1:$G$173,3,FALSE),IF('1.GHG Inventory Form'!$E$6="IPCC AR4 Report(2007)",VLOOKUP($J23,'6.GWP'!$B$1:$G$173,4,FALSE),IF('1.GHG Inventory Form'!$E$6="IPCC AR5 Report(2013)",VLOOKUP($J23,'6.GWP'!$B$1:$G$173,5,FALSE),IF('1.GHG Inventory Form'!$E$6="IPCC AR6 Report(2021)",VLOOKUP($J23,'6.GWP'!$B$2:$G$173,6,FALSE),0))))),IF(AND(AC23="V",$I23="自訂值"),IF('1.GHG Inventory Form'!$E$6="IPCC AR2 Report(1995)",VLOOKUP($K23,'6.GWP'!$B$1:$G$173,2,FALSE),IF('1.GHG Inventory Form'!$E$6="IPCC AR3 Report(2001)",VLOOKUP($K23,'6.GWP'!$B$1:$G$173,3,FALSE),IF('1.GHG Inventory Form'!$E$6="IPCC AR4 Report(2007)",VLOOKUP($K23,'6.GWP'!$B$1:$G$173,4,FALSE),IF('1.GHG Inventory Form'!$E$6="IPCC AR5 Report(2013)",VLOOKUP($K23,'6.GWP'!$B$1:$G$173,5,FALSE),IF('1.GHG Inventory Form'!$E$6="IPCC AR6 Report(2021)",VLOOKUP($K23,'6.GWP'!$B$2:$G$173,6,FALSE),0))))),0)),0) -> 0 | AS23: =IF(AD23="V",IF('1.GHG Inventory Form'!$E$6="IPCC AR2 Report(1995)",'6.GWP'!$C$5,IF('1.GHG Inventory Form'!$E$6="IPCC AR3 Report(2001)",'6.GWP'!$D$5,IF('1.GHG Inventory Form'!$E$6="IPCC AR4 Report(2007)",'6.GWP'!$E$5,IF('1.GHG Inventory Form'!$E$6="IPCC AR5 Report(2013)",'6.GWP'!$F$5,IF('1.GHG Inventory Form'!$E$6="IPCC AR6 Report(2021)",'6.GWP'!$G$5,0))))),0) -> 0 | AT23: =IF(AE23="V",IF('1.GHG Inventory Form'!$E$6="IPCC AR2 Report(1995)",'6.GWP'!$C$4,IF('1.GHG Inventory Form'!$E$6="IPCC AR3 Report(2001)",'6.GWP'!$D$4,IF('1.GHG Inventory Form'!$E$6="IPCC AR4 Report(2007)",'6.GWP'!$E$4,IF('1.GHG Inventory Form'!$E$6="IPCC AR5 Report(2013)",'6.GWP'!$F$4,IF('1.GHG Inventory Form'!$E$6="IPCC AR6 Report(2021)",'6.GWP'!$G$4,0))))),0) -> 0 | AU23: =IFERROR($L23*AF23*AN23,"") | AV23: =IFERROR($L23*AG23*AO23,"") | AW23: =IFERROR($L23*AH23*AP23,"") | AX23: =IFERROR($L23*AI23*AQ23,"") | AY23: =IFERROR($L23*AJ23*AR23,"") | AZ23: =IFERROR($L23*AK23*AS23,"") | BA23: =IFERROR($L23*AL23*AT23,"") | BB23: =ROUND(SUM(AU23:BA23),4) -> 0 | BC23: =BB23/SUM($BB$16:$BB$99) -> 0 | BD23: =BB23/$BB$169 -> 0 | BI23: =IF(H23="","",IF(I23="預設值Default",H23&J23,IF(I23="自訂值Custom Value",H23&K23,""))) | BJ23: =IF(H23="其它設備，請說明","",IF(O23=0,"",O23)) | BK23: =IF(H23="","",IF(I23="預設值Default",AM23,IF(I23="自訂值Custom Value",X23,"")))
A24: 9 | I24: 預設值Default | M24: =IFERROR(IF(I24="預設值Default",VLOOKUP($J24,'4.Default Emission Factor'!$D:$V,16,FALSE),"請填寫自訂活動數據單位Please fill in Custom Unit"),"請選擇預設排放係數名稱Please Choose Default Fuel or Greenhouse Gas") -> 請選擇預設排放係數名稱Please Choose Default Fuel or Greenhouse Gas | Y24: =IF(AF24>0.0000000001,"V","") | Z24: =IF(AG24>0.0000000001,"V","") | AA24: =IF(AH24>0.0000000001,"V","") | AB24: =IF(AI24>0.0000000001,"V","") | AC24: =IF(AJ24>0.0000000001,"V","") | AD24: =IF(AK24>0.0000000001,"V","") | AE24: =IF(AL24>0.0000000001,"V","") | AF24: =IFERROR(IF($I24="預設值Default",ROUND(VLOOKUP($J24,'4.Default Emission Factor'!$D:$V,2,FALSE),10),IF($I24="自訂值Custom Value",P24,0)),0) -> 0 | AG24: =IFERROR(IF($I24="預設值Default",ROUND(VLOOKUP($J24,'4.Default Emission Factor'!$D:$V,4,FALSE),10),IF($I24="自訂值Custom Value",Q24,0)),0) -> 0 | AH24: =IFERROR(IF($I24="預設值Default",ROUND(VLOOKUP($J24,'4.Default Emission Factor'!$D:$V,6,FALSE),10),IF($I24="自訂值Custom Value",R24,0)),0) -> 0 | AI24: =IFERROR(IF($I24="預設值Default",ROUND(VLOOKUP($J24,'4.Default Emission Factor'!$D:$V,8,FALSE),10),IF($I24="自訂值Custom Value",S24,0)),0) -> 0 | AJ24: =IFERROR(IF($I24="預設值Default",ROUND(VLOOKUP($J24,'4.Default Emission Factor'!$D:$V,10,FALSE),10),IF($I24="自訂值Custom Value",T24,0)),0) -> 0 | AK24: =IFERROR(IF($I24="預設值Default",ROUND(VLOOKUP($J24,'4.Default Emission Factor'!$D:$V,12,FALSE),10),IF($I24="自訂值Custom Value",U24,0)),0) -> 0 | AL24: =IFERROR(IF($I24="預設值Default",ROUND(VLOOKUP($J24,'4.Default Emission Factor'!$D:$V,14,FALSE),10),IF($I24="自訂值Custom Value",V24,0)),0) -> 0 | AM24: =IFERROR(IF(I24="預設值Default",VLOOKUP($J24,'4.Default Emission Factor'!$D:$V,17,FALSE),IF(I24="自訂值Custom Value",X24,"")),"") | AN24: =IF(Y24="V",1,0) -> 0 | AO24: =IF(Z24="V",IF('1.GHG Inventory Form'!$E$6="IPCC AR2 Report(1995)",'6.GWP'!$C$2,IF('1.GHG Inventory Form'!$E$6="IPCC AR3 Report(2001)",'6.GWP'!$D$2,IF('1.GHG Inventory Form'!$E$6="IPCC AR4 Report(2007)",'6.GWP'!$E$2,IF('1.GHG Inventory Form'!$E$6="IPCC AR5 Report(2013)",'6.GWP'!$F$2,IF('1.GHG Inventory Form'!$E$6="IPCC AR6 Report(2021)",'6.GWP'!$G$2,0))))),0) -> 0 | AP24: =IF(AA24="V",IF('1.GHG Inventory Form'!$E$6="IPCC AR2 Report(1995)",'6.GWP'!$C$3,IF('1.GHG Inventory Form'!$E$6="IPCC AR3 Report(2001)",'6.GWP'!$D$3,IF('1.GHG Inventory Form'!$E$6="IPCC AR4 Report(2007)",'6.GWP'!$E$3,IF('1.GHG Inventory Form'!$E$6="IPCC AR5 Report(2013)",'6.GWP'!$F$3,IF('1.GHG Inventory Form'!$E$6="IPCC AR6 Report(2021)",'6.GWP'!$G$3,0))))),0) -> 0 | AQ24: =IFERROR(IF(AND(AB24="V",$I24="預設值"),IF('1.GHG Inventory Form'!$E$6="IPCC AR2 Report(1995)",VLOOKUP($J24,'6.GWP'!$B$1:$G$173,2,FALSE),IF('1.GHG Inventory Form'!$E$6="IPCC AR3 Report(2001)",VLOOKUP($J24,'6.GWP'!$B$1:$G$173,3,FALSE),IF('1.GHG Inventory Form'!$E$6="IPCC AR4 Report(2007)",VLOOKUP($J24,'6.GWP'!$B$1:$G$173,4,FALSE),IF('1.GHG Inventory Form'!$E$6="IPCC AR5 Report(2013)",VLOOKUP($J24,'6.GWP'!$B$1:$G$173,5,FALSE),IF('1.GHG Inventory Form'!$E$6="IPCC AR6 Report(2021)",VLOOKUP($J24,'6.GWP'!$B$2:$G$173,6,FALSE),0))))),IF(AND(AB24="V",$I24="自訂值"),IF('1.GHG Inventory Form'!$E$6="IPCC AR2 Report(1995)",VLOOKUP($K24,'6.GWP'!$B$1:$G$173,2,FALSE),IF('1.GHG Inventory Form'!$E$6="IPCC AR3 Report(2001)",VLOOKUP($K24,'6.GWP'!$B$1:$G$173,3,FALSE),IF('1.GHG Inventory Form'!$E$6="IPCC AR4 Report(2007)",VLOOKUP($K24,'6.GWP'!$B$1:$G$173,4,FALSE),IF('1.GHG Inventory Form'!$E$6="IPCC AR5 Report(2013)",VLOOKUP($K24,'6.GWP'!$B$1:$G$173,5,FALSE),IF('1.GHG Inventory Form'!$E$6="IPCC AR6 Report(2021)",VLOOKUP($K24,'6.GWP'!$B$2:$G$173,6,FALSE),0))))),0)),0) -> 0 | AR24: =IFERROR(IF(AND(AC24="V",$I24="預設值"),IF('1.GHG Inventory Form'!$E$6="IPCC AR2 Report(1995)",VLOOKUP($J24,'6.GWP'!$B$1:$G$173,2,FALSE),IF('1.GHG Inventory Form'!$E$6="IPCC AR3 Report(2001)",VLOOKUP($J24,'6.GWP'!$B$1:$G$173,3,FALSE),IF('1.GHG Inventory Form'!$E$6="IPCC AR4 Report(2007)",VLOOKUP($J24,'6.GWP'!$B$1:$G$173,4,FALSE),IF('1.GHG Inventory Form'!$E$6="IPCC AR5 Report(2013)",VLOOKUP($J24,'6.GWP'!$B$1:$G$173,5,FALSE),IF('1.GHG Inventory Form'!$E$6="IPCC AR6 Report(2021)",VLOOKUP($J24,'6.GWP'!$B$2:$G$173,6,FALSE),0))))),IF(AND(AC24="V",$I24="自訂值"),IF('1.GHG Inventory Form'!$E$6="IPCC AR2 Report(1995)",VLOOKUP($K24,'6.GWP'!$B$1:$G$173,2,FALSE),IF('1.GHG Inventory Form'!$E$6="IPCC AR3 Report(2001)",VLOOKUP($K24,'6.GWP'!$B$1:$G$173,3,FALSE),IF('1.GHG Inventory Form'!$E$6="IPCC AR4 Report(2007)",VLOOKUP($K24,'6.GWP'!$B$1:$G$173,4,FALSE),IF('1.GHG Inventory Form'!$E$6="IPCC AR5 Report(2013)",VLOOKUP($K24,'6.GWP'!$B$1:$G$173,5,FALSE),IF('1.GHG Inventory Form'!$E$6="IPCC AR6 Report(2021)",VLOOKUP($K24,'6.GWP'!$B$2:$G$173,6,FALSE),0))))),0)),0) -> 0 | AS24: =IF(AD24="V",IF('1.GHG Inventory Form'!$E$6="IPCC AR2 Report(1995)",'6.GWP'!$C$5,IF('1.GHG Inventory Form'!$E$6="IPCC AR3 Report(2001)",'6.GWP'!$D$5,IF('1.GHG Inventory Form'!$E$6="IPCC AR4 Report(2007)",'6.GWP'!$E$5,IF('1.GHG Inventory Form'!$E$6="IPCC AR5 Report(2013)",'6.GWP'!$F$5,IF('1.GHG Inventory Form'!$E$6="IPCC AR6 Report(2021)",'6.GWP'!$G$5,0))))),0) -> 0 | AT24: =IF(AE24="V",IF('1.GHG Inventory Form'!$E$6="IPCC AR2 Report(1995)",'6.GWP'!$C$4,IF('1.GHG Inventory Form'!$E$6="IPCC AR3 Report(2001)",'6.GWP'!$D$4,IF('1.GHG Inventory Form'!$E$6="IPCC AR4 Report(2007)",'6.GWP'!$E$4,IF('1.GHG Inventory Form'!$E$6="IPCC AR5 Report(2013)",'6.GWP'!$F$4,IF('1.GHG Inventory Form'!$E$6="IPCC AR6 Report(2021)",'6.GWP'!$G$4,0))))),0) -> 0 | AU24: =IFERROR($L24*AF24*AN24,"") | AV24: =IFERROR($L24*AG24*AO24,"") | AW24: =IFERROR($L24*AH24*AP24,"") | AX24: =IFERROR($L24*AI24*AQ24,"") | AY24: =IFERROR($L24*AJ24*AR24,"") | AZ24: =IFERROR($L24*AK24*AS24,"") | BA24: =IFERROR($L24*AL24*AT24,"") | BB24: =ROUND(SUM(AU24:BA24),4) -> 0 | BC24: =BB24/SUM($BB$16:$BB$99) -> 0 | BD24: =BB24/$BB$169 -> 0 | BI24: =IF(H24="","",IF(I24="預設值Default",H24&J24,IF(I24="自訂值Custom Value",H24&K24,""))) | BJ24: =IF(H24="其它設備，請說明","",IF(O24=0,"",O24)) | BK24: =IF(H24="","",IF(I24="預設值Default",AM24,IF(I24="自訂值Custom Value",X24,"")))
