Workbook

Sheet Emission Inventory Results
A1: 台達組織碳盤查平台-盤查清冊
D2: 盤查與驗證概況 | F2: 盤查內容說明
D3: 2023GHG 排放 (tCO2e) | F3: 定義 | G3: 排放源 | H3: 計算方法 | I3: 活動數據來源 | J3: 排放係數來源 | K3: 數據保管單位
A4: 類別1：直接GHG排放與移除 | B4: 固定燃燒直接排放 | D4: 1,292.824222 | F4: 係任何類型燃料(化石燃料或生質燃料)在固定式設備(例:加熱器、燃氣渦輪、鍋爐)中燃燒之結果，可藉以產生熱、機械功及蒸汽。 | G4: 鍋爐[天然氣] | I4: 天然氣 | J4: 中國之燃料排放係數
D5: 1,292.824222 | G5: 餐飲/廚房設備[天然氣] | I5: 天然氣 | J5: 中國之燃料排放係數
D6: 1,292.824222 | G6: RTO廢氣處理設施(天然氣) | I6: 天然氣 | J6: 中國之燃料排放係數
D7: 1,292.824222 | G7: 緊急發電機[柴油] | I7: 發電機 | J7: 中國之燃料排放係數
D8: 1,292.824222 | G8: 割草機/噴藥機[汽油] | I8: 割草機 | J8: 中國之燃料排放係數
D9: 1,292.824222 | G9: RTO廢氣處理設施運行(辅房） | I9: RTO廢氣處理設施運行(辅房） | J9: 中國之燃料排放係數
D10: 1,292.824222 | G10: RCO廢氣處理設施運行（一期北） | I10: RCO廢氣處理設施運行（一期北） | J10: 中國之燃料排放係數
D11: 1,292.824222 | G11: RCO廢氣處理設施運行（二期） | I11: RCO廢氣處理設施運行（二期） | J11: 中國之燃料排放係數
B12: 移動燃燒直接排放 | D12: 90.51069 | F12: 係燃料在運輸設備(例:機動車輛、貨車、船舶、飛機、機動堆高機)內燃燒之結果 | G12: 車輛[汽油] | I12: 車輛[汽油] | J12: 中國之燃料排放係數
D13: 90.51069 | G13: 車輛[柴油] | I13: 柴油(移動) | J13: 中國之燃料排放係數
B14: 工業製程之直接製程排放及移除 | D14: 0 | F14: 產業過程之直接過程排放與移除。
B15: 人為系統中溫室氣體釋放產生的直接逸散排放 | D15: 994.790241 | F15: 由人為系統所釋放的溫室氣體產生的直接逸散性排放。 | G15: 品保空調/研发楼饮水机/倉庫空調/除濕機 | I15: 品保空調/研发楼饮水机/倉庫空調/除濕機 | J15: 2022 年環保署排放係管理表6.0.4
D16: 994.790241 | G16: 倉庫空調/廠務冰水機 | I16: 倉庫空調/廠務冰水機 | J16: 2022 年環保署排放係管理表6.0.4
D17: 994.790241 | G17: 品保除濕機/溫濕度管控櫃/廠務冰水機/廠務雙效熱泵/研发楼冰櫃/研发楼饮水机 | I17: 品保除濕機/溫濕度管控櫃/廠務冰水機/廠務雙效熱泵/研发楼冰櫃/研发楼饮水机 | J17: 2022 年環保署排放係管理表6.0.4
D18: 994.790241 | G18: 品保冷熱衝擊試驗機/品保冷熱衝擊試驗機/品保恆溫恆濕機 | I18: 品保冷熱衝擊試驗機/品保冷熱衝擊試驗機/品保恆溫恆濕機 | J18: 2022 年環保署排放係管理表6.0.4
D19: 994.790241 | G19: 品保冷熱衝擊試驗機 | I19: 品保冷熱衝擊試驗機 | J19: 2022 年環保署排放係管理表6.0.4
D20: 994.790241 | G20: 品保冷熱衝擊試驗機/造粉冰水機 | I20: 品保冷熱衝擊試驗機/造粉冰水機 | J20: 2022 年環保署排放係管理表6.0.4
D21: 994.790241 | G21: 製造激光冷水機/製造除濕機/製造激光冰水機/造粉冷庫/除濕機 | I21: 製造激光冷水機/製造除濕機/製造激光冰水機/造粉冷庫/除濕機 | J21: 2022 年環保署排放係管理表6.0.4
D22: 994.790241 | G22: 造粉冷凝機/廠務冰水機 | I22: 造粉冷凝機/廠務冰水機 | J22: 2022 年環保署排放係管理表6.0.4
D23: 994.790241 | G23: 製造激光冷水機/製造激光冰水機/造粉冰機/冷凝機 | I23: 製造激光冷水機/製造激光冰水機/造粉冰機/冷凝機 | J23: 2022 年環保署排放係管理表6.0.4
D24: 994.790241 | G24: 製造激光冷水機 | I24: 製造激光冷水機 | J24: 2022 年環保署排放係管理表6.0.4
D25: 994.790241 | G25: 廠務冰水機/廠務冷幹機/廠務空調 | I25: 廠務冰水機/廠務冷幹機/廠務空調 | J25: 2022 年環保署排放係管理表6.0.4
D26: 994.790241 | G26: 研发楼商務車空调 | I26: 研发楼商務車空调 | J26: 2022 年環保署排放係管理表6.0.4
D27: 994.790241 | G27: 主管楼冰箱/餐厅冰櫃 | I27: 主管楼冰箱/餐厅冰櫃 | J27: 2022 年環保署排放係管理表6.0.4
... D34: 994.790241 | G34: 化糞池(宿舍) | I34: 化糞池(宿舍) | J34: 中國之燃料排放係數
B35: 土地利用變更和森林 (LULUCF) 的直接排放和移除 | D35: 0 | F35: 涵蓋由 活生質體至土壤內有機物質之所有溫室氣體。依據IPCC，可依據 6 個主要的土地使用類別(林地、農地、牧草地、濕地、居留地、其他土地)，及數個碳儲存庫(地上活生質、地下活生質、 枯木、落葉、土壤有機物質)評估其排放量。
A36: 類別2：輸入能源之間接GHG排放 | B36: 輸入電力的間接排放 | D36: 所在地基準 | E36: 市場基準 | F36: 包含有關組織生產與消耗輸入電力之溫室氣體排放。 | G36: 全廠區用電 | I36: 外購電力 | J36: 中國之燃料排放係數
B37: 輸入電力的間接排放 | D37: 71,072.382037 | E37: 0 | F37: 包含有關組織生產與消耗輸入電力之溫室氣體排放。 | G37: 全廠區用電 | I37: 外購電力 | J37: 中國之燃料排放係數
B38: 輸入能源的間接排放 | D38: 0 | F38: 包含有關組織透過實體聯網生產所消耗能源(蒸汽、熱能、冷卻及壓縮空氣)之溫室氣體排放，電力之排放除外。
A39: 類別3：運輸造成之間接排放 | B39: 上游運輸和貨物配送產生的排放 | D39: 0 | F39: 1階供應商至營運據點的產品運輸及配送。
B40: 下游運輸和貨物配送產生的排放 | D40: 0 | F40: 銷售產品從公司到終端消費者的運輸及配送。
B41: 員工通勤產生的排放 | D41: 0 | F41: 員工從居住點到工作點的運輸。
B42: 客戶和訪客運輸產生的排放 | D42: 0 | F42: 包括客戶與訪客前往報告公司的工廠，與旅行相關連的排放。
B43: 商務旅行產生的排放 | D43: 60.674 | F43: 員工商務相關的運輸。 | G43: 員工差旅 | I43: 員工差旅 | J43: 國際航空差旅運輸(乾坤)
A44: 類別4：組織使用產品造成之間接排放 | B44: 產品使用階段的排放或移除 | D44: 259.122098 | F44: 賣出產品的使用 | G44: 工廠生產生活使用的自來水 | I44: 工廠生產生活使用的自來水 | J44: 中國之燃料排放係數
B45: 資本商品的排放 | D45: 0 | F45: 資本貨物的開採、生產及運輸
B46: 固體和液體廢棄物處理產生的排放 | D46: 550.02027 | F46: 非公司擁有的設施廢棄物處置與處理。 | G46: 表面處理污泥（回收） | I46: 表面處理污泥（回收） | J46: 中國之燃料排放係數
...

Sheet Emission Inventory Scope 1
B2: 報告邊界 | I2: 總碳排放量 | J2: =D3 + 'Emission Inventory Scope 2-6'!D2 | K2: 噸CO2e
B3: 直接溫室氣體排放 | D3: =SUM(AJ6:AJ36) | F3: 噸CO2e | G3: 類型 | H3: 鑑別(有/無) | I3: 排放源 | J3: 原燃物料或產品 | K3: 活動數據 | L3: 活動數據單位 | M3: 活動數據 | N3: 排放係數 | U3: 排放係數來源 | V3: GWP | AC3: 溫室氣體排放量 | AJ3: 合計t-CO2e | AK3: 類別1、2佔比 | AL3: 總碳排放量佔比 | AM3: 原活動數據 | AN3: 原活動數據單位 | AO3: 單位轉換比例 | AP3: 逸散方式 | AQ3: 計算方法 | AR3: 逸散率(%)
N4: CO2 | O4: CH4 | P4: N2O | Q4: HFCs | R4: PFCs | S4: SF6 | T4: NF3 | V4: CO2 | W4: CH4 | X4: N2O | Y4: HFCs | Z4: PFCs | AA4: SF6 | AB4: NF3 | AC4: CO2 | AD4: CH4 | AE4: N2O | AF4: HFCs | AG4: PFCs | AH4: SF6 | AI4: NF3
B5: 類別1: | C5: 直接溫室氣體排放和移除(1)
B6: 1.1 | C6: 固定燃燒直接排放 | G6: 固定燃燒 | H6: 有 | I6: 鍋爐[天然氣] | J6: 天然氣 | K6: =AM6*AO6 | L6: 立方公尺 | N6: 2.18400000000000000000000000000000 | O6: 0.00003890000000000000000000000000 | P6: 0.00000389000000000000000000000000 | Q6: 0 | R6: 0 | S6: 0 | T6: 0 | U6: 中國之燃料排放係數 | V6: 1.00000000 | W6: 27.90000000 | X6: 273.00000000 | Y6: 0 | Z6: 0 | AA6: 0 | AB6: 0 | AC6: =K6*N6*V6/1000 | AD6: =K6*O6*W6/1000 | AE6: =K6*P6*X6/1000 | AF6: =K6*Q6*Y6/1000 | AG6: =K6*R6*Z6/1000 | AH6: =K6*S6*AA6/1000 | AI6: =K6*T6*AB6/1000 | AJ6: =SUM(AC6:AI6) | AK6: =AJ6/(D3 +SUM('Emission Inventory Scope 2-6'!W4,'Emission Inventory Scope 2-6'!W5)) | AL6: =AJ6/(D3 +'Emission Inventory Scope 2-6'!D2) | AM6: 173116.9333000000 | AN6: 立方公尺 | AO6: 1
G7: 固定燃燒 | I7: 餐飲/廚房設備[天然氣] | J7: 天然氣 | K7: =AM7*AO7 | L7: 立方公尺 | N7: 2.18400000000000000000000000000000 | O7: 0.00003890000000000000000000000000 | P7: 0.00000389000000000000000000000000 | Q7: 0 | R7: 0 | S7: 0 | T7: 0 | U7: 中國之燃料排放係數 | V7: 1.00000000 | W7: 27.90000000 | X7: 273.00000000 | Y7: 0 | Z7: 0 | AA7: 0 | AB7: 0 | AC7: =K7*N7*V7/1000 | AD7: =K7*O7*W7/1000 | AE7: =K7*P7*X7/1000 | AF7: =K7*Q7*Y7/1000 | AG7: =K7*R7*Z7/1000 | AH7: =K7*S7*AA7/1000 | AI7: =K7*T7*AB7/1000 | AJ7: =SUM(AC7:AI7) | AK7: =AJ7/(D3 +SUM('Emission Inventory Scope 2-6'!W4,'Emission Inventory Scope 2-6'!W5)) | AL7: =AJ7/(D3 +'Emission Inventory Scope 2-6'!D2) | AM7: 122074.5091000000 | AN7: 立方公尺 | AO7: 1
G8: 固定燃燒 | I8: RTO廢氣處理設施(天然氣) | J8: 天然氣 | K8: =AM8*AO8 | L8: 立方公尺 | N8: 2.18400000000000000000000000000000 | O8: 0.00003890000000000000000000000000 | P8: 0.00000389000000000000000000000000 | Q8: 0 | R8: 0 | S8: 0 | T8: 0 | U8: 中國之燃料排放係數 | V8: 1.00000000 | W8: 27.90000000 | X8: 273.00000000 | Y8: 0 | Z8: 0 | AA8: 0 | AB8: 0 | AC8: =K8*N8*V8/1000 | AD8: =K8*O8*W8/1000 | AE8: =K8*P8*X8/1000 | AF8: =K8*Q8*Y8/1000 | AG8: =K8*R8*Z8/1000 | AH8: =K8*S8*AA8/1000 | AI8: =K8*T8*AB8/1000 | AJ8: =SUM(AC8:AI8) | AK8: =AJ8/(D3 +SUM('Emission Inventory Scope 2-6'!W4,'Emission Inventory Scope 2-6'!W5)) | AL8: =AJ8/(D3 +'Emission Inventory Scope 2-6'!D2) | AM8: 278474.7273000000 | AN8: 立方公尺 | AO8: 1
G9: 固定燃燒 | I9: 緊急發電機[柴油] | J9: 柴油 | K9: =AM9*AO9 | L9: 公斤 | N9: 3.16050000000000000000000000000000 | O9: 0.00012800000000000000000000000000 | P9: 0.00002560000000000000000000000000 | Q9: 0 | R9: 0 | S9: 0 | T9: 0 | U9: 中國之燃料排放係數 | V9: 1.00000000 | W9: 27.90000000 | X9: 273.00000000 | Y9: 0 | Z9: 0 | AA9: 0 | AB9: 0 | AC9: =K9*N9*V9/1000 | AD9: =K9*O9*W9/1000 | AE9: =K9*P9*X9/1000 | AF9: =K9*Q9*Y9/1000 | AG9: =K9*R9*Z9/1000 | AH9: =K9*S9*AA9/1000 | AI9: =K9*T9*AB9/1000 | AJ9: =SUM(AC9:AI9) | AK9: =AJ9/(D3 +SUM('Emission Inventory Scope 2-6'!W4,'Emission Inventory Scope 2-6'!W5)) | AL9: =AJ9/(D3 +'Emission Inventory Scope 2-6'!D2) | AM9: 9575.999999999998 | AN9: 公斤 | AO9: 1
G10: 固定燃燒 | I10: 割草機/噴藥機[汽油] | J10: 汽油 | K10: =AM10*AO10 | L10: 公斤 | N10: 2.98480000000000000000000000000000 | O10: 0.00012900000000000000000000000000 | P10: 0.00002580000000000000000000000000 | Q10: 0 | R10: 0 | S10: 0 | T10: 0 | U10: 中國之燃料排放係數 | V10: 1.00000000 | W10: 27.90000000 | X10: 273.00000000 | Y10: 0 | Z10: 0 | AA10: 0 | AB10: 0 | AC10: =K10*N10*V10/1000 | AD10: =K10*O10*W10/1000 | AE10: =K10*P10*X10/1000 | AF10: =K10*Q10*Y10/1000 | AG10: =K10*R10*Z10/1000 | AH10: =K10*S10*AA10/1000 | AI10: =K10*T10*AB10/1000 | AJ10: =SUM(AC10:AI10) | AK10: =AJ10/(D3 +SUM('Emission Inventory Scope 2-6'!W4,'Emission Inventory Scope 2-6'!W5)) | AL10: =AJ10/(D3 +'Emission Inventory Scope 2-6'!D2) | AM10: 146.0570000000000 | AN10: 公斤 | AO10: 1
G11: 固定燃燒 | I11: RTO廢氣處理設施運行(辅房） | J11: VOCs排放(輔房) | K11: =AM11*AO11 | L11: 公斤 | N11: 0.00000100000000000000000000000000 | O11: 0 | P11: 0 | Q11: 0 | R11: 0 | S11: 0 | T11: 0 | U11: 中國之燃料排放係數 | V11: 1.00000000 | W11: 0 | X11: 0 | Y11: 0 | Z11: 0 | AA11: 0 | AB11: 0 | AC11: =K11*N11*V11/1000 | AD11: =K11*O11*W11/1000 | AE11: =K11*P11*X11/1000 | AF11: =K11*Q11*Y11/1000 | AG11: =K11*R11*Z11/1000 | AH11: =K11*S11*AA11/1000 | AI11: =K11*T11*AB11/1000 | AJ11: =SUM(AC11:AI11) | AK11: =AJ11/(D3 +SUM('Emission Inventory Scope 2-6'!W4,'Emission Inventory Scope 2-6'!W5)) | AL11: =AJ11/(D3 +'Emission Inventory Scope 2-6'!D2) | AM11: 94411199.99999999 | AN11: 公斤 | AO11: 1
G12: 固定燃燒 | I12: RCO廢氣處理設施運行（一期北） | J12: VOCs排放(一期北) | K12: =AM12*AO12 | L12: 公斤 | N12: 0.00008100000000000000000000000000 | O12: 0 | P12: 0 | Q12: 0 | R12: 0 | S12: 0 | T12: 0 | U12: 中國之燃料排放係數 | V12: 1.00000000 | W12: 0 | X12: 0 | Y12: 0 | Z12: 0 | AA12: 0 | AB12: 0 | AC12: =K12*N12*V12/1000 | AD12: =K12*O12*W12/1000 | AE12: =K12*P12*X12/1000 | AF12: =K12*Q12*Y12/1000 | AG12: =K12*R12*Z12/1000 | AH12: =K12*S12*AA12/1000 | AI12: =K12*T12*AB12/1000 | AJ12: =SUM(AC12:AI12) | AK12: =AJ12/(D3 +SUM('Emission Inventory Scope 2-6'!W4,'Emission Inventory Scope 2-6'!W5)) | AL12: =AJ12/(D3 +'Emission Inventory Scope 2-6'!D2) | AM12: 85400879.99999999 | AN12: 公斤 | AO12: 1
G13: 固定燃燒 | I13: RCO廢氣處理設施運行（二期） | J13: VOCs排放(二期) | K13: =AM13*AO13 | L13: 公斤 | N13: 0.00000900000000000000000000000000 | O13: 0 | P13: 0 | Q13: 0 | R13: 0 | S13: 0 | T13: 0 | U13: 中國之燃料排放係數 | V13: 1.00000000 | W13: 0 | X13: 0 | Y13: 0 | Z13: 0 | AA13: 0 | AB13: 0 | AC13: =K13*N13*V13/1000 | AD13: =K13*O13*W13/1000 | AE13: =K13*P13*X13/1000 | AF13: =K13*Q13*Y13/1000 | AG13: =K13*R13*Z13/1000 | AH13: =K13*S13*AA13/1000 | AI13: =K13*T13*AB13/1000 | AJ13: =SUM(AC13:AI13) | AK13: =AJ13/(D3 +SUM('Emission Inventory Scope 2-6'!W4,'Emission Inventory Scope 2-6'!W5)) | AL13: =AJ13/(D3 +'Emission Inventory Scope 2-6'!D2) | AM13: 98891928.00000000 | AN13: 公斤 | AO13: 1
B14: 1.2 | C14: 移動燃燒直接排放 | G14: 移動燃燒 | H14: 有 | I14: 車輛[汽油] | J14: 汽油(移動) | K14: =AM14*AO14 | L14: 公斤 | N14: 2.98480000000000000000000000000000 | O14: 0.00108000000000000000000000000000 | P14: 0.00034500000000000000000000000000 | Q14: 0 | R14: 0 | S14: 0 | T14: 0 | U14: 中國之燃料排放係數 | V14: 1.00000000 | W14: 27.90000000 | X14: 273.00000000 | Y14: 0 | Z14: 0 | AA14: 0 | AB14: 0 | AC14: =K14*N14*V14/1000 | AD14: =K14*O14*W14/1000 | AE14: =K14*P14*X14/1000 | AF14: =K14*Q14*Y14/1000 | AG14: =K14*R14*Z14/1000 | AH14: =K14*S14*AA14/1000 | AI14: =K14*T14*AB14/1000 | AJ14: =SUM(AC14:AI14) | AK14: =AJ14/(D3 +SUM('Emission Inventory Scope 2-6'!W4,'Emission Inventory Scope 2-6'!W5)) | AL14: =AJ14/(D3 +'Emission Inventory Scope 2-6'!D2) | AM14: 25637.53520000000 | AN14: 公斤 | AO14: 1
G15: 移動燃燒 | I15: 車輛[柴油] | J15: 柴油(移動) | K15: =AM15*AO15 | L15: 公斤 | N15: 3.16050000000000000000000000000000 | O15: 0.00016600000000000000000000000000 | P15: 0.00016600000000000000000000000000 | Q15: 0 | R15: 0 | S15: 0 | T15: 0 | U15: 中國之燃料排放係數 | V15: 1.00000000 | W15: 27.90000000 | X15: 273.00000000 | Y15: 0 | Z15: 0 | AA15: 0 | AB15: 0 | AC15: =K15*N15*V15/1000 | AD15: =K15*O15*W15/1000 | AE15: =K15*P15*X15/1000 | AF15: =K15*Q15*Y15/1000 | AG15: =K15*R15*Z15/1000 | AH15: =K15*S15*AA15/1000 | AI15: =K15*T15*AB15/1000 | AJ15: =SUM(AC15:AI15) | AK15: =AJ15/(D3 +SUM('Emission Inventory Scope 2-6'!W4,'Emission Inventory Scope 2-6'!W5)) | AL15: =AJ15/(D3 +'Emission Inventory Scope 2-6'!D2) | AM15: 3364.200000000000 | AN15: 公斤 | AO15: 1
B16: 1.3 | C16: 工業製程之直接製程排放及移除 | H16: 無
B17: 1.4 | C17: 人為系統中溫室氣體釋放產生的直接逸散排放 | G17: 逸散排放 | H17: 有 | I17: 品保空調/研发楼饮水机/倉庫空調/除濕機 | J17: R-22 | K17: =AM17*AO17 | L17: 公斤 | N17: 0 | O17: 0 | P17: 0 | Q17: 1.00000000000000000000000000000000 | R17: 0 | S17: 0 | T17: 0 | U17: 2022 年環保署排放係管理表6.0.4 | V17: 0 | W17: 0 | X17: 0 | Y17: 1960.00000000 | Z17: 0 | AA17: 0 | AB17: 0 | AC17: =K17*N17*V17*AR17*0.01/1000 | AD17: =K17*O17*W17*AR17*0.01/1000 | AE17: =K17*P17*X17*AR17*0.01/1000 | AF17: =K17*Q17*Y17*AR17*0.01/1000 | AG17: =K17*R17*Z17*AR17*0.01/1000 | AH17: =K17*S17*AA17*AR17*0.01/1000 | AI17: =K17*T17*AB17*AR17*0.01/1000 | AJ17: =SUM(AC17:AI17) | AK17: =AJ17/(D3 +SUM('Emission Inventory Scope 2-6'!W4,'Emission Inventory Scope 2-6'!W5)) | AL17: =AJ17/(D3 +'Emission Inventory Scope 2-6'!D2) | AM17: 125.3840000000000 | AN17: 公斤 | AO17: 1 | AP17: 冷媒逸散 | AQ17: 逸散率法 | AR17: 15.0000000000000000
G18: 逸散排放 | I18: 倉庫空調/廠務冰水機 | J18: R-410A | K18: =AM18*AO18 | L18: 公斤 | N18: 0 | O18: 0 | P18: 0 | Q18: 1.00000000000000000000000000000000 | R18: 0 | S18: 0 | T18: 0 | U18: 2022 年環保署排放係管理表6.0.4 | V18: 0 | W18: 0 | X18: 0 | Y18: 2255.50000000 | Z18: 0 | AA18: 0 | AB18: 0 | AC18: =K18*N18*V18*AR18*0.01/1000 | AD18: =K18*O18*W18*AR18*0.01/1000 | AE18: =K18*P18*X18*AR18*0.01/1000 | AF18: =K18*Q18*Y18*AR18*0.01/1000 | AG18: =K18*R18*Z18*AR18*0.01/1000 | AH18: =K18*S18*AA18*AR18*0.01/1000 | AI18: =K18*T18*AB18*AR18*0.01/1000 | AJ18: =SUM(AC18:AI18) | AK18: =AJ18/(D3 +SUM('Emission Inventory Scope 2-6'!W4,'Emission Inventory Scope 2-6'!W5)) | AL18: =AJ18/(D3 +'Emission Inventory Scope 2-6'!D2) | AM18: 45.49999999999998 | AN18: 公斤 | AO18: 1 | AP18: 冷媒逸散 | AQ18: 逸散率法 | AR18: 15.0000000000000000
G19: 逸散排放 | I19: 品保除濕機/溫濕度管控櫃/廠務冰水機/廠務雙效熱泵/研发楼冰櫃/研发楼饮水机 | J19: R-134a | K19: =AM19*AO19 | L19: 公斤 | N19: 0 | O19: 0 | P19: 0 | Q19: 1.00000000000000000000000000000000 | R19: 0 | S19: 0 | T19: 0 | U19: 2022 年環保署排放係管理表6.0.4 | V19: 0 | W19: 0 | X19: 0 | Y19: 1530.00000000 | Z19: 0 | AA19: 0 | AB19: 0 | AC19: =K19*N19*V19*AR19*0.01/1000 | AD19: =K19*O19*W19*AR19*0.01/1000 | AE19: =K19*P19*X19*AR19*0.01/1000 | AF19: =K19*Q19*Y19*AR19*0.01/1000 | AG19: =K19*R19*Z19*AR19*0.01/1000 | AH19: =K19*S19*AA19*AR19*0.01/1000 | AI19: =K19*T19*AB19*AR19*0.01/1000 | AJ19: =SUM(AC19:AI19) | AK19: =AJ19/(D3 +SUM('Emission Inventory Scope 2-6'!W4,'Emission Inventory Scope 2-6'!W5)) | AL19: =AJ19/(D3 +'Emission Inventory Scope 2-6'!D2) | AM19: 529.5610000000002 | AN19: 公斤 | AO19: 1 | AP19: 冷媒逸散 | AQ19: 逸散率法 | AR19: 15.0000000000000000
G20: 逸散排放 | I20: 品保冷熱衝擊試驗機/品保冷熱衝擊試驗機/品保恆溫恆濕機 | J20: R-404A | K20: =AM20*AO20 | L20: 公斤 | N20: 0 | O20: 0 | P20: 0 | Q20: 1.00000000000000000000000000000000 | R20: 0 | S20: 0 | T20: 0 | U20: 2022 年環保署排放係管理表6.0.4 | V20: 0 | W20: 0 | X20: 0 | Y20: 4728.00000000 | Z20: 0 | AA20: 0 | AB20: 0 | AC20: =K20*N20*V20*AR20*0.01/1000 | AD20: =K20*O20*W20*AR20*0.01/1000 | AE20: =K20*P20*X20*AR20*0.01/1000 | AF20: =K20*Q20*Y20*AR20*0.01/1000 | AG20: =K20*R20*Z20*AR20*0.01/1000 | AH20: =K20*S20*AA20*AR20*0.01/1000 | AI20: =K20*T20*AB20*AR20*0.01/1000 | AJ20: =SUM(AC20:AI20) | AK20: =AJ20/(D3 +SUM('Emission Inventory Scope 2-6'!W4,'Emission Inventory Scope 2-6'!W5)) | AL20: =AJ20/(D3 +'Emission Inventory Scope 2-6'!D2) | AM20: 44.29999999999999 | AN20: 公斤 | AO20: 1 | AP20: 冷媒逸散 | AQ20: 逸散率法 | AR20: 15.0000000000000000
G21: 逸散排放 | I21: 品保冷熱衝擊試驗機 | J21: R-23 | K21: =AM21*AO21 | L21: 公斤 | N21: 0 | O21: 0 | P21: 0 | Q21: 1.00000000000000000000000000000000 | R21: 0 | S21: 0 | T21: 0 | U21: 2022 年環保署排放係管理表6.0.4 | V21: 0 | W21: 0 | X21: 0 | Y21: 14600.00000000 | Z21: 0 | AA21: 0 | AB21: 0 | AC21: =K21*N21*V21*AR21*0.01/1000 | AD21: =K21*O21*W21*AR21*0.01/1000 | AE21: =K21*P21*X21*AR21*0.01/1000 | AF21: =K21*Q21*Y21*AR21*0.01/1000 | AG21: =K21*R21*Z21*AR21*0.01/1000 | AH21: =K21*S21*AA21*AR21*0.01/1000 | AI21: =K21*T21*AB21*AR21*0.01/1000 | AJ21: =SUM(AC21:AI21) | AK21: =AJ21/(D3 +SUM('Emission Inventory Scope 2-6'!W4,'Emission Inventory Scope 2-6'!W5)) | AL21: =AJ21/(D3 +'Emission Inventory Scope 2-6'!D2) | AM21: 1.999999999999993 | AN21: 公斤 | AO21: 1 | AP21: 冷媒逸散 | AQ21: 逸散率法 | AR21: 15.0000000000000000
G22: 逸散排放 | I22: 品保冷熱衝擊試驗機/造粉冰水機 | J22: R-508A | K22: =AM22*AO22 | L22: 公斤 | N22: 0 | O22: 0 | P22: 0 | Q22: 1.00000000000000000000000000000000 | R22: 0 | S22: 0 | T22: 0 | U22: 2022 年環保署排放係管理表6.0.4 | V22: 0 | W22: 0 | X22: 0 | Y22: 13258.00000000 | Z22: 0 | AA22: 0 | AB22: 0 | AC22: =K22*N22*V22*AR22*0.01/1000 | AD22: =K22*O22*W22*AR22*0.01/1000 | AE22: =K22*P22*X22*AR22*0.01/1000 | AF22: =K22*Q22*Y22*AR22*0.01/1000 | AG22: =K22*R22*Z22*AR22*0.01/1000 | AH22: =K22*S22*AA22*AR22*0.01/1000 | AI22: =K22*T22*AB22*AR22*0.01/1000 | AJ22: =SUM(AC22:AI22) | AK22: =AJ22/(D3 +SUM('Emission Inventory Scope 2-6'!W4,'Emission Inventory Scope 2-6'!W5)) | AL22: =AJ22/(D3 +'Emission Inventory Scope 2-6'!D2) | AM22: 6.809999999999985 | AN22: 公斤 | AO22: 1 | AP22: 冷媒逸散 | AQ22: 逸散率法 | AR22: 15.0000000000000000
G23: 逸散排放 | I23: 製造激光冷水機/製造除濕機/製造激光冰水機/造粉冷庫/除濕機 | J23: R-22 | K23: =AM23*AO23 | L23: 公斤 | N23: 0 | O23: 0 | P23: 0 | Q23: 1.00000000000000000000000000000000 | R23: 0 | S23: 0 | T23: 0 | U23: 2022 年環保署排放係管理表6.0.4 | V23: 0 | W23: 0 | X23: 0 | Y23: 1960.00000000 | Z23: 0 | AA23: 0 | AB23: 0 | AC23: =K23*N23*V23*AR23*0.01/1000 | AD23: =K23*O23*W23*AR23*0.01/1000 | AE23: =K23*P23*X23*AR23*0.01/1000 | AF23: =K23*Q23*Y23*AR23*0.01/1000 | AG23: =K23*R23*Z23*AR23*0.01/1000 | AH23: =K23*S23*AA23*AR23*0.01/1000 | AI23: =K23*T23*AB23*AR23*0.01/1000 | AJ23: =SUM(AC23:AI23) | AK23: =AJ23/(D3 +SUM('Emission Inventory Scope 2-6'!W4,'Emission Inventory Scope 2-6'!W5)) | AL23: =AJ23/(D3 +'Emission Inventory Scope 2-6'!D2) | AM23: 212.0300000000000 | AN23: 公斤 | AO23: 1 | AP23: 冷媒逸散 | AQ23: 逸散率法 | AR23: 15.0000000000000000
G24: 逸散排放 | I24: 造粉冷凝機/廠務冰水機 | J24: R-404A | K24: =AM24*AO24 | L24: 公斤 | N24: 0 | O24: 0 | P24: 0 | Q24: 1.00000000000000000000000000000000 | R24: 0 | S24: 0 | T24: 0 | U24: 2022 年環保署排放係管理表6.0.4 | V24: 0 | W24: 0 | X24: 0 | Y24: 4728.00000000 | Z24: 0 | AA24: 0 | AB24: 0 | AC24: =K24*N24*V24*AR24*0.01/1000 | AD24: =K24*O24*W24*AR24*0.01/1000 | AE24: =K24*P24*X24*AR24*0.01/1000 | AF24: =K24*Q24*Y24*AR24*0.01/1000 | AG24: =K24*R24*Z24*AR24*0.01/1000 | AH24: =K24*S24*AA24*AR24*0.01/1000 | AI24: =K24*T24*AB24*AR24*0.01/1000 | AJ24: =SUM(AC24:AI24) | AK24: =AJ24/(D3 +SUM('Emission Inventory Scope 2-6'!W4,'Emission Inventory Scope 2-6'!W5)) | AL24: =AJ24/(D3 +'Emission Inventory Scope 2-6'!D2) | AM24: 21.59999999999999 | AN24: 公斤 | AO24: 1 | AP24: 冷媒逸散 | AQ24: 逸散率法 | AR24: 15.0000000000000000
G25: 逸散排放 | I25: 製造激光冷水機/製造激光冰水機/造粉冰機/冷凝機 | J25: R-410A | K25: =AM25*AO25 | L25: 公斤 | N25: 0 | O25: 0 | P25: 0 | Q25: 1.00000000000000000000000000000000 | R25: 0 | S25: 0 | T25: 0 | U25: 2022 年環保署排放係管理表6.0.4 | V25: 0 | W25: 0 | X25: 0 | Y25: 2255.50000000 | Z25: 0 | AA25: 0 | AB25: 0 | AC25: =K25*N25*V25*AR25*0.01/1000 | AD25: =K25*O25*W25*AR25*0.01/1000 | AE25: =K25*P25*X25*AR25*0.01/1000 | AF25: =K25*Q25*Y25*AR25*0.01/1000 | AG25: =K25*R25*Z25*AR25*0.01/1000 | AH25: =K25*S25*AA25*AR25*0.01/1000 | AI25: =K25*T25*AB25*AR25*0.01/1000 | AJ25: =SUM(AC25:AI25) | AK25: =AJ25/(D3 +SUM('Emission Inventory Scope 2-6'!W4,'Emission Inventory Scope 2-6'!W5)) | AL25: =AJ25/(D3 +'Emission Inventory Scope 2-6'!D2) | AM25: 169.3800000000000 | AN25: 公斤 | AO25: 1 | AP25: 冷媒逸散 | AQ25: 逸散率法 | AR25: 15.0000000000000000
G26: 逸散排放 | I26: 製造激光冷水機 | J26: R-134a | K26: =AM26*AO26 | L26: 公斤 | N26: 0 | O26: 0 | P26: 0 | Q26: 1.00000000000000000000000000000000 | R26: 0 | S26: 0 | T26: 0 | U26: 2022 年環保署排放係管理表6.0.4 | V26: 0 | W26: 0 | X26: 0 | Y26: 1530.00000000 | Z26: 0 | AA26: 0 | AB26: 0 | AC26: =K26*N26*V26*AR26*0.01/1000 | AD26: =K26*O26*W26*AR26*0.01/1000 | AE26: =K26*P26*X26*AR26*0.01/1000 | AF26: =K26*Q26*Y26*AR26*0.01/1000 | AG26: =K26*R26*Z26*AR26*0.01/1000 | AH26: =K26*S26*AA26*AR26*0.01/1000 | AI26: =K26*T26*AB26*AR26*0.01/1000 | AJ26: =SUM(AC26:AI26) | AK26: =AJ26/(D3 +SUM('Emission Inventory Scope 2-6'!W4,'Emission Inventory Scope 2-6'!W5)) | AL26: =AJ26/(D3 +'Emission Inventory Scope 2-6'!D2) | AM26: 58.85999999999999 | AN26: 公斤 | AO26: 1 | AP26: 冷媒逸散 | AQ26: 逸散率法 | AR26: 15.0000000000000000
G27: 逸散排放 | I27: 廠務冰水機/廠務冷幹機/廠務空調 | J27: R-22 | K27: =AM27*AO27 | L27: 公斤 | N27: 0 | O27: 0 | P27: 0 | Q27: 1.00000000000000000000000000000000 | R27: 0 | S27: 0 | T27: 0 | U27: 2022 年環保署排放係管理表6.0.4 | V27: 0 | W27: 0 | X27: 0 | Y27: 1960.00000000 | Z27: 0 | AA27: 0 | AB27: 0 | AC27: =K27*N27*V27*AR27*0.01/1000 | AD27: =K27*O27*W27*AR27*0.01/1000 | AE27: =K27*P27*X27*AR27*0.01/1000 | AF27: =K27*Q27*Y27*AR27*0.01/1000 | AG27: =K27*R27*Z27*AR27*0.01/1000 | AH27: =K27*S27*AA27*AR27*0.01/1000 | AI27: =K27*T27*AB27*AR27*0.01/1000 | AJ27: =SUM(AC27:AI27) | AK27: =AJ27/(D3 +SUM('Emission Inventory Scope 2-6'!W4,'Emission Inventory Scope 2-6'!W5)) | AL27: =AJ27/(D3 +'Emission Inventory Scope 2-6'!D2) | AM27: 313.3000000000000 | AN27: 公斤 | AO27: 1 | AP27: 冷媒逸散 | AQ27: 逸散率法 | AR27: 15.0000000000000000
G28: 逸散排放 | I28: 研发楼商務車空调 | J28: R-134a | K28: =AM28*AO28 | L28: 公斤 | N28: 0 | O28: 0 | P28: 0 | Q28: 1.00000000000000000000000000000000 | R28: 0 | S28: 0 | T28: 0 | U28: 2022 年環保署排放係管理表6.0.4 | V28: 0 | W28: 0 | X28: 0 | Y28: 1530.00000000 | Z28: 0 | AA28: 0 | AB28: 0 | AC28: =K28*N28*V28*AR28*0.01/1000 | AD28: =K28*O28*W28*AR28*0.01/1000 | AE28: =K28*P28*X28*AR28*0.01/1000 | AF28: =K28*Q28*Y28*AR28*0.01/1000 | AG28: =K28*R28*Z28*AR28*0.01/1000 | AH28: =K28*S28*AA28*AR28*0.01/1000 | AI28: =K28*T28*AB28*AR28*0.01/1000 | AJ28: =SUM(AC28:AI28) | AK28: =AJ28/(D3 +SUM('Emission Inventory Scope 2-6'!W4,'Emission Inventory Scope 2-6'!W5)) | AL28: =AJ28/(D3 +'Emission Inventory Scope 2-6'!D2) | AM28: 5.000000000000000 | AN28: 公斤 | AO28: 1 | AP28: 冷媒逸散 | AQ28: 逸散率法 | AR28: 20.0000000000000000
G29: 逸散排放 | I29: 主管楼冰箱/餐厅冰櫃 | J29: R-134a | K29: =AM29*AO29 | L29: 公斤 | N29: 0 | O29: 0 | P29: 0 | Q29: 1.00000000000000000000000000000000 | R29: 0 | S29: 0 | T29: 0 | U29: 2022 年環保署排放係管理表6.0.4 | V29: 0 | W29: 0 | X29: 0 | Y29: 1530.00000000 | Z29: 0 | AA29: 0 | AB29: 0 | AC29: =K29*N29*V29*AR29*0.01/1000 | AD29: =K29*O29*W29*AR29*0.01/1000 | AE29: =K29*P29*X29*AR29*0.01/1000 | AF29: =K29*Q29*Y29*AR29*0.01/1000 | AG29: =K29*R29*Z29*AR29*0.01/1000 | AH29: =K29*S29*AA29*AR29*0.01/1000 | AI29: =K29*T29*AB29*AR29*0.01/1000 | AJ29: =SUM(AC29:AI29) | AK29: =AJ29/(D3 +SUM('Emission Inventory Scope 2-6'!W4,'Emission Inventory Scope 2-6'!W5)) | AL29: =AJ29/(D3 +'Emission Inventory Scope 2-6'!D2) | AM29: 0.9019999999999895 | AN29: 公斤 | AO29: 1 | AP29: 冷媒逸散 | AQ29: 逸散率法 | AR29: 10.0000000000000000
G30: 逸散排放 | I30: 主管楼空調R-22 | J30: R-22 | K30: =AM30*AO30 | L30: 公斤 | N30: 0 | O30: 0 | P30: 0 | Q30: 1.00000000000000000000000000000000 | R30: 0 | S30: 0 | T30: 0 | U30: 2022 年環保署排放係管理表6.0.4 | V30: 0 | W30: 0 | X30: 0 | Y30: 1960.00000000 | Z30: 0 | AA30: 0 | AB30: 0 | AC30: =K30*N30*V30*AR30*0.01/1000 | AD30: =K30*O30*W30*AR30*0.01/1000 | AE30: =K30*P30*X30*AR30*0.01/1000 | AF30: =K30*Q30*Y30*AR30*0.01/1000 | AG30: =K30*R30*Z30*AR30*0.01/1000 | AH30: =K30*S30*AA30*AR30*0.01/1000 | AI30: =K30*T30*AB30*AR30*0.01/1000 | AJ30: =SUM(AC30:AI30) | AK30: =AJ30/(D3 +SUM('Emission Inventory Scope 2-6'!W4,'Emission Inventory Scope 2-6'!W5)) | AL30: =AJ30/(D3 +'Emission Inventory Scope 2-6'!D2) | AM30: 185.8500000000000 | AN30: 公斤 | AO30: 1 | AP30: 冷媒逸散 | AQ30: 逸散率法 | AR30: 10.0000000000000000
G31: 逸散排放 | I31: 主管楼空調R-32 | J31: R-32 | K31: =AM31*AO31 | L31: 公斤 | N31: 0 | O31: 0 | P31: 0 | Q31: 1.00000000000000000000000000000000 | R31: 0 | S31: 0 | T31: 0 | U31: 2022 年環保署排放係管理表6.0.4 | V31: 0 | W31: 0 | X31: 0 | Y31: 771.00000000 | Z31: 0 | AA31: 0 | AB31: 0 | AC31: =K31*N31*V31*AR31*0.01/1000 | AD31: =K31*O31*W31*AR31*0.01/1000 | AE31: =K31*P31*X31*AR31*0.01/1000 | AF31: =K31*Q31*Y31*AR31*0.01/1000 | AG31: =K31*R31*Z31*AR31*0.01/1000 | AH31: =K31*S31*AA31*AR31*0.01/1000 | AI31: =K31*T31*AB31*AR31*0.01/1000 | AJ31: =SUM(AC31:AI31) | AK31: =AJ31/(D3 +SUM('Emission Inventory Scope 2-6'!W4,'Emission Inventory Scope 2-6'!W5)) | AL31: =AJ31/(D3 +'Emission Inventory Scope 2-6'!D2) | AM31: 2.249999999999987 | AN31: 公斤 | AO31: 1 | AP31: 冷媒逸散 | AQ31: 逸散率法 | AR31: 10.0000000000000000
G32: 逸散排放 | I32: 主管楼空調R-410A | J32: R-410A | K32: =AM32*AO32 | L32: 公斤 | N32: 0 | O32: 0 | P32: 0 | Q32: 1.00000000000000000000000000000000 | R32: 0 | S32: 0 | T32: 0 | U32: 2022 年環保署排放係管理表6.0.4 | V32: 0 | W32: 0 | X32: 0 | Y32: 2255.50000000 | Z32: 0 | AA32: 0 | AB32: 0 | AC32: =K32*N32*V32*AR32*0.01/1000 | AD32: =K32*O32*W32*AR32*0.01/1000 | AE32: =K32*P32*X32*AR32*0.01/1000 | AF32: =K32*Q32*Y32*AR32*0.01/1000 | AG32: =K32*R32*Z32*AR32*0.01/1000 | AH32: =K32*S32*AA32*AR32*0.01/1000 | AI32: =K32*T32*AB32*AR32*0.01/1000 | AJ32: =SUM(AC32:AI32) | AK32: =AJ32/(D3 +SUM('Emission Inventory Scope 2-6'!W4,'Emission Inventory Scope 2-6'!W5)) | AL32: =AJ32/(D3 +'Emission Inventory Scope 2-6'!D2) | AM32: 32.06000000000001 | AN32: 公斤 | AO32: 1 | AP32: 冷媒逸散 | AQ32: 逸散率法 | AR32: 10.0000000000000000
G33: 逸散排放 | I33: 主管楼冰箱R-600a | J33: R-600a | K33: =AM33*AO33 | L33: 公斤 | N33: 0 | O33: 0 | P33: 0 | Q33: 1.00000000000000000000000000000000 | R33: 0 | S33: 0 | T33: 0 | U33: 2022 年環保署排放係管理表6.0.4 | V33: 0 | W33: 0 | X33: 0 | Y33: 0 | Z33: 0 | AA33: 0 | AB33: 0 | AC33: =K33*N33*V33*AR33*0.01/1000 | AD33: =K33*O33*W33*AR33*0.01/1000 | AE33: =K33*P33*X33*AR33*0.01/1000 | AF33: =K33*Q33*Y33*AR33*0.01/1000 | AG33: =K33*R33*Z33*AR33*0.01/1000 | AH33: =K33*S33*AA33*AR33*0.01/1000 | AI33: =K33*T33*AB33*AR33*0.01/1000 | AJ33: =SUM(AC33:AI33) | AK33: =AJ33/(D3 +SUM('Emission Inventory Scope 2-6'!W4,'Emission Inventory Scope 2-6'!W5)) | AL33: =AJ33/(D3 +'Emission Inventory Scope 2-6'!D2) | AM33: 3.858999999999990 | AN33: 公斤 | AO33: 1 | AP33: 冷媒逸散 | AQ33: 逸散率法 | AR33: 10.0000000000000000
G34: 逸散排放 | I34: WD-40 使用(CO2) | J34: WD-40 使用(CO2) | K34: =AM34*AO34 | L34: 公斤 | N34: 1.00000000000000000000000000000000 | O34: 0 | P34: 0 | Q34: 0 | R34: 0 | S34: 0 | T34: 0 | U34: 2022 年環保署排放係管理表6.0.4 | V34: 1.00000000 | W34: 0 | X34: 0 | Y34: 0 | Z34: 0 | AA34: 0 | AB34: 0 | AC34: =K34*N34*V34/1000 | AD34: =K34*O34*W34/1000 | AE34: =K34*P34*X34/1000 | AF34: =K34*Q34*Y34/1000 | AG34: =K34*R34*Z34/1000 | AH34: =K34*S34*AA34/1000 | AI34: =K34*T34*AB34/1000 | AJ34: =SUM(AC34:AI34) | AK34: =AJ34/(D3 +SUM('Emission Inventory Scope 2-6'!W4,'Emission Inventory Scope 2-6'!W5)) | AL34: =AJ34/(D3 +'Emission Inventory Scope 2-6'!D2) | AM34: 9.983500000000019 | AN34: 公斤 | AO34: 1 | AP34: 其他逸散
G35: 逸散排放 | I35: 化糞池(工廠) | J35: 化糞池CH4 | K35: =AM35*AO35 | L35: 公斤 | N35: 0 | O35: 0.48000000000000000000000000000000 | P35: 0 | Q35: 0 | R35: 0 | S35: 0 | T35: 0 | U35: 中國之燃料排放係數 | V35: 0 | W35: 27.90000000 | X35: 0 | Y35: 0 | Z35: 0 | AA35: 0 | AB35: 0 | AC35: =K35*N35*V35/1000 | AD35: =K35*O35*W35/1000 | AE35: =K35*P35*X35/1000 | AF35: =K35*Q35*Y35/1000 | AG35: =K35*R35*Z35/1000 | AH35: =K35*S35*AA35/1000 | AI35: =K35*T35*AB35/1000 | AJ35: =SUM(AC35:AI35) | AK35: =AJ35/(D3 +SUM('Emission Inventory Scope 2-6'!W4,'Emission Inventory Scope 2-6'!W5)) | AL35: =AJ35/(D3 +'Emission Inventory Scope 2-6'!D2) | AM35: 23846.22350000000 | AN35: 公斤 | AO35: 1 | AP35: 其他逸散
G36: 逸散排放 | I36: 化糞池(宿舍) | J36: 化糞池CH4 | K36: =AM36*AO36 | L36: 公斤 | N36: 0 | O36: 0.48000000000000000000000000000000 | P36: 0 | Q36: 0 | R36: 0 | S36: 0 | T36: 0 | U36: 中國之燃料排放係數 | V36: 0 | W36: 27.90000000 | X36: 0 | Y36: 0 | Z36: 0 | AA36: 0 | AB36: 0 | AC36: =K36*N36*V36/1000 | AD36: =K36*O36*W36/1000 | AE36: =K36*P36*X36/1000 | AF36: =K36*Q36*Y36/1000 | AG36: =K36*R36*Z36/1000 | AH36: =K36*S36*AA36/1000 | AI36: =K36*T36*AB36/1000 | AJ36: =SUM(AC36:AI36) | AK36: =AJ36/(D3 +SUM('Emission Inventory Scope 2-6'!W4,'Emission Inventory Scope 2-6'!W5)) | AL36: =AJ36/(D3 +'Emission Inventory Scope 2-6'!D2) | AM36: 12411.98330000000 | AN36: 公斤 | AO36: 1 | AP36: 其他逸散
B37: 1.5 | C37: 土地利用變更和森林 (LULUCF) 的直接排放和移除 | H37: 無

Sheet Emission Inventory Scope 2-6
J1: 參數1 | K1: 參數2 | L1: 參數3 | M1: 參數4 | N1: 參數5
B2: 間接溫室氣體排放 | D2: =SUM(W4,W5,W7,W8,W9,W10,W11,W13,W14,W15,W30,W31,W33,W34,W35,W36,W38) | F2: 噸CO2e | G2: 排放源鑑別 | I2: 是否納入盤查 | J2: 資訊取得難易度 | K2: 活動數據準確性 | L2: 數據蒐集及準備時間 | M2: 是否為預期使用者需求必要要求 | O2: 重大性得分 | P2: 重大性鑑別(S/NS) | Q2: 活動數據 | R2: 活動數據單位 | S2: 活動數據佐證 | T2: 排放係數 | U2: 排放係數來源 | V2: 小計t-CO2e | W2: 合計t-CO2e | X2: 原活動數據 | Y2: 原活動數據單位 | Z2: 單位轉換比例
B3: 類別 2: | C3: 輸入能源的間接溫室氣體排放
B4: 2.1 | C4: 輸入電力的間接排放 | G4: 有 | H4: 全廠區用電 | I4: 否 | O4: 0 | P4: NS | Q4: =X4*Z4 | R4: KWh | T4: 0.79210000000000000000000000000000 | U4: 中國之燃料排放係數 | V4: =Q4*T4/1000 | W4: =SUM(V4:V4) | X4: 89726527.00000000 | Y4: KWh | Z4: 1
B5: 2.2 | C5: 輸入能源的間接排放 | G5: 否 | I5: 不適用
B6: 類別 3: | C6: 運輸產生的間接溫室氣體排放
B7: 3.1 | C7: 上游運輸和貨物配送產生的排放 | G7: 否 | I7: 不適用
B8: 3.2 | C8: 下游運輸和貨物配送產生的排放 | G8: 否 | I8: 不適用
B9: 3.3 | C9: 員工通勤產生的排放 | G9: 否 | I9: 不適用
B10: 3.4 | C10: 客戶和訪客運輸產生的排放 | G10: 否 | I10: 不適用
B11: 3.5 | C11: 商務旅行產生的排放 | G11: 有 | H11: 員工差旅 | I11: 否 | O11: 0 | P11: NS | Q11: =X11*Z11 | R11: 公斤 | T11: 1.00000000000000000000000000000000 | U11: 國際航空差旅運輸(乾坤) | V11: =Q11*T11/1000 | W11: =SUM(V11:V11) | X11: 60674.00000000001 | Y11: 公斤 | Z11: 1
B12: 類別 4: | C12: 組織使用的產品之間接溫室氣體排放
B13: 4.1 | C13: 源自採購商品的排放 | G13: 有 | H13: 工廠生產生活使用的自來水 | I13: 否 | O13: 0 | P13: NS | Q13: =X13*Z13 | R13: 公斤 | T13: 0.78800000000000000000000000000000 | U13: 中國之燃料排放係數 | V13: =Q13*T13/1000 | W13: =SUM(V13:V13) | X13: 328835.1496000000 | Y13: 公斤 | Z13: 1
B14: 4.2 | C14: 資本商品的排放 | G14: 否 | I14: 不適用
B15: 4.3 | C15: 固體和液體廢棄物處理產生的排放 | G15: 有 | H15: 表面處理污泥（回收） | I15: 否 | O15: 0 | P15: NS | Q15: =X15*Z15 | R15: 公斤 | T15: 34.00000000000000000000000000000000 | U15: 中國之燃料排放係數 | V15: =Q15*T15/1000 | W15: =SUM(V15:V29) | X15: 38.57199999999999 | Y15: 公斤 | Z15: 1
G16: 有 | H16: 廢有機溶劑（回收） | I16: 否 | O16: 0 | P16: NS | Q16: =X16*Z16 | R16: 公斤 | T16: 34.00000000000000000000000000000000 | U16: 中國之燃料排放係數 | V16: =Q16*T16/1000 | X16: 197.8400000000000 | Y16: 公斤 | Z16: 1
G17: 有 | H17: 廢有機溶劑（焚燒） | I17: 否 | O17: 0 | P17: NS | Q17: =X17*Z17 | R17: 公斤 | T17: 2550.00000000000000000000000000000000 | U17: 中國之燃料排放係數 | V17: =Q17*T17/1000 | X17: 25.02000000000002 | Y17: 公斤 | Z17: 1
G18: 有 | H18: 廢礦物油/防鏽油（回收） | I18: 否 | O18: 0 | P18: NS | Q18: =X18*Z18 | R18: 公斤 | T18: 34.00000000000000000000000000000000 | U18: 中國之燃料排放係數 | V18: =Q18*T18/1000 | X18: 24.60000000000000 | Y18: 公斤 | Z18: 1
G19: 有 | H19: 廢礦物油/防鏽油（焚燒） | I19: 否 | O19: 0 | P19: NS | Q19: =X19*Z19 | R19: 公斤 | T19: 2550.00000000000000000000000000000000 | U19: 中國之燃料排放係數 | V19: =Q19*T19/1000 | X19: 2.039999999999996 | Y19: 公斤 | Z19: 1
G20: 有 | H20: 表面處理廢液（回收） | I20: 否 | O20: 0 | P20: NS | Q20: =X20*Z20 | R20: 公斤 | T20: 34.00000000000000000000000000000000 | U20: 中國之燃料排放係數 | V20: =Q20*T20/1000 | X20: 20.49999999999999 | Y20: 公斤 | Z20: 1
G21: 有 | H21: 有機廢物（廢容器&吸附過濾介質焚燒） | I21: 否 | O21: 0 | P21: NS | Q21: =X21*Z21 | R21: 公斤 | T21: 2550.00000000000000000000000000000000 | U21: 中國之燃料排放係數 | V21: =Q21*T21/1000 | X21: 41.40200000000001 | Y21: 公斤 | Z21: 1
G22: 有 | H22: 廢樹脂膠（焚燒） | I22: 否 | O22: 0 | P22: NS | Q22: =X22*Z22 | R22: 公斤 | T22: 2550.00000000000000000000000000000000 | U22: 中國之燃料排放係數 | V22: =Q22*T22/1000 | X22: 25.70000000000000 | Y22: 公斤 | Z22: 1
G23: 有 | H23: 廢濾芯（焚燒） | I23: 否 | O23: 0 | P23: NS | Q23: =X23*Z23 | R23: 公斤 | T23: 2550.00000000000000000000000000000000 | U23: 中國之燃料排放係數 | V23: =Q23*T23/1000 | X23: 9.109999999999985 | Y23: 公斤 | Z23: 1
G24: 有 | H24: 廢活性炭（焚燒） | I24: 否 | O24: 0 | P24: NS | Q24: =X24*Z24 | R24: 公斤 | T24: 2550.00000000000000000000000000000000 | U24: 中國之燃料排放係數 | V24: =Q24*T24/1000 | X24: 3.538999999999999 | Y24: 公斤 | Z24: 1
G25: 有 | H25: 廢活性炭（再生循環利用） | I25: 否 | O25: 0 | P25: NS | Q25: =X25*Z25 | R25: 公斤 | T25: 34.00000000000000000000000000000000 | U25: 中國之燃料排放係數 | V25: =Q25*T25/1000 | X25: 9.699999999999991 | Y25: 公斤 | Z25: 1
G26: 有 | H26: 廢乳化液（回收） | I26: 否 | O26: 0 | P26: NS | Q26: =X26*Z26 | R26: 公斤 | T26: 34.00000000000000000000000000000000 | U26: 中國之燃料排放係數 | V26: =Q26*T26/1000 | X26: 17.03999999999999 | Y26: 公斤 | Z26: 1
G27: 有 | H27: 蒸馏残渣（结晶盐焚燒） | I27: 否 | O27: 0 | P27: NS | Q27: =X27*Z27 | R27: 公斤 | T27: 2550.00000000000000000000000000000000 | U27: 中國之燃料排放係數 | V27: =Q27*T27/1000 | X27: 1.000000000000015 | Y27: 公斤 | Z27: 1
... G29: 有 | H29: 非製程廢水處理 | I29: 否 | O29: 0 | P29: NS | Q29: =X29*Z29 | R29: 公斤 | T29: 0.33600000000000000000000000000000 | U29: 中國之燃料排放係數 | V29: =Q29*T29/1000 | X29: 115073.2795000000 | Y29: 公斤 | Z29: 1
B30: 4.4 | C30: 租賃設備資產使用造成之排放 | G30: 否 | I30: 不適用
B31: 4.5 | C31: 上述子類別中未描述使用服務而產生的排放 | G31: 否 | I31: 不適用
B32: 類別 5: | C32: 使用組織的產品所產生之間接溫室氣體排放
B33: 5.1 | C33: 產品使用階段的排放或移除 | G33: 否 | I33: 不適用
B34: 5.2 | C34: 下游租賃資產的排放 | G34: 否 | I34: 不適用
B35: 5.3 | C35: 產品生命終期階段的排放 | G35: 否 | I35: 不適用
B36: 5.4 | C36: 投資產生的排放 | G36: 否 | I36: 不適用
B37: 類別 6: | C37: 其他
B38: 6.1 | C38: 其他來源之間接溫室氣體排放量 | G38: 否 | I38: 不適用
